File: PB19_TRI_16622.csv
Index,Date,Time,Counter,FbLoad,Lvdt1,Lvdt2,Force(kN),Potm,LVDT1,LVDT2,Chain,Stress [MPa],Strain Ax. [%],Strain Ax [-],Strain Rad. [%],Strain Vol. [%],Gemidd,IFlow,IPress,IVol,FlowA,PressA,VolA,FlowB,PressB,VolB
235,44728.46662,234.224048,58228276,6.776803,0.212859,0.21739,7.494144,1.937682,-0.786,-0.781072,19.912166,10.457269,0.001297,0.00001297,0,0.001297,-0.784197,0.02281,100,78.3207,0,7.9,42.4425,0,1.9,30.2995
262,44728.46693,261.224048,58228303,7.627013,0.22322,0.227437,8.205146,1.94557,-0.777405,-0.773117,19.912166,11.587314,0.014644,0.00014644,0,0.014644,-0.775289,0.01462,100,78.3125,0,7.8,42.4425,0,1.9,30.2995
289,44728.46725,288.224048,58228330,9.711455,0.250316,0.254409,10.266428,1.971209,-0.750404,-0.746131,19.912166,14.521827,0.053203,0.00053203,0,0.053203,-0.74831,0.011,100,78.3074,0,7.9,42.4425,0,1.9,30.2995
316,44728.46756,315.224048,58228357,11.917255,0.277635,0.281846,12.466148,1.995861,-0.722979,-0.718586,19.912166,17.673913,0.09247,0.0009247,0,0.09247,-0.72083,0.00834,100,78.3033,0,7.8,42.4425,0,1.9,30.2995
343,44728.46787,342.224048,58228384,14.232896,0.304707,0.308782,14.810443,2.024458,-0.695901,-0.691732,19.912166,20.975801,0.131003,0.00131003,0,0.131003,-0.693928,0.00535,100,78.3003,0,7.8,42.4425,0,1.9,30.2995
370,44728.46818,369.224048,58228411,16.686994,0.331495,0.335404,17.305883,2.052069,-0.669012,-0.664976,19.912166,24.456647,0.169312,0.00169312,0,0.169312,-0.667072,0.00289,100,78.2984,0,7.8,42.4425,0,1.9,30.2995
397,44728.4685,396.224048,58228438,19.302354,0.358438,0.362254,19.92901,2.078694,-0.642193,-0.638121,19.912166,28.134171,0.2076,0.002076,0,0.2076,-0.640198,0.0013,100,78.2976,0,7.8,42.4425,0,1.9,30.2995
424,44728.46881,423.224048,58228465,22.105751,0.385794,0.389439,22.740993,2.104332,-0.614964,-0.611135,19.912166,32.160005,0.24639,0.0024639,0,0.24639,-0.613069,0,100,78.2975,0,7.8,42.4425,0,1.9,30.2995
451,44728.46912,450.224048,58228492,24.944084,0.412862,0.416346,25.547031,2.129971,-0.587893,-0.584773,19.912166,36.186181,0.284812,0.00284812,0,0.284812,-0.586222,0,100,78.2975,0,7.8,42.4425,0,1.9,30.2995
478,44728.46943,477.224048,58228519,27.914187,0.439846,0.443255,28.547173,2.157581,-0.560801,-0.557524,19.912166,40.439421,0.323528,0.00323528,0,0.323528,-0.55924,0,100,78.2975,0,7.8,42.4425,0,1.9,30.2995
505,44728.46975,504.224048,58228546,30.906623,0.466744,0.469953,31.609367,2.182234,-0.533821,-0.530505,19.912166,44.741541,0.361948,0.00361948,0,0.361948,-0.532099,-0.01248,100,78.3003,0,7.8,42.4425,0,1.9,30.2995
532,44728.47006,531.224048,58228573,33.94525,0.493772,0.497304,34.724464,2.208859,-0.50669,-0.503125,19.912166,49.075904,0.40079,0.0040079,0,0.40079,-0.504919,-0.00706,100,78.3039,0,7.8,42.4425,0,1.9,30.2995
559,44728.47037,558.224048,58228600,36.970323,0.520795,0.524313,37.776355,2.235483,-0.479831,-0.476204,19.912166,53.407882,0.439191,0.00439191,0,0.439191,-0.477987,-0.00975,100,78.3076,0,7.8,42.4425,0,1.9,30.2995
586,44728.47068,585.224048,58228627,40.030954,0.547891,0.551474,40.833855,2.263094,-0.452686,-0.449054,19.912166,57.783156,0.47813,0.0047813,0,0.47813,-0.450923,-0.011,100,78.3124,0,7.8,42.4425,0,1.9,30.2995
613,44728.471,612.224048,58228654,43.038003,0.574812,0.578372,43.911526,2.289719,-0.425631,-0.421969,19.912166,62.120357,0.516714,0.00516714,0,0.516714,-0.423942,-0.01332,100,78.318,0,7.8,42.4425,0,1.9,30.2995
640,44728.47131,639.224048,58228681,45.915111,0.601625,0.605352,46.861094,2.313385,-0.398784,-0.394786,19.912166,66.261155,0.55509,0.0055509,0,0.55509,-0.39699,-0.01598,100,78.3248,0,7.8,42.4425,0,1.9,30.2995
667,44728.47162,666.224048,58228708,48.821807,0.629135,0.632979,49.721897,2.34001,-0.371442,-0.367701,19.912166,70.390401,0.59428,0.0059428,0,0.59428,-0.369646,-0.01986,100,78.3332,0,7.8,42.4425,0,1.9,30.2995
694,44728.47193,693.224048,58228735,51.521171,0.655817,0.659512,52.493569,2.36762,-0.34486,-0.341175,19.912166,74.288736,0.632213,0.00632213,0,0.632213,-0.343146,-0.0225,100,78.3429,0,7.8,42.4425,0,1.9,30.2995
721,44728.47225,720.224048,58228762,54.267273,0.68303,0.686889,55.432754,2.395231,-0.317232,-0.313433,19.912166,78.3972,0.671815,0.00671815,0,0.671815,-0.31523,-0.02722,100,78.3547,0,7.8,42.4425,0,1.9,30.2995
748,44728.47256,747.224048,58228789,56.771457,0.709989,0.713639,57.999653,2.42087,-0.290451,-0.286611,19.912166,82.027695,0.709843,0.00709843,0,0.709843,-0.2887,-0.03173,100,78.3681,0,7.8,42.4425,0,1.9,30.2995
775,44728.47287,774.224048,58228816,59.138964,0.737027,0.740712,60.441559,2.446508,-0.263557,-0.259724,19.912166,85.496952,0.748297,0.00748297,0,0.748297,-0.261783,-0.03669,100,78.3844,0,7.8,42.4425,0,1.9,30.2995
802,44728.47318,801.224048,58228843,61.342311,0.763994,0.767584,62.758738,2.470175,-0.23649,-0.232705,19.912166,88.773924,0.786946,0.00786946,0,0.786946,-0.234728,-0.04312,100,78.4032,0,7.9,42.4425,0,1.9,30.2995
829,44728.4735,828.224048,58228870,63.316499,0.790964,0.794636,64.85426,2.497785,-0.20958,-0.205948,19.912166,91.737901,0.825433,0.00825433,0,0.825433,-0.207641,-0.05192,100,78.4253,0,7.8,42.4425,0,1.9,30.2995
856,44728.47381,855.224048,58228897,65.055705,0.817733,0.821455,66.732754,2.522438,-0.18263,-0.178798,19.912166,94.399114,0.86396,0.0086396,0,0.86396,-0.180837,-0.05872,100,78.4506,0,7.8,42.4425,0,1.9,30.2995
883,44728.47412,882.224048,58228924,66.466913,0.843954,0.847565,68.256823,2.549062,-0.156551,-0.152732,19.912166,96.570506,0.901249,0.00901249,0,0.901249,-0.154681,-0.0684,100,78.4799,0,7.8,42.4425,0,1.9,30.2995
910,44728.47443,909.224048,58228951,61.42642,0.817388,0.8207,63.375311,2.520466,-0.183397,-0.180277,19.912166,89.681481,0.862735,0.00862735,0,0.862735,-0.181676,0.03463,100,78.4725,0,7.8,42.4425,0,1.9,30.2995
937,44728.47475,936.224048,58228978,56.974387,0.790411,0.794192,59.106286,2.497785,-0.210422,-0.206441,19.912166,83.626278,0.824518,0.00824518,0,0.824518,-0.208387,0.02516,100,78.4617,0,7.8,42.4425,0,1.9,30.2995
964,44728.47506,963.224048,58229005,52.515953,0.762729,0.767207,54.842209,2.471161,-0.238345,-0.233888,19.912166,77.610944,0.785161,0.00785161,0,0.785161,-0.236014,0.0258,100,78.4507,0,7.8,42.4425,0,1.9,30.2995
991,44728.47537,990.224048,58229032,48.430761,0.736513,0.741256,50.989892,2.445522,-0.264335,-0.259428,19.912166,72.141306,0.748174,0.00748174,0,0.748174,-0.261863,0.02513,100,78.4399,0,7.8,42.4425,0,1.9,30.2995
1018,44728.47568,1017.224048,58229059,44.271679,0.70947,0.713869,47.06195,2.42087,-0.291334,-0.286874,19.912166,66.588794,0.709459,0.00709459,0,0.709459,-0.289082,0.02548,100,78.4285,0,7.8,42.4425,0,1.9,30.2995
1045,44728.476,1044.224048,58229086,40.322214,0.682087,0.686758,43.340767,2.395231,-0.318855,-0.314222,19.912166,61.337174,0.670083,0.00670083,0,0.670083,-0.316543,0.026,100,78.4167,0,7.8,42.4425,0,1.9,30.2995
1072,44728.47631,1071.224048,58229113,36.497586,0.65449,0.659673,39.864856,2.36762,-0.346341,-0.340912,19.912166,56.355261,0.631119,0.00631119,0,0.631119,-0.34377,0.02629,100,78.4048,0,7.8,42.4425,0,1.9,30.2995
1099,44728.47662,1098.224048,58229140,32.891029,0.627404,0.632982,36.539726,2.341982,-0.373358,-0.367602,19.912166,51.705306,0.593031,0.00593031,0,0.593031,-0.370468,0.02667,100,78.3926,0,7.8,42.4425,0,1.9,30.2995
1126,44728.47693,1125.224048,58229167,29.410125,0.599918,0.606315,33.386525,2.317329,-0.400855,-0.394457,19.912166,47.233195,0.554314,0.00554314,0,0.554314,-0.397534,0.02696,100,78.3802,0,7.8,42.4425,0,1.9,30.2995
1153,44728.47725,1152.224048,58229194,26.030962,0.572921,0.579451,30.329956,2.289719,-0.428039,-0.421377,19.912166,42.885975,0.515509,0.00515509,0,0.515509,-0.424734,0.0289,100,78.3673,0,7.8,42.4425,0,1.9,30.2995
1180,44728.47756,1179.224048,58229221,22.758308,0.54584,0.552424,27.391015,2.263094,-0.455139,-0.448561,19.912166,38.756621,0.476874,0.00476874,0,0.476874,-0.451769,0.02904,100,78.3542,0,7.8,42.4425,0,1.9,30.2995
1207,44728.47787,1206.224048,58229248,19.6347,0.519125,0.525692,24.63446,2.236469,-0.481833,-0.475448,19.912166,34.88001,0.438745,0.00438745,0,0.438745,-0.478469,0.03017,100,78.3408,0,7.8,42.4425,0,1.9,30.2995
1234,44728.47818,1233.224048,58229275,16.617233,0.492262,0.498532,22.020215,2.207872,-0.508751,-0.502237,19.912166,31.173054,0.400393,0.00400393,0,0.400393,-0.50545,0.02901,100,78.3276,0,7.8,42.4425,0,1.9,30.2995
1261,44728.4785,1260.224048,58229302,13.727285,0.465281,0.471712,19.571913,2.18322,-0.535723,-0.529092,19.912166,27.673726,0.361656,0.00361656,0,0.361656,-0.532334,0.02858,100,78.3146,0,7.8,42.4425,0,1.9,30.2995
1288,44728.47881,1287.224048,58229329,12.129772,0.446131,0.453211,18.399759,2.162512,-0.554668,-0.547598,19.912166,26.028441,0.335038,0.00335038,0,0.335038,-0.551064,4.92193,112.8,78.1004,0,7.8,42.4425,0,1.9,30.2995
1315,44728.47912,1314.224048,58229356,13.013657,0.446079,0.452957,19.716408,2.162512,-0.554627,-0.54763,19.912166,27.888977,0.334828,0.00334828,0,0.334828,-0.551226,4.93004,151.9,77.4034,0,7.8,42.4425,0,1.9,30.2995
1342,44728.47943,1341.224048,58229383,13.485263,0.446142,0.453092,20.599757,2.162512,-0.554666,-0.547762,19.912166,29.201996,0.334841,0.00334841,0,0.334841,-0.551233,0.10946,180,76.8722,0,7.9,42.4425,0,1.9,30.2995
1369,44728.47975,1368.224048,58229410,16.030753,0.466223,0.472642,23.657327,2.18322,-0.534276,-0.52781,19.912166,33.492012,0.363622,0.00363622,0,0.363622,-0.530988,0.05951,200,76.51,0,7.8,42.4425,0,1.9,30.2995
1396,44728.48006,1395.224048,58229437,19.019948,0.493768,0.49932,27.127736,2.211817,-0.506738,-0.50135,19.912166,38.394624,0.402309,0.00402309,0,0.402309,-0.503939,0.03845,200,76.4893,0,7.8,42.4425,0,1.9,30.2995
1423,44728.48037,1422.224048,58229464,22.084954,0.521078,0.525971,30.674274,2.236469,-0.479588,-0.474659,19.912166,43.347067,0.440563,0.00440563,0,0.440563,-0.477165,0.0251,200,76.4763,0,7.8,42.4425,0,1.9,30.2995
1450,44728.48068,1449.224048,58229491,25.232849,0.548266,0.553065,34.323619,2.26408,-0.452269,-0.447377,19.912166,48.57209,0.479715,0.00479715,0,0.479715,-0.44979,0.0174,200,76.4675,0,7.8,42.4425,0,1.9,30.2995
1477,44728.481,1476.224048,58229518,28.373466,0.574984,0.579929,37.911404,2.289719,-0.425671,-0.420523,19.912166,53.641265,0.517856,0.00517856,0,0.517856,-0.423091,0.01198,200,76.4615,0,7.8,42.4425,0,1.9,30.2995
1504,44728.48131,1503.224048,58229545,31.598053,0.60251,0.60709,41.643029,2.316343,-0.398277,-0.393537,19.912166,58.886232,0.556553,0.00556553,0,0.556553,-0.396017,0.00807,200,76.4573,0,7.8,42.4425,0,1.9,30.2995
1531,44728.48162,1530.224048,58229572,34.768249,0.629659,0.633495,45.29867,2.343954,-0.371161,-0.367011,19.912166,64.070048,0.594907,0.00594907,0,0.594907,-0.369209,0.00376,200,76.4549,0,7.8,42.4425,0,1.9,30.2995
1558,44728.48193,1557.224048,58229599,38.06199,0.656737,0.660406,49.116311,2.370579,-0.34367,-0.340057,19.912166,69.518353,0.633865,0.00633865,0,0.633865,-0.341894,0.00017,200,76.4542,0,7.8,42.4425,0,1.9,30.2995
1585,44728.48225,1584.224048,58229626,41.380651,0.684325,0.687311,52.923479,2.399175,-0.316144,-0.313137,19.912166,74.89487,0.672659,0.00672659,0,0.672659,-0.314685,0,200,76.4542,0,7.8,42.4425,0,1.9,30.2995
1612,44728.48256,1611.224048,58229653,44.608642,0.710803,0.713841,56.691332,2.424814,-0.289657,-0.286578,19.912166,80.169781,0.710493,0.00710493,0,0.710493,-0.288245,-0.00283,200,76.4547,0,7.8,42.4425,0,1.9,30.2995
1639,44728.48287,1638.224048,58229680,47.891707,0.736828,0.740764,60.440505,2.450453,-0.263673,-0.259526,19.912166,85.499065,0.7484,0.007484,0,0.7484,-0.26171,-0.00744,200,76.4602,0,7.7,42.4425,0,1.9,30.2995
1666,44728.48318,1665.224048,58229707,51.218451,0.763927,0.768094,64.274648,2.479049,-0.236579,-0.232376,19.912166,90.922388,0.787363,0.00787363,0,0.787363,-0.234436,-0.00906,200,76.4644,0,7.8,42.4425,0,1.9,30.2995
1693,44728.4835,1692.224048,58229734,54.412617,0.79074,0.794928,67.973417,2.503702,-0.209667,-0.205554,19.912166,96.145524,0.825634,0.00825634,0,0.825634,-0.207504,-0.01065,200,76.4694,0,7.8,42.4425,0,1.9,30.2995
1720,44728.48381,1719.224048,58229761,57.535028,0.817587,0.821859,71.601626,2.528354,-0.182879,-0.178765,19.912166,101.277907,0.864045,0.00864045,0,0.864045,-0.180807,-0.01326,200,76.4754,0,7.8,42.4425,0,1.9,30.2995
1747,44728.48412,1746.224048,58229788,60.711237,0.84522,0.849256,75.263586,2.553007,-0.155266,-0.151154,19.912166,106.45231,0.903264,0.00903264,0,0.903264,-0.153285,-0.01688,200,76.4826,0,7.8,42.4425,0,1.9,30.2995
1774,44728.48443,1773.224048,58229815,63.635089,0.871813,0.875741,78.639698,2.578645,-0.128695,-0.124596,19.912166,111.24307,0.94118,0.0094118,0,0.94118,-0.126764,-0.01691,200,76.4906,0,7.7,42.4425,0,1.9,30.2995
1801,44728.48475,1800.224048,58229842,66.554195,0.899269,0.903001,82.081922,2.604284,-0.101201,-0.097609,19.912166,116.114443,0.980402,0.00980402,0,0.980402,-0.099309,-0.0218,200,76.4997,0,7.8,42.4425,0,1.9,30.2995
1828,44728.48506,1827.224048,58229869,69.231317,0.926113,0.929809,85.265482,2.628936,-0.074378,-0.070722,19.912166,120.610041,1.018596,0.01018596,0,1.018596,-0.072573,-0.02493,200,76.5102,0,7.8,42.4425,0,1.9,30.2995
1855,44728.48537,1854.224048,58229896,71.854467,0.953301,0.957082,88.359842,2.655561,-0.047043,-0.043374,19.912166,124.988175,1.05766,0.0105766,0,1.05766,-0.045228,-0.02869,200,76.5219,0,7.8,42.4425,0,1.9,30.2995
1882,44728.48568,1881.224048,58229923,74.156079,0.980413,0.984054,91.153577,2.683172,-0.020107,-0.016618,19.912166,128.947732,1.095994,0.01095994,0,1.095994,-0.018207,-0.03281,200,76.5355,0,7.8,42.4425,0,1.9,30.2995
1909,44728.486,1908.224048,58229950,76.238303,1.007175,1.010791,93.754366,2.706838,0.00688,0.010631,19.912166,132.625098,1.134488,0.01134488,0,1.134488,0.008726,-0.03602,200,76.5508,0,7.8,42.4425,0,1.9,30.2995
1936,44728.48631,1935.224048,58229977,78.054783,1.034012,1.037671,96.070754,2.732477,0.033688,0.03742,19.912166,135.886383,1.172934,0.01172934,0,1.172934,0.035463,-0.04106,200,76.5689,0,7.8,42.4425,0,1.9,30.2995
1963,44728.48662,1962.224048,58230004,79.590293,1.061269,1.064923,98.105275,2.760087,0.060878,0.064505,19.912166,138.782229,1.211832,0.01211832,0,1.211832,0.062766,-0.04668,200,76.5899,0,7.8,42.4425,0,1.9,30.2995
1990,44728.48693,1989.224048,58230031,75.666752,1.048995,1.052272,94.650901,2.746282,0.048211,0.051521,19.912166,133.910966,1.193545,0.01193545,0,1.193545,0.04983,0.03472,200,76.59,0,7.8,42.4425,0,1.9,30.2995
2017,44728.48725,2016.224048,58230058,70.579184,1.022586,1.025846,90.063207,2.722616,0.021784,0.025127,19.912166,127.442846,1.155901,0.01155901,0,1.155901,0.023427,0.02212,200,76.5794,0,7.8,42.4425,0,1.9,30.2995
2044,44728.48756,2043.224048,58230085,65.405603,0.994823,0.998208,85.404128,2.694019,-0.006003,-0.00255,19.912166,120.835446,1.116251,0.01116251,0,1.116251,-0.004214,0.02493,200,76.5688,0,7.8,42.4425,0,1.9,30.2995
2071,44728.48787,2070.224048,58230112,60.560148,0.968582,0.97223,81.082193,2.670352,-0.03231,-0.028517,19.912166,114.719758,1.078918,0.01078918,0,1.078918,-0.030426,0.02351,200,76.5585,0,7.9,42.4425,0,1.9,30.2995
2098,44728.48818,2097.224048,58230139,55.738433,0.941708,0.94565,76.804356,2.644714,-0.05911,-0.055372,19.912166,108.678962,1.040757,0.01040757,0,1.040757,-0.05706,0.02386,200,76.5478,0,7.8,42.4425,0,1.9,30.2995
2125,44728.4885,2124.224048,58230166,50.821989,0.91362,0.91783,72.396951,2.616117,-0.087225,-0.083015,19.912166,102.442303,1.000818,0.01000818,0,1.000818,-0.085037,0.02449,200,76.5366,0,7.8,42.4425,0,1.9,30.2995
2152,44728.48881,2151.224048,58230193,46.156531,0.886765,0.891466,68.32516,2.592451,-0.114149,-0.109574,19.912166,96.682421,0.962706,0.00962706,0,0.962706,-0.111792,0.02441,200,76.5255,0,7.8,42.4425,0,1.9,30.2995
2179,44728.48912,2178.224048,58230220,41.599183,0.8598,0.864716,64.316373,2.566812,-0.141207,-0.13633,19.912166,91.011362,0.924362,0.00924362,0,0.924362,-0.138665,0.02542,200,76.5144,0,7.8,42.4425,0,1.9,30.2995
2206,44728.48943,2205.224048,58230247,37.093162,0.832381,0.837648,60.396534,2.539201,-0.168421,-0.163283,19.912166,85.461713,0.885556,0.00885556,0,0.885556,-0.165701,0.02542,200,76.5029,0,7.9,42.4425,0,1.9,30.2995
2233,44728.48975,2232.224048,58230274,32.712662,0.805478,0.81078,56.573932,2.512577,-0.195687,-0.190368,19.912166,80.083868,0.846684,0.00846684,0,0.846684,-0.19301,0.02606,200,76.4912,0,7.8,42.4425,0,1.9,30.2995
2260,44728.49006,2259.224048,58230301,28.366937,0.778709,0.783283,52.90101,2.48891,-0.222194,-0.217584,19.912166,74.860429,0.808319,0.00808319,0,0.808319,-0.219868,0.0273,200,76.4792,0,7.8,42.4425,0,1.9,30.2995
2287,44728.49037,2286.224048,58230328,24.103757,0.751907,0.755499,49.238225,2.4613,-0.249125,-0.245589,19.912166,69.677408,0.769175,0.00769175,0,0.769175,-0.247272,0.02652,200,76.467,0,7.8,42.4425,0,1.9,30.2995
2314,44728.49068,2313.224048,58230355,20.15118,0.724924,0.728957,45.897723,2.435661,-0.275971,-0.271918,19.912166,65.000774,0.731068,0.00731068,0,0.731068,-0.273967,0.02603,200,76.4551,0,7.8,42.4425,0,1.9,30.2995
2341,44728.491,2340.224048,58230382,16.252497,0.6973,0.702268,42.652839,2.411009,-0.303653,-0.298904,19.912166,60.353337,0.692105,0.00692105,0,0.692105,-0.301235,0.02594,200,76.4433,0,7.8,42.4425,0,1.9,30.2995
2368,44728.49131,2367.224048,58230409,12.437806,0.669902,0.67535,39.520605,2.383398,-0.330844,-0.325595,19.912166,55.892748,0.653494,0.00653494,0,0.653494,-0.328144,0.02638,200,76.4316,0,7.9,42.4425,0,1.9,30.2995
2395,44728.49162,2394.224048,58230436,8.802781,0.642848,0.648946,36.518384,2.354801,-0.358202,-0.351891,19.912166,51.647142,0.615128,0.00615128,0,0.615128,-0.355125,0.0258,200,76.4199,0,7.8,42.4425,0,1.9,30.2995
2422,44728.49193,2421.224048,58230463,5.207466,0.615352,0.621954,33.584279,2.330149,-0.385461,-0.378844,19.912166,47.543745,0.576445,0.00576445,0,0.576445,-0.382079,0.02571,200,76.4082,0,7.8,42.4425,0,1.9,30.2995
2449,44728.49225,2448.224048,58230490,1.722551,0.588471,0.595006,30.771726,2.301552,-0.41248,-0.405797,19.912166,43.513022,0.537739,0.00537739,0,0.537739,-0.409185,0.0256,200,76.3966,0,7.8,42.4425,0,1.9,30.2995
2476,44728.49256,2475.224048,58230517,-1.666472,0.561752,0.568014,28.036804,2.277885,-0.439074,-0.432915,19.912166,39.700781,0.49962,0.0049962,0,0.49962,-0.435856,0.0251,200,76.3853,0,7.8,42.4425,0,1.9,30.2995
2503,44728.49287,2502.224048,58230544,-3.107034,0.54827,0.554247,27.285926,2.261122,-0.452761,-0.446687,19.912166,38.562829,0.47989,0.0047989,0,0.47989,-0.449795,2.07406,217.3,76.1215,0,7.8,42.4425,0,1.9,30.2995
2530,44728.49318,2529.224048,58230571,-2.424894,0.548252,0.554053,28.68176,2.262108,-0.452722,-0.446358,19.912166,40.460397,0.479571,0.00479571,0,0.479571,-0.449763,0.24094,260,75.437,0,7.7,42.4425,0,1.9,30.2995
2557,44728.4935,2556.224048,58230598,-1.947367,0.548425,0.55434,29.87647,2.262108,-0.45216,-0.445931,19.912166,42.166527,0.480578,0.00480578,0,0.480578,-0.449127,-0.0527,300,74.8087,0,7.8,42.4425,0,1.9,30.2995
2584,44728.49381,2583.224048,58230625,1.219432,0.575215,0.580941,33.580066,2.289719,-0.4255,-0.419734,19.912166,47.489898,0.518516,0.00518516,0,0.518516,-0.422629,0.05212,300,74.7782,0,7.8,42.4425,0,1.9,30.2995
2611,44728.49412,2610.224048,58230652,4.383279,0.60259,0.607874,37.426935,2.316343,-0.398003,-0.392452,19.912166,52.94595,0.557518,0.00557518,0,0.557518,-0.395274,0.032,300,74.7616,0,7.8,42.4425,0,1.9,30.2995
2638,44728.49443,2637.224048,58230679,7.518429,0.629833,0.634956,41.21781,2.341982,-0.370731,-0.365597,19.912166,58.291865,0.596247,0.00596247,0,0.596247,-0.368312,0.02235,300,74.7503,0,7.9,42.4425,0,1.9,30.2995
2665,44728.49475,2664.224048,58230706,10.722011,0.65714,0.661236,45.055235,2.369593,-0.343336,-0.339038,19.912166,63.696955,0.634636,0.00634636,0,0.634636,-0.341273,0.01546,300,74.7426,0,7.8,42.4425,0,1.9,30.2995
2692,44728.49506,2691.224048,58230733,14.059592,0.684393,0.688122,49.027948,2.396217,-0.3158,-0.311954,19.912166,69.323942,0.67369,0.0067369,0,0.67369,-0.31388,0.0108,300,74.7372,0,7.8,42.4425,0,1.9,30.2995
2719,44728.49537,2718.224048,58230760,17.373656,0.711904,0.714888,52.868818,2.421856,-0.288683,-0.285888,19.912166,74.829056,0.711907,0.00711907,0,0.711907,-0.287255,0.00747,300,74.7334,0,7.8,42.4425,0,1.9,30.2995
2746,44728.49568,2745.224048,58230787,20.711318,0.739328,0.741285,56.786101,2.44848,-0.261244,-0.259526,19.912166,80.377581,0.750528,0.00750528,0,0.750528,-0.260221,0.00396,300,74.7314,0,7.8,42.4425,0,1.9,30.2995
2773,44728.496,2772.224048,58230814,24.076501,0.765493,0.767771,60.864548,2.477077,-0.23474,-0.232277,19.912166,86.057974,0.788304,0.00788304,0,0.788304,-0.233638,0.00049,300,74.7307,0,7.8,42.4425,0,1.9,30.2995
2800,44728.49631,2799.224048,58230841,27.704164,0.791989,0.795698,65.027502,2.50173,-0.208249,-0.204568,19.912166,91.964222,0.827224,0.00827224,0,0.827224,-0.206351,0,300,74.7307,0,7.8,42.4425,0,1.9,30.2995
2827,44728.49662,2826.224048,58230868,31.117739,0.818608,0.822369,68.986977,2.527368,-0.181892,-0.178042,19.912166,97.570823,0.865041,0.00865041,0,0.865041,-0.180062,0,300,74.7307,0,7.8,42.4425,0,1.9,30.2995
2854,44728.49693,2853.224048,58230895,34.583179,0.845288,0.849024,72.990149,2.553007,-0.155044,-0.151319,19.912166,103.229875,0.903331,0.00903331,0,0.903331,-0.153229,-0.00868,300,74.7374,0,7.8,42.4425,0,1.9,30.2995
2881,44728.49725,2880.224048,58230922,38.132945,0.872659,0.876365,77.033704,2.581604,-0.127761,-0.123971,19.912166,108.968794,0.942322,0.00942322,0,0.942322,-0.126027,-0.00738,300,74.7408,0,7.8,42.4425,0,1.9,30.2995
2908,44728.49756,2907.224048,58230949,41.556689,0.899397,0.903018,80.973537,2.607242,-0.101028,-0.097248,19.912166,114.541446,0.980505,0.00980505,0,0.980505,-0.099237,-0.00999,300,74.7448,0,7.8,42.4425,0,1.9,30.2995
2935,44728.49787,2934.224048,58230976,45.108422,0.926915,0.930285,85.0463,2.635839,-0.07343,-0.070097,19.912166,120.298971,1.019753,0.01019753,0,1.019753,-0.071697,-0.0114,300,74.75,0,7.8,42.4425,0,1.9,30.2995
2962,44728.49818,2961.224048,58231003,48.538701,0.953773,0.956985,88.920833,2.661478,-0.046589,-0.043341,19.912166,125.780206,1.057833,0.01057833,0,1.057833,-0.045107,-0.01369,300,74.7557,0,7.8,42.4425,0,1.9,30.2995
2989,44728.4985,2988.224048,58231030,51.943473,0.980986,0.984292,92.789739,2.68613,-0.019541,-0.016289,19.912166,131.264442,1.096621,0.01096621,0,1.096621,-0.01799,-0.01413,300,74.7627,0,7.8,42.4425,0,1.9,30.2995
3016,44728.49881,3015.224048,58231057,55.281994,1.007873,1.011254,96.595954,2.713741,0.007471,0.010993,19.912166,136.650103,1.135304,0.01135304,0,1.135304,0.009184,-0.0154,300,74.7695,0,7.8,42.4425,0,1.9,30.2995
3043,44728.49912,3042.224048,58231084,58.557576,1.034899,1.038259,100.318858,2.738393,0.034429,0.037979,19.912166,141.904082,1.173811,0.01173811,0,1.173811,0.036286,-0.0172,300,74.7777,0,7.8,42.4425,0,1.9,30.2995
3070,44728.49943,3069.224048,58231111,61.744787,1.061828,1.06527,103.930759,2.763046,0.061486,0.065064,19.912166,147.026464,1.212552,0.01212552,0,1.212552,0.06319,-0.01798,300,74.7864,0,7.8,42.4425,0,1.9,30.2995
3097,44728.49975,3096.224048,58231138,64.871446,1.089323,1.092713,107.495508,2.78967,0.088877,0.092247,19.912166,152.064945,1.25174,0.0125174,0,1.25174,0.090628,-0.02128,300,74.7963,0,7.8,42.4425,0,1.9,30.2995
3124,44728.50006,3123.224048,58231165,67.762877,1.115626,1.119674,110.777109,2.818267,0.11522,0.119201,19.912166,156.71311,1.289619,0.01289619,0,1.289619,0.117349,-0.02403,300,74.8064,0,7.8,42.4425,0,1.9,30.2995
3151,44728.50037,3150.224048,58231192,70.527463,1.142282,1.14708,113.958208,2.84292,0.141881,0.146877,19.912166,161.21333,1.328436,0.01328436,0,1.328436,0.144355,-0.02684,300,74.8182,0,7.8,42.4425,0,1.9,30.2995
3178,44728.50068,3177.224048,58231219,73.163966,1.169617,1.175083,116.982555,2.869544,0.169249,0.174915,19.912166,165.502233,1.367893,0.01367893,0,1.367893,0.172027,-0.03339,300,74.8319,0,7.8,42.4425,0,1.9,30.2995
3205,44728.501,3204.224048,58231246,75.182532,1.195737,1.201212,119.400758,2.893211,0.195344,0.200751,19.912166,168.916016,1.405168,0.01405168,0,1.405168,0.198028,-0.0326,300,74.8463,0,7.8,42.4425,0,1.9,30.2995
3232,44728.50131,3231.224048,58231273,77.07285,1.22282,1.228042,121.700839,2.918849,0.222537,0.227803,19.912166,172.16621,1.443906,0.01443906,0,1.443906,0.225169,-0.03866,300,74.863,0,7.8,42.4425,0,1.9,30.2995
3259,44728.50162,3258.224048,58231300,75.098334,1.226103,1.230474,120.075736,2.921807,0.225369,0.229874,19.912166,169.89991,1.447409,0.01447409,0,1.447409,0.227578,0.00344,300,74.8719,0,7.8,42.4425,0,1.9,30.2995
3286,44728.50193,3285.224048,58231327,69.748988,1.199093,1.203555,115.111758,2.896169,0.198211,0.202789,19.912166,162.881645,1.408818,0.01408818,0,1.408818,0.20042,0.02142,300,74.8559,0,7.8,42.4425,0,1.9,30.2995
3313,44728.50225,3312.224048,58231354,64.561143,1.171727,1.176211,110.32098,2.871516,0.170878,0.175342,19.912166,156.092052,1.369611,0.01369611,0,1.369611,0.173124,0.02192,300,74.8459,0,7.8,42.4425,0,1.9,30.2995
3340,44728.50256,3339.224048,58231381,59.620066,1.14569,1.149975,105.810645,2.845878,0.144953,0.149277,19.912166,149.722114,1.33245,0.0133245,0,1.33245,0.147107,0.02111,300,74.8362,0,7.8,42.4425,0,1.9,30.2995
3367,44728.50287,3366.224048,58231408,54.502776,1.118485,1.122145,101.122513,2.818267,0.117716,0.12114,19.912166,143.076155,1.293101,0.01293101,0,1.293101,0.119505,0.02169,300,74.826,0,7.8,42.4425,0,1.9,30.2995
3394,44728.50318,3393.224048,58231435,49.560984,1.09137,1.095106,96.595236,2.788684,0.090583,0.094417,19.912166,136.669448,1.254617,0.01254617,0,1.254617,0.09255,0.02316,300,74.8157,0,7.9,42.4425,0,1.9,30.2995
3421,44728.5035,3420.224048,58231462,44.71568,1.064387,1.068053,92.19338,2.763046,0.063582,0.067036,19.912166,130.448805,1.215939,0.01215939,0,1.215939,0.06541,0.02455,300,74.8054,0,7.8,42.4425,0,1.9,30.2995
3448,44728.50381,3447.224048,58231489,40.095089,1.038128,1.04202,88.028612,2.737407,0.037428,0.041233,19.912166,124.548732,1.178715,0.01178715,0,1.178715,0.039511,0.02082,300,74.7953,0,7.8,42.4425,0,1.9,30.2995
3475,44728.50412,3474.224048,58231516,35.391519,1.010845,1.014773,83.773023,2.710782,0.010198,0.013984,19.912166,118.518571,1.139636,0.01139636,0,1.139636,0.012155,0.02441,300,74.7847,0,7.9,42.4425,0,1.9,30.2995
3502,44728.50443,3501.224048,58231543,30.565783,0.982727,0.986982,79.428893,2.685144,-0.018022,-0.01366,19.912166,112.368447,1.099632,0.01099632,0,1.099632,-0.015848,0.02467,300,74.7739,0,7.8,42.4425,0,1.9,30.2995
3529,44728.50475,3528.224048,58231570,26.144628,0.956339,0.960675,75.456997,2.660491,-0.044571,-0.040153,19.912166,106.78381,1.061861,0.01061861,0,1.061861,-0.042364,0.02328,300,74.7633,0,7.8,42.4425,0,1.9,30.2995
3556,44728.50506,3555.224048,58231597,21.620138,0.928959,0.933488,71.427212,2.633867,-0.072001,-0.067566,19.912166,101.064314,1.022846,0.01022846,0,1.022846,-0.069611,0.02354,300,74.7526,0,7.8,42.4425,0,1.9,30.2995
3583,44728.50537,3582.224048,58231624,17.26229,0.901822,0.906517,67.580394,2.607242,-0.098968,-0.094355,19.912166,95.626798,0.984409,0.00984409,0,0.984409,-0.096582,0.02415,300,74.7418,0,7.8,42.4425,0,1.9,30.2995
3610,44728.50568,3609.224048,58231651,12.966062,0.875036,0.879701,63.807349,2.580618,-0.125877,-0.121046,19.912166,90.301408,0.94581,0.0094581,0,0.94581,-0.12353,0.02423,300,74.731,0,7.8,42.4425,0,1.9,30.2995
3637,44728.506,3636.224048,58231678,8.748005,0.847954,0.852657,60.125191,2.555965,-0.152895,-0.148032,19.912166,85.07461,0.907353,0.00907353,0,0.907353,-0.150604,0.02383,300,74.7204,0,7.8,42.4425,0,1.9,30.2995
3664,44728.50631,3663.224048,58231705,4.598889,0.820827,0.825647,56.521919,2.52934,-0.18012,-0.175379,19.912166,79.977848,0.868521,0.00868521,0,0.868521,-0.177627,0.0236,300,74.7097,0,7.8,42.4425,0,1.9,30.2995
3691,44728.50662,3690.224048,58231732,0.485408,0.794321,0.797945,52.959694,2.502716,-0.206452,-0.20276,19.912166,74.932353,0.830013,0.00830013,0,0.830013,-0.204594,0.02444,300,74.6989,0,7.8,42.4425,0,1.9,30.2995
3718,44728.50693,3717.224048,58231759,-3.487693,0.767855,0.77069,49.541228,2.478063,-0.23296,-0.229878,19.912166,70.090614,0.79154,0.0079154,0,0.79154,-0.231512,0.02354,300,74.6882,0,7.8,42.4425,0,1.9,30.2995
3745,44728.50725,3744.224048,58231786,-7.299935,0.740443,0.743839,46.287385,2.451439,-0.260364,-0.256962,19.912166,65.50562,0.752966,0.00752966,0,0.752966,-0.258531,0.02319,300,74.6776,0,7.8,42.4425,0,1.9,30.2995
3772,44728.50756,3771.224048,58231813,-10.984985,0.713036,0.717342,43.166123,2.4258,-0.287922,-0.283686,19.912166,61.088017,0.714244,0.00714244,0,0.714244,-0.285651,0.02258,300,74.6674,0,7.7,42.4425,0,1.9,30.2995
3799,44728.50787,3798.224048,58231840,-14.575421,0.685291,0.691037,40.140964,2.400162,-0.315606,-0.309949,19.912166,56.798023,0.675665,0.00675665,0,0.675665,-0.312625,0.02244,300,74.6573,0,7.8,42.4425,0,1.9,30.2995
3826,44728.50818,3825.224048,58231867,-18.055976,0.658373,0.664255,37.233121,2.372551,-0.342481,-0.336738,19.912166,52.702198,0.637215,0.00637215,0,0.637215,-0.339567,0.02177,300,74.6472,0,7.8,42.4425,0,1.9,30.2995
3853,44728.5085,3852.224048,58231894,-21.501462,0.631306,0.63717,34.331444,2.34494,-0.36964,-0.363658,19.912166,48.585157,0.598602,0.00598602,0,0.598602,-0.366652,0.02224,300,74.6372,0,7.8,42.4425,0,1.9,30.2995
3880,44728.50881,3879.224048,58231921,-23.827561,0.612122,0.618073,32.590635,2.326204,-0.38868,-0.382558,19.912166,46.085616,0.571266,0.00571266,0,0.571266,-0.385791,2.26404,304,74.563,0,7.8,42.4425,0,1.9,30.2995
3907,44728.50912,3906.224048,58231948,-22.874383,0.612018,0.617852,34.115388,2.326204,-0.388626,-0.382657,19.912166,48.27019,0.571351,0.00571351,0,0.571351,-0.385706,4.91614,357.7,73.8022,0,7.8,42.4425,0,1.9,30.2995
3934,44728.50943,3933.224048,58231975,-21.99795,0.613418,0.618881,35.507844,2.326204,-0.387261,-0.381703,19.912166,50.216465,0.573018,0.00573018,0,0.573018,-0.384478,-0.07819,400,73.1867,0,7.8,42.4425,0,1.9,30.2995
3961,44728.50975,3960.224048,58232002,-18.633679,0.640277,0.645594,39.445071,2.353815,-0.360261,-0.354783,19.912166,55.785725,0.611316,0.00611316,0,0.611316,-0.357583,0.04584,400,73.1594,0,7.8,42.4425,0,1.9,30.2995
3988,44728.51006,3987.224048,58232029,-15.283281,0.667128,0.672227,43.331748,2.382412,-0.333297,-0.328323,19.912166,61.267277,0.649621,0.00649621,0,0.649621,-0.330855,0.02759,400,73.145,0,7.8,42.4425,0,1.9,30.2995
4015,44728.51037,4014.224048,58232056,-11.924094,0.694407,0.698622,47.19712,2.40805,-0.306077,-0.301961,19.912166,66.751445,0.687977,0.00687977,0,0.687977,-0.304006,0.01902,400,73.1352,0,7.8,42.4425,0,1.9,30.2995
4042,44728.51068,4041.224048,58232083,-8.497267,0.721872,0.724777,51.156528,2.432703,-0.278326,-0.275501,19.912166,72.345843,0.726543,0.00726543,0,0.726543,-0.276809,0.01369,400,73.1283,0,7.8,42.4425,0,1.9,30.2995
4069,44728.511,4068.224048,58232110,-5.009936,0.749398,0.751325,55.08347,2.459327,-0.251087,-0.249205,19.912166,77.912892,0.764849,0.00764849,0,0.764849,-0.250196,0.00946,400,73.1238,0,7.8,42.4425,0,1.9,30.2995
4096,44728.51131,4095.224048,58232137,-1.429575,0.77616,0.777783,59.129283,2.485952,-0.224296,-0.222548,19.912166,83.636502,0.802953,0.00802953,0,0.802953,-0.223523,0.00515,400,73.1207,0,7.9,42.4425,0,1.9,30.2995
4123,44728.51162,4122.224048,58232164,2.345414,0.802406,0.805438,63.337694,2.511591,-0.198042,-0.195134,19.912166,89.585149,0.841341,0.00841341,0,0.841341,-0.196642,0.00104,400,73.1193,0,7.8,42.4425,0,1.9,30.2995
4150,44728.51193,4149.224048,58232191,6.216311,0.829382,0.833004,67.639001,2.538215,-0.170995,-0.167162,19.912166,95.666112,0.880571,0.00880571,0,0.880571,-0.169191,0,400,73.1187,0,7.8,42.4425,0,1.9,30.2995
4177,44728.51225,4176.224048,58232218,9.738584,0.855184,0.858709,71.571392,2.563854,-0.145316,-0.141852,19.912166,101.2371,0.917123,0.00917123,0,0.917123,-0.143442,0,400,73.1187,0,7.8,42.4425,0,1.9,30.2995
4204,44728.51256,4203.224048,58232245,13.636948,0.882838,0.886244,75.841837,2.589492,-0.117566,-0.113913,19.912166,107.276408,0.956592,0.00956592,0,0.956592,-0.115859,0,400,73.1187,0,7.8,42.4425,0,1.9,30.2995
4231,44728.51287,4230.224048,58232272,17.622531,0.911264,0.91461,80.172557,2.620061,-0.089268,-0.085908,19.912166,113.413555,0.99727,0.0099727,0,0.99727,-0.087484,-0.01314,400,73.1291,0,7.8,42.4425,0,1.9,30.2995
4258,44728.51318,4257.224048,58232299,21.152739,0.936411,0.939642,84.05442,2.644714,-0.063998,-0.060729,19.912166,118.903123,1.03315,0.0103315,0,1.03315,-0.06242,-0.00741,400,73.1306,0,7.8,42.4425,0,1.9,30.2995
4285,44728.5135,4284.224048,58232326,24.960177,0.963385,0.966773,88.19218,2.670352,-0.037072,-0.033612,19.912166,124.750372,1.071526,0.01071526,0,1.071526,-0.035433,-0.01013,400,73.1344,0,7.8,42.4425,0,1.9,30.2995
4312,44728.51381,4311.224048,58232353,28.790549,0.990463,0.993846,92.408258,2.697963,-0.009452,-0.005837,19.912166,130.649165,1.110929,0.01110929,0,1.110929,-0.007886,-0.01109,400,73.1387,0,7.8,42.4425,0,1.9,30.2995
4339,44728.51412,4338.224048,58232380,32.637007,1.017758,1.020997,96.43894,2.723602,0.017314,0.020821,19.912166,136.428555,1.14919,0.0114919,0,1.14919,0.018933,-0.01224,400,73.1436,0,7.8,42.4425,0,1.9,30.2995
4366,44728.51443,4365.224048,58232407,36.414513,1.044515,1.047919,100.472081,2.750226,0.04412,0.04761,19.912166,142.133513,1.187697,0.01187697,0,1.187697,0.045913,-0.01213,400,73.1492,0,7.9,42.4425,0,1.9,30.2995
4393,44728.51475,4392.224048,58232434,40.159278,1.071505,1.074881,104.48729,2.773893,0.071109,0.074629,19.912166,147.80167,1.226034,0.01226034,0,1.226034,0.072633,-0.01479,400,73.1551,0,7.8,42.4425,0,1.9,30.2995
4420,44728.51506,4419.224048,58232461,44.003877,1.098733,1.102355,108.543275,2.80249,0.098364,0.102174,19.912166,153.547613,1.265337,0.01265337,0,1.265337,0.100199,-0.01395,400,73.162,0,7.8,42.4425,0,1.9,30.2995
4447,44728.51537,4446.224048,58232488,47.8338,1.125924,1.129966,112.57351,2.8301,0.125519,0.129653,19.912166,159.257292,1.304383,0.01304383,0,1.304383,0.127478,-0.01783,400,73.1694,0,7.8,42.4425,0,1.9,30.2995
4474,44728.51568,4473.224048,58232515,51.552089,1.152381,1.157325,116.533615,2.856725,0.152117,0.1571,19.912166,164.834442,1.342988,0.01342988,0,1.342988,0.154416,-0.01529,400,73.1772,0,7.8,42.4425,0,1.9,30.2995
4501,44728.516,4500.224048,58232542,55.207775,1.179142,1.184532,120.357065,2.880391,0.178875,0.184217,19.912166,170.249038,1.381544,0.01381544,0,1.381544,0.18162,-0.0185,400,73.1855,0,7.8,42.4425,0,1.9,30.2995
4528,44728.51631,4527.224048,58232569,58.729311,1.20647,1.211679,124.069038,2.907016,0.206125,0.211368,19.912166,175.507786,1.420424,0.01420424,0,1.420424,0.208707,-0.02032,400,73.1945,0,7.8,42.4425,0,1.9,30.2995
4555,44728.51662,4554.224048,58232596,62.157452,1.233832,1.238863,127.666908,2.931668,0.233504,0.238519,19.912166,180.599219,1.459371,0.01459371,0,1.459371,0.236018,-0.02114,400,73.2039,0,7.8,42.4425,0,1.9,30.2995
4582,44728.51693,4581.224048,58232623,65.373496,1.260864,1.265681,131.066815,2.957307,0.260481,0.265472,19.912166,185.414433,1.497802,0.01497802,0,1.497802,0.262877,-0.02273,400,73.214,0,7.8,42.4425,0,1.9,30.2995
4609,44728.51725,4608.224048,58232650,68.321875,1.287903,1.291848,134.16797,2.982946,0.287599,0.291538,19.912166,189.79938,1.535898,0.01535898,0,1.535898,0.289538,-0.02276,400,73.2243,0,7.8,42.4425,0,1.9,30.2995
4636,44728.51756,4635.224048,58232677,71.151316,1.315638,1.319045,137.174797,3.008584,0.315368,0.31882,19.912166,194.053117,1.575177,0.01575177,0,1.575177,0.317034,-0.02861,400,73.2361,0,7.8,42.4425,0,1.9,30.2995
4663,44728.51787,4662.224048,58232704,73.628028,1.342677,1.34579,139.828334,3.034223,0.342461,0.345543,19.912166,197.801459,1.613597,0.01613597,0,1.613597,0.343981,-0.02788,400,73.2488,0,7.8,42.4425,0,1.9,30.2995
4690,44728.51818,4689.224048,58232731,75.200286,1.367455,1.370185,141.496682,3.061833,0.366726,0.369341,19.912166,200.188315,1.648209,0.01648209,0,1.648209,0.368129,-0.03101,400,73.2633,0,7.8,42.4425,0,1.9,30.2995
4717,44728.5185,4716.224048,58232758,69.568437,1.340334,1.343055,136.060146,3.033237,0.339604,0.342223,19.912166,192.509703,1.609482,0.01609482,0,1.609482,0.341047,0.03032,400,73.2476,0,7.8,42.4425,0,1.9,30.2995
4744,44728.51881,4743.224048,58232785,64.505363,1.313381,1.316169,131.155557,3.005626,0.312527,0.315303,19.912166,185.586737,1.570882,0.01570882,0,1.570882,0.314027,0.01937,400,73.2384,0,7.8,42.4425,0,1.9,30.2995
4771,44728.51912,4770.224048,58232812,59.603808,1.286686,1.28971,126.48264,2.982946,0.286049,0.289073,19.912166,178.955531,1.533107,0.01533107,0,1.533107,0.287584,0.02018,400,73.2291,0,7.8,42.4425,0,1.9,30.2995
4798,44728.51943,4797.224048,58232839,54.756419,1.259651,1.263223,121.854911,2.956321,0.258952,0.262481,19.912166,172.404994,1.494769,0.01494769,0,1.494769,0.26072,0.01969,400,73.2201,0,7.8,42.4425,0,1.9,30.2995
4825,44728.51975,4824.224048,58232866,49.725988,1.231462,1.235509,117.05803,2.927724,0.230773,0.234706,19.912166,165.62506,1.454886,0.01454886,0,1.454886,0.23283,0.02215,400,73.2104,0,7.8,42.4425,0,1.9,30.2995
4852,44728.52006,4851.224048,58232893,45.008322,1.204874,1.209709,112.558778,2.904058,0.204063,0.209001,19.912166,159.261661,1.417425,0.01417425,0,1.417425,0.206607,0.02099,400,73.2013,0,7.8,42.4425,0,1.9,30.2995
4879,44728.52037,4878.224048,58232920,40.347198,1.17823,1.18334,108.176707,2.879405,0.177503,0.182672,19.912166,153.049105,1.379549,0.01379549,0,1.379549,0.180049,0.01876,400,73.1919,0,7.8,42.4425,0,1.9,30.2995
4906,44728.52068,4905.224048,58232947,35.487916,1.150786,1.155372,103.581417,2.851794,0.150116,0.154602,19.912166,146.555561,1.340135,0.01340135,0,1.340135,0.152499,0.02134,400,73.1821,0,7.6,42.4425,0,1.9,30.2995
4933,44728.521,4932.224048,58232974,30.886837,1.124918,1.128861,99.269214,2.826156,0.124002,0.128075,19.912166,140.456731,1.302439,0.01302439,0,1.302439,0.126117,0.0185,400,73.173,0,7.6,42.4425,0,1.9,30.2995
4960,44728.52131,4959.224048,58233001,26.160814,1.097123,1.100973,94.838168,2.797559,0.096449,0.100498,19.912166,134.187893,1.262947,0.01262947,0,1.262947,0.098473,0.01856,400,73.1632,0,7.6,42.4425,0,1.9,30.2995
4987,44728.52162,4986.224048,58233028,21.521653,1.069756,1.073964,90.546599,2.768962,0.069025,0.07338,19.912166,128.109824,1.224018,0.01224018,0,1.224018,0.071205,0.02267,400,73.1536,0,7.7,42.4425,0,1.9,30.2995
5014,44728.52193,5013.224048,58233055,17.196758,1.043853,1.048174,86.560457,2.745296,0.043046,0.047511,19.912166,122.472167,1.186952,0.01186952,0,1.186952,0.045276,0.01948,400,73.1443,0,7.6,42.4425,0,1.9,30.2995
5041,44728.52225,5040.224048,58233082,12.784735,1.016944,1.021285,82.497056,2.717685,0.016258,0.020558,19.912166,116.724393,1.148642,0.01148642,0,1.148642,0.018386,0.02035,400,73.1346,0,7.7,42.4425,0,1.9,30.2995
5068,44728.52256,5067.224048,58233109,8.354927,0.989687,0.994365,78.444815,2.69106,-0.011072,-0.006264,19.912166,110.984231,1.109839,0.01109839,0,1.109839,-0.008703,0.02163,400,73.1249,0,7.7,42.4425,0,1.9,30.2995
5095,44728.52287,5094.224048,58233136,3.926282,0.96199,0.966558,74.417647,2.665422,-0.038858,-0.034302,19.912166,105.291792,1.070155,0.01070155,0,1.070155,-0.036559,0.01928,400,73.1151,0,7.6,42.4425,0,1.9,30.2995
5122,44728.52318,5121.224048,58233163,-0.242469,0.935473,0.940091,70.652762,2.640769,-0.065358,-0.060696,19.912166,99.972572,1.032246,0.01032246,0,1.032246,-0.063018,0.01859,400,73.1058,0,7.6,42.4425,0,1.9,30.2995
5149,44728.5235,5148.224048,58233190,-4.519409,0.907694,0.912584,66.806835,2.612173,-0.093154,-0.08834,19.912166,94.522085,0.99281,0.0099281,0,0.99281,-0.090623,0.02478,400,73.096,0,7.6,42.4425,0,1.9,30.2995
5176,44728.52381,5175.224048,58233217,-8.518694,0.881412,0.88623,63.226589,2.586534,-0.119391,-0.114669,19.912166,89.462244,0.955221,0.00955221,0,0.955221,-0.116935,0.02073,400,73.0869,0,7.6,42.4425,0,1.9,30.2995
5203,44728.52412,5202.224048,58233244,-12.516858,0.854822,0.85967,59.670747,2.562868,-0.146002,-0.141162,19.912166,84.436038,0.917293,0.00917293,0,0.917293,-0.143469,0.02024,400,73.0777,0,7.6,42.4425,0,1.9,30.2995
5230,44728.52443,5229.224048,58233271,-16.559556,0.827461,0.832002,56.080229,2.535257,-0.173349,-0.168773,19.912166,79.354533,0.877923,0.00877923,0,0.877923,-0.171051,0.02206,400,73.068,0,7.7,42.4425,0,1.9,30.2995
5257,44728.52475,5256.224048,58233298,-20.598007,0.800517,0.803654,52.489018,2.507646,-0.200339,-0.197271,19.912166,74.270479,0.838388,0.00838388,0,0.838388,-0.198724,0.02392,400,73.0581,0,7.6,42.4425,0,1.9,30.2995
5284,44728.52506,5283.224048,58233325,-24.279995,0.774686,0.77735,49.26925,2.484966,-0.226119,-0.223567,19.912166,69.714842,0.801217,0.00801217,0,0.801217,-0.22477,0.02128,400,73.0489,0,7.6,42.4425,0,1.9,30.2995
5311,44728.52537,5310.224048,58233352,-27.9117,0.747809,0.750831,46.10918,2.457355,-0.253041,-0.250158,19.912166,65.250144,0.763089,0.00763089,0,0.763089,-0.251425,0.0216,400,73.0399,0,7.6,42.4425,0,1.9,30.2995
5338,44728.52568,5337.224048,58233379,-31.600223,0.718744,0.723092,42.898876,2.429745,-0.282154,-0.277769,19.912166,60.692108,0.722436,0.00722436,0,0.722436,-0.279915,0.02305,400,73.0306,0,7.6,42.4425,0,1.9,30.2995
5365,44728.526,5364.224048,58233406,-34.833573,0.692728,0.69832,40.102448,2.407064,-0.308168,-0.302454,19.912166,56.75018,0.686122,0.00686122,0,0.686122,-0.305369,0.01876,400,73.0226,0,7.6,42.4425,0,1.9,30.2995
5392,44728.52631,5391.224048,58233433,-34.852056,0.685838,0.69143,40.628019,2.400162,-0.314667,-0.309061,19.912166,57.449081,0.67666,0.0067666,0,0.67666,-0.311863,0.36604,440,72.4805,0,7.6,42.4425,0,1.9,30.2995
5419,44728.52662,5418.224048,58233460,-32.96125,0.690508,0.69491,42.967145,2.404106,-0.309848,-0.305248,19.912166,60.778956,0.682693,0.00682693,0,0.682693,-0.307702,-0.01042,500,71.6684,0,7.7,42.4425,0,1.9,30.2995
5446,44728.52693,5445.224048,58233487,-29.44819,0.717529,0.720994,46.882288,2.429745,-0.283048,-0.279643,19.912166,66.3187,0.72038,0.0072038,0,0.72038,-0.281237,0.041,500,71.6451,0,7.6,42.4425,0,1.9,30.2995
5473,44728.52725,5472.224048,58233514,-25.962769,0.745219,0.747411,50.899434,2.455383,-0.255379,-0.252492,19.912166,71.688543,0.75808,0.0075808,0,0.75808,-0.254797,0.02507,500,71.6321,0,7.6,42.4425,0,1.9,30.2995
5500,44728.52756,5499.224048,58233541,-22.025158,0.773525,0.77477,55.240581,2.48398,-0.226383,-0.224947,19.912166,78.1039,0.79956,0.0079956,0,0.79956,-0.225752,0.01659,500,71.6237,0,7.6,42.4425,0,1.9,30.2995
5527,44728.52787,5526.224048,58233568,-18.553673,0.798393,0.800053,59.048609,2.505674,-0.202086,-0.200328,19.912166,83.513882,0.834689,0.00834689,0,0.834689,-0.201308,0.01207,500,71.618,0,7.6,42.4425,0,1.9,30.2995
5554,44728.52818,5553.224048,58233595,-14.560186,0.824698,0.828184,63.421496,2.534271,-0.175683,-0.172224,19.912166,89.701723,0.873702,0.00873702,0,0.873702,-0.173957,0.00671,500,71.6143,0,7.6,42.4425,0,1.9,30.2995
5581,44728.5285,5580.224048,58233622,-10.674432,0.851822,0.855412,67.669974,2.559909,-0.148704,-0.144843,19.912166,95.714212,0.912398,0.00912398,0,0.912398,-0.146784,0.00115,500,71.6124,0,7.7,42.4425,0,1.9,30.2995
5608,44728.52881,5607.224048,58233649,-6.881475,0.878017,0.881577,71.796568,2.584562,-0.122427,-0.118778,19.912166,101.558944,0.94982,0.0094982,0,0.94982,-0.120553,0.00031,500,71.6113,0,7.6,42.4425,0,1.9,30.2995
5635,44728.52912,5634.224048,58233676,-2.943598,0.905066,0.908519,76.093841,2.612173,-0.0953,-0.091693,19.912166,107.631441,0.988527,0.00988527,0,0.988527,-0.093595,0,500,71.6108,0,7.6,42.4425,0,1.9,30.2995
5662,44728.52943,5661.224048,58233703,1.082546,0.932563,0.935969,80.410058,2.640769,-0.067861,-0.064312,19.912166,113.74373,1.027622,0.01027622,0,1.027622,-0.066108,0,500,71.6108,0,7.6,42.4425,0,1.9,30.2995
5689,44728.52975,5688.224048,58233730,4.970324,0.958911,0.96216,84.584376,2.666408,-0.041442,-0.038213,19.912166,119.65066,1.065406,0.01065406,0,1.065406,-0.039806,-0.03072,500,71.6185,0,7.6,42.4425,0,1.9,30.2995
5716,44728.53006,5715.224048,58233757,9.186632,0.987105,0.990549,89.042792,2.692047,-0.013295,-0.00988,19.912166,125.956806,1.105711,0.01105711,0,1.105711,-0.011593,-0.00112,500,71.623,0,7.6,42.4425,0,1.9,30.2995
5743,44728.53037,5742.224048,58233784,12.974645,1.012851,1.016366,93.085892,2.717685,0.012373,0.01589,19.912166,131.677475,1.142477,0.01142477,0,1.142477,0.014204,-0.00634,500,71.6258,0,7.7,42.4425,0,1.9,30.2995
5770,44728.53068,5769.224048,58233811,17.153579,1.040767,1.044277,97.474765,2.745296,0.040345,0.043896,19.912166,137.881524,1.182395,0.01182395,0,1.182395,0.042086,-0.0101,500,71.6296,0,7.7,42.4425,0,1.9,30.2995
5797,44728.531,5796.224048,58233838,21.064309,1.066891,1.070491,101.587668,2.769948,0.066597,0.070224,19.912166,143.70192,1.219901,0.01219901,0,1.219901,0.068369,-0.00865,500,71.6332,0,7.6,42.4425,0,1.9,30.2995
5824,44728.53131,5823.224048,58233865,25.277245,1.095286,1.098921,105.945663,2.798545,0.094712,0.098361,19.912166,149.890688,1.260188,0.01260188,0,1.260188,0.096535,-0.01491,500,71.6385,0,7.6,42.4425,0,1.9,30.2995
5851,44728.53162,5850.224048,58233892,29.16933,1.120798,1.124492,110.01608,2.824184,0.120468,0.12423,19.912166,155.629239,1.29698,0.0129698,0,1.29698,0.122343,-0.01343,500,71.6428,0,7.6,42.4425,0,1.9,30.2995
5878,44728.53193,5877.224048,58233919,33.254688,1.147719,1.151976,114.26302,2.851794,0.147414,0.15184,19.912166,161.635247,1.335887,0.01335887,0,1.335887,0.14954,-0.01239,500,71.6487,0,7.7,42.4425,0,1.9,30.2995
5905,44728.53225,5904.224048,58233946,37.18619,1.173661,1.178422,118.303037,2.876447,0.173321,0.178202,19.912166,167.342915,1.373258,0.01373258,0,1.373258,0.175741,-0.01097,500,71.6542,0,7.7,42.4425,0,1.9,30.2995
5932,44728.53256,5931.224048,58233973,41.282355,1.200518,1.205944,122.495955,2.902086,0.200233,0.205484,19.912166,173.284206,1.412085,0.01412085,0,1.412085,0.202869,-0.01581,500,71.6612,0,7.6,42.4425,0,1.9,30.2995
5959,44728.53287,5958.224048,58234000,45.210498,1.227365,1.23275,126.527997,2.926738,0.226978,0.232536,19.912166,178.976835,1.450331,0.01450331,0,1.450331,0.229756,-0.01589,500,71.6678,0,7.6,42.4425,0,1.9,30.2995
5986,44728.53318,5985.224048,58234027,49.213793,1.254952,1.259944,130.589366,2.952377,0.254592,0.259621,19.912166,184.734262,1.489448,0.01489448,0,1.489448,0.257024,-0.01491,500,71.6752,0,7.7,42.4425,0,1.9,30.2995
6013,44728.5335,6012.224048,58234054,53.046069,1.282462,1.286425,134.523722,2.977029,0.282241,0.286377,19.912166,190.29245,1.528276,0.01528276,0,1.528276,0.284218,-0.01838,500,71.6826,0,7.7,42.4425,0,1.9,30.2995
6040,44728.53381,6039.224048,58234081,56.799058,1.309642,1.313054,138.308431,3.002668,0.309348,0.312871,19.912166,195.649897,1.566628,0.01566628,0,1.566628,0.311014,-0.02001,500,71.6908,0,7.7,42.4425,0,1.9,30.2995
6067,44728.53412,6066.224048,58234108,60.472762,1.3365,1.340074,142.061679,3.029292,0.33617,0.339692,19.912166,200.964819,1.605015,0.01605015,0,1.605015,0.33792,-0.01833,500,71.699,0,7.7,42.4425,0,1.9,30.2995
6094,44728.53443,6093.224048,58234135,64.159086,1.36399,1.367664,145.81032,3.057889,0.363784,0.367238,19.912166,206.267197,1.644467,0.01644467,0,1.644467,0.365537,-0.01853,500,71.708,0,7.7,42.4425,0,1.9,30.2995
6121,44728.53475,6120.224048,58234162,67.484718,1.390322,1.394245,149.175403,3.081555,0.389927,0.393994,19.912166,211.030926,1.682117,0.01682117,0,1.682117,0.391892,-0.02134,500,71.7174,0,7.6,42.4425,0,1.9,30.2995
6148,44728.53506,6147.224048,58234189,70.856742,1.417883,1.422237,152.602387,3.109166,0.417557,0.422065,19.912166,215.868692,1.721856,0.01721856,0,1.721856,0.419726,-0.02565,500,71.7282,0,7.6,42.4425,0,1.9,30.2995
6175,44728.53537,6174.224048,58234216,73.698549,1.444291,1.448698,155.497058,3.134805,0.444139,0.448657,19.912166,219.977906,1.759843,0.01759843,0,1.759843,0.4463,-0.02339,500,71.7392,0,7.7,42.4425,0,1.9,30.2995
6202,44728.53568,6201.224048,58234243,76.177862,1.470582,1.475186,158.06945,3.160443,0.470344,0.474953,19.912166,223.605709,1.797452,0.01797452,0,1.797452,0.472578,-0.02893,500,71.7511,0,7.6,42.4425,0,1.9,30.2995
6229,44728.536,6228.224048,58234270,78.431604,1.497561,1.502733,160.390443,3.188054,0.49726,0.502597,19.912166,226.908512,1.836301,0.01836301,0,1.836301,0.49982,-0.03463,500,71.765,0,7.6,42.4425,0,1.9,30.2995
6256,44728.53631,6255.224048,58234297,80.396541,1.52435,1.529817,162.426007,3.214679,0.524191,0.529715,19.912166,229.780711,1.874945,0.01874945,0,1.874945,0.526912,-0.03654,500,71.7803,0,7.6,42.4425,0,1.9,30.2995
6283,44728.53662,6282.224048,58234324,81.924796,1.550372,1.557145,164.085605,3.239331,0.550194,0.557161,19.912166,232.116234,1.913075,0.01913075,0,1.913075,0.553578,-0.04016,500,71.7971,0,7.6,42.4425,0,1.9,30.2995
6310,44728.53693,6309.224048,58234351,83.190489,1.576888,1.584959,165.478456,3.266942,0.576783,0.584936,19.912166,234.08705,1.951889,0.01951889,0,1.951889,0.58075,-0.03952,500,71.8159,0,7.6,42.4425,0,1.9,30.2995
6337,44728.53725,6336.224048,58234378,83.92971,1.60358,1.611493,166.322537,3.29258,0.603387,0.611397,19.912166,235.302104,1.989781,0.01989781,0,1.989781,0.607257,-0.04401,500,71.8361,0,7.7,42.4425,0,1.9,30.2995
6364,44728.53756,6363.224048,58234405,84.391571,1.63029,1.638626,166.93629,3.316247,0.630061,0.638548,19.912166,236.169468,2.028118,0.02028118,0,2.028118,0.634092,-0.04981,500,71.8578,0,7.7,42.4425,0,1.9,30.2995
6391,44728.53787,6390.224048,58234432,84.601976,1.658469,1.667604,167.30828,3.339913,0.658261,0.667342,19.912166,236.698083,2.069138,0.02069138,0,2.069138,0.662825,-0.05754,500,71.8817,0,7.6,42.4425,0,1.9,30.2995
6418,44728.53818,6417.224048,58234459,83.837579,1.68436,1.695984,166.750009,3.360621,0.684227,0.695972,19.912166,235.903368,2.107848,0.02107848,0,2.107848,0.690057,-0.05786,500,71.9077,0,7.6,42.4425,0,1.9,30.2995
6445,44728.5385,6444.224048,58234486,82.085587,1.71083,1.724472,165.21632,3.387246,0.710598,0.724273,19.912166,233.744153,2.147127,0.02147127,0,2.147127,0.717577,-0.06304,500,71.9356,0,7.7,42.4425,0,1.9,30.2995
6472,44728.53881,6471.224048,58234513,77.922899,1.738716,1.752008,161.290602,3.416829,0.738542,0.752115,19.912166,228.196969,2.186744,0.02186744,0,2.186744,0.745242,-0.07743,500,71.9677,0,7.7,42.4425,0,1.9,30.2995
6499,44728.53912,6498.224048,58234540,67.720036,1.765194,1.779179,151.367386,3.44444,0.765078,0.778838,19.912166,214.152669,2.225146,0.02225146,0,2.225146,0.772012,-0.08823,500,72.0042,0,7.6,42.4425,0,1.9,30.2995
6506,44728.5392,6505.224048,58234547,63.104409,1.750975,1.764703,146.566757,3.43162,0.748477,0.761877,19.912166,207.517187,2.202018,0.02202018,0,2.202018,0.755624,-0.02597,499.5,72.0053,0,7.7,42.4425,0,1.9,30.2995