File: PB20_TRI_16622.csv
Index,Date,Time,Counter,FbLoad,Lvdt1,Lvdt2,Force(kN),Potm,LVDT1,LVDT2,Chain,Stress [MPa],Strain Ax. [%],Strain Ax [-],Strain Rad. [%],Strain Vol. [%],Gemidd,IFlow,IPress,IVol,FlowA,PressA,VolA,FlowB,PressB,VolB
0,44728.57628,0,58237751,-16.462828,0.031748,0.043931,0.195197,1.762156,-0.968934,-0.957024,19.912166,0.279586,-0.253129,-0.00253129,0,-0.253129,-0.962979,0,3,81.7698,0,7.7,42.4425,0,1.9,30.2995
25,44728.57656,24.246624,58237775,-15.996946,0.031871,0.044201,0.196794,1.760184,-0.968628,-0.956268,19.912166,0.26528,-0.253209,-0.00253209,0,-0.253209,-0.962605,0,3,81.7698,0,7.7,42.4425,0,1.9,30.2995
50,44728.57685,49.246624,58237800,-15.354789,0.044731,0.056864,0.411204,1.773989,-0.954966,-0.942857,19.912166,0.583178,-0.233302,-0.00233302,0,-0.233302,-0.948902,4.99954,6.4,81.2121,0,7.6,42.4425,0,1.9,30.2995
75,44728.57714,74.246624,58237825,-13.29929,0.117845,0.128631,1.919318,1.843016,-0.884252,-0.872154,19.912166,2.81204,-0.131364,-0.00131364,0,-0.131364,-0.878501,0.23141,20,80.3551,0,7.7,42.4425,0,1.9,30.2995
100,44728.57743,99.246624,58237850,-12.134382,0.136554,0.146547,2.73418,1.861752,-0.863445,-0.853484,19.912166,3.893758,-0.103968,-0.00103968,0,-0.103968,-0.858368,0.06918,30,80.0168,0,7.7,42.4425,0,1.9,30.2995
125,44728.57772,124.246624,58237875,-10.298855,0.164147,0.173668,4.163854,1.888377,-0.836644,-0.827057,19.912166,5.852555,-0.066522,-0.00066522,0,-0.066522,-0.831981,3.73344,53.6,79.4112,0,7.7,42.4425,0,1.9,30.2995
150,44728.57801,149.246624,58237900,-7.742382,0.195957,0.204918,6.191618,1.918946,-0.80583,-0.796948,19.912166,8.742578,-0.022291,-0.00022291,0,-0.022291,-0.801491,1.09605,78.5,78.8639,0,7.7,42.4425,0,1.9,30.2995
175,44728.5783,174.246624,58237925,-6.290864,0.209046,0.218135,7.363485,1.931765,-0.791343,-0.781828,19.912166,10.352505,-0.00224,-0.0000224,0,-0.00224,-0.787002,4.94046,111.1,78.236,0,7.7,42.4425,0,1.9,30.2995
200,44728.57859,199.246624,58237950,-5.4857,0.17582,0.226421,7.748053,1.941626,-0.823911,-0.774465,19.912166,10.980939,-0.019247,-0.00019247,0,-0.019247,-0.798772,0.04181,100,78.3803,0,7.6,42.4425,0,1.9,30.2995
225,44728.57888,224.246624,58237975,-4.987534,0.226994,0.227615,7.833571,1.941626,-0.773863,-0.773348,19.912166,11.08319,0.017207,0.00017207,0,0.017207,-0.773545,0.03376,100,78.3648,0,7.7,42.4425,0,1.9,30.2995
250,44728.57917,249.246624,58238000,-4.207856,0.231293,0.232228,8.269115,1.947543,-0.769197,-0.768088,19.912166,11.661428,0.023831,0.00023831,0,0.023831,-0.768869,0.02441,100,78.3533,0,7.7,42.4425,0,1.9,30.2995
275,44728.57946,274.246624,58238025,-1.91841,0.256159,0.257393,10.180533,1.970223,-0.744518,-0.743272,19.912166,14.396401,0.059692,0.00059692,0,0.059692,-0.743806,0.01476,100,78.3466,0,7.7,42.4425,0,1.9,30.2995
300,44728.57975,299.246624,58238050,0.441072,0.280814,0.282607,12.197597,1.993889,-0.719844,-0.718093,19.912166,17.28102,0.095384,0.00095384,0,0.095384,-0.718822,0.0112,100,78.3416,0,7.7,42.4425,0,1.9,30.2995
325,44728.58004,324.246624,58238075,2.968708,0.305985,0.307851,14.407875,2.020514,-0.694659,-0.692652,19.912166,20.379771,0.131327,0.00131327,0,0.131327,-0.693585,0.00828,100,78.3379,0,7.7,42.4425,0,1.9,30.2995
350,44728.58032,349.246624,58238100,5.643653,0.330952,0.332702,16.708827,2.045166,-0.669583,-0.667802,19.912166,23.636936,0.166988,0.00166988,0,0.166988,-0.668699,0.00518,100,78.3353,0,7.7,42.4425,0,1.9,30.2995
375,44728.58061,374.246624,58238125,8.390582,0.355743,0.357547,19.142674,2.069819,-0.644667,-0.642854,19.912166,27.065919,0.202343,0.00202343,0,0.202343,-0.643959,0.00318,100,78.3336,0,7.7,42.4425,0,1.9,30.2995
400,44728.5809,399.246624,58238150,11.30047,0.38119,0.382853,21.752898,2.093485,-0.619501,-0.617676,19.912166,30.76477,0.238358,0.00238358,0,0.238358,-0.6186,0.00104,100,78.333,0,7.7,42.4425,0,1.9,30.2995
425,44728.58119,424.246624,58238175,14.293078,0.406206,0.407842,24.449081,2.117151,-0.594435,-0.592728,19.912166,34.578705,0.274334,0.00274334,0,0.274334,-0.593556,0,100,78.3329,0,7.7,42.4425,0,1.9,30.2995
450,44728.58148,449.246624,58238200,17.379927,0.431459,0.43253,27.247606,2.139832,-0.569106,-0.567812,19.912166,38.528864,0.310151,0.00310151,0,0.310151,-0.568484,0,100,78.3329,0,7.7,42.4425,0,1.9,30.2995
475,44728.58177,474.246624,58238225,20.551337,0.456491,0.457622,30.155042,2.16547,-0.544041,-0.542733,19.912166,42.66282,0.345835,0.00345835,0,0.345835,-0.543398,0,100,78.3329,0,7.6,42.4425,0,1.9,30.2995
500,44728.58206,499.246624,58238250,23.837033,0.481278,0.482966,33.15566,2.191109,-0.519188,-0.517423,19.912166,46.897859,0.38163,0.0038163,0,0.38163,-0.518378,-0.01184,100,78.3374,0,7.7,42.4425,0,1.9,30.2995
525,44728.58235,524.246624,58238275,27.123274,0.505992,0.508218,36.182327,2.214775,-0.494499,-0.492376,19.912166,51.147473,0.417221,0.00417221,0,0.417221,-0.493496,-0.00761,100,78.341,0,7.7,42.4425,0,1.9,30.2995
550,44728.58264,549.246624,58238300,30.390253,0.531474,0.533028,39.219991,2.239428,-0.468898,-0.467395,19.912166,55.486809,0.453224,0.00453224,0,0.453224,-0.46808,-0.01042,100,78.3453,0,7.7,42.4425,0,1.9,30.2995
575,44728.58293,574.246624,58238325,33.626763,0.556851,0.557662,42.181663,2.265066,-0.443765,-0.44294,19.912166,59.689276,0.48897,0.0048897,0,0.48897,-0.443309,-0.01204,100,78.3501,0,7.7,42.4425,0,1.9,30.2995
600,44728.58322,599.246624,58238350,36.790633,0.581572,0.582333,45.185387,2.288732,-0.418677,-0.418222,19.912166,63.864111,0.524229,0.00524229,0,0.524229,-0.418601,-0.01546,100,78.356,0,7.7,42.4425,0,1.9,30.2995
625,44728.58351,624.246624,58238375,40.053267,0.607161,0.607236,48.151181,2.312399,-0.393389,-0.392978,19.912166,68.092049,0.56042,0.0056042,0,0.56042,-0.393279,-0.01789,100,78.3632,0,7.8,42.4425,0,1.9,30.2995
650,44728.5838,649.246624,58238400,43.193467,0.632753,0.632127,51.131894,2.337051,-0.367419,-0.368358,19.912166,72.433414,0.596942,0.00596942,0,0.596942,-0.367731,-0.02169,100,78.3715,0,7.7,42.4425,0,1.9,30.2995
675,44728.58409,674.246624,58238425,46.157562,0.657413,0.656771,53.963377,2.360718,-0.34285,-0.343607,19.912166,76.248325,0.631738,0.00631738,0,0.631738,-0.343357,-0.02302,100,78.3811,0,7.7,42.4425,0,1.9,30.2995
700,44728.58438,699.246624,58238450,49.072745,0.682493,0.681844,56.650092,2.386356,-0.318048,-0.318758,19.912166,80.110825,0.667207,0.00667207,0,0.667207,-0.318545,-0.02707,100,78.3924,0,7.7,42.4425,0,1.9,30.2995
725,44728.58466,724.246624,58238475,51.866039,0.707724,0.70698,59.394436,2.411995,-0.292571,-0.292889,19.912166,83.960499,0.703675,0.00703675,0,0.703675,-0.293018,-0.03226,100,78.4051,0,7.7,42.4425,0,1.9,30.2995
750,44728.58495,749.246624,58238500,54.435279,0.732159,0.732158,61.747585,2.434675,-0.26825,-0.268467,19.912166,87.3631,0.738947,0.00738947,0,0.738947,-0.268339,-0.03727,100,78.4199,0,7.7,42.4425,0,1.9,30.2995
775,44728.58524,774.246624,58238525,56.429185,0.754991,0.754652,63.594328,2.457355,-0.245883,-0.245984,19.912166,89.967129,0.770798,0.00770798,0,0.770798,-0.246204,-0.0388,100,78.4359,0,7.7,42.4425,0,1.9,30.2995
800,44728.58553,799.246624,58238550,52.060811,0.730102,0.729577,59.098912,2.431717,-0.270906,-0.271392,19.912166,83.582924,0.73482,0.0073482,0,0.73482,-0.27127,0.04135,100,78.4285,0,7.7,42.4425,0,1.9,30.2995
825,44728.58582,824.246624,58238575,48.010631,0.70538,0.704343,54.928826,2.40805,-0.295454,-0.296636,19.912166,77.78009,0.699651,0.00699651,0,0.699651,-0.295936,0.01928,100,78.4198,0,7.7,42.4425,0,1.9,30.2995
850,44728.58611,849.246624,58238600,44.055884,0.680359,0.679317,50.993269,2.384384,-0.320439,-0.321256,19.912166,72.066338,0.664,0.00664,0,0.664,-0.320702,0.01836,100,78.4121,0,7.7,42.4425,0,1.9,30.2995
875,44728.5864,874.246624,58238625,40.218984,0.655369,0.654411,47.033799,2.356773,-0.345568,-0.346434,19.912166,66.548757,0.628032,0.00628032,0,0.628032,-0.346096,0.01769,100,78.4047,0,7.8,42.4425,0,1.9,30.2995
900,44728.58669,899.246624,58238650,36.49357,0.630088,0.629718,43.287425,2.335079,-0.370931,-0.371415,19.912166,61.410369,0.592702,0.00592702,0,0.592702,-0.371064,0.01879,100,78.3969,0,7.7,42.4425,0,1.9,30.2995
925,44728.58698,924.246624,58238675,33.000227,0.60502,0.60524,39.820702,2.310427,-0.39565,-0.39564,19.912166,56.358346,0.557333,0.00557333,0,0.557333,-0.395581,0.01795,100,78.3892,0,7.7,42.4425,0,1.9,30.2995
950,44728.58727,949.246624,58238700,29.484001,0.579622,0.580278,36.335694,2.285774,-0.421217,-0.420621,19.912166,51.405279,0.52095,0.0052095,0,0.52095,-0.420925,0.0192,100,78.3813,0,7.7,42.4425,0,1.9,30.2995
975,44728.58756,974.246624,58238725,26.152071,0.55424,0.555307,32.98132,2.262108,-0.446726,-0.445734,19.912166,46.687892,0.485036,0.00485036,0,0.485036,-0.446199,0.0194,100,78.3733,0,7.6,42.4425,0,1.9,30.2995
1000,44728.58785,999.246624,58238750,22.971166,0.528912,0.531181,29.877658,2.238442,-0.472207,-0.469926,19.912166,42.278407,0.449544,0.00449544,0,0.449544,-0.471052,0.01992,100,78.3651,0,7.7,42.4425,0,1.9,30.2995
1025,44728.58814,1024.246624,58238775,19.881585,0.503595,0.506302,26.907294,2.212803,-0.497246,-0.494447,19.912166,38.029446,0.413684,0.00413684,0,0.413684,-0.496109,0.02061,100,78.3566,0,7.7,42.4425,0,1.9,30.2995
1050,44728.58843,1049.246624,58238800,16.924879,0.478667,0.481283,24.003146,2.189137,-0.522202,-0.519658,19.912166,34.012044,0.378512,0.00378512,0,0.378512,-0.52061,0.01969,100,78.3483,0,7.7,42.4425,0,1.9,30.2995
1075,44728.58872,1074.246624,58238825,14.039729,0.453856,0.455956,21.238376,2.164484,-0.547283,-0.545329,19.912166,30.091788,0.342345,0.00342345,0,0.342345,-0.546138,0.02018,100,78.3398,0,7.7,42.4425,0,1.9,30.2995
1100,44728.58901,1099.246624,58238850,11.726876,0.43238,0.434692,19.060081,2.14279,-0.568682,-0.566366,19.912166,26.981605,0.311741,0.00311741,0,0.311741,-0.567495,0.01633,100,78.3322,0,7.7,42.4425,0,1.9,30.2995
1125,44728.58929,1124.246624,58238875,13.147974,0.432704,0.434896,20.590574,2.14279,-0.568586,-0.566268,19.912166,29.133316,0.311638,0.00311638,0,0.311638,-0.567549,1.60782,157.9,77.3344,0,7.7,42.4425,0,1.9,30.2995
1150,44728.58958,1149.246624,58238900,15.098922,0.441446,0.443468,22.826019,2.152651,-0.558987,-0.556965,19.912166,32.273044,0.325123,0.00325123,0,0.325123,-0.558004,0.31675,200,76.593,0,7.7,42.4425,0,1.9,30.2995
1175,44728.58987,1174.246624,58238925,18.233085,0.466304,0.468914,26.127676,2.17829,-0.534172,-0.531557,19.912166,36.997855,0.361203,0.00361203,0,0.361203,-0.532853,0.05586,200,76.5683,0,7.7,42.4425,0,1.9,30.2995
1200,44728.59016,1199.246624,58238950,21.407651,0.490843,0.493854,29.514707,2.20097,-0.509741,-0.506707,19.912166,41.765629,0.396349,0.00396349,0,0.396349,-0.508114,0.03405,200,76.552,0,7.7,42.4425,0,1.9,30.2995
1225,44728.59045,1224.246624,58238975,24.706402,0.51636,0.518836,33.037001,2.225622,-0.484264,-0.481694,19.912166,46.697218,0.432107,0.00432107,0,0.432107,-0.48304,0.02339,200,76.5411,0,7.7,42.4425,0,1.9,30.2995
1250,44728.59074,1249.246624,58239000,27.963619,0.541523,0.543272,36.540881,2.249289,-0.45905,-0.457271,19.912166,51.674829,0.467744,0.00467744,0,0.467744,-0.458266,0.01749,200,76.5332,0,7.7,42.4425,0,1.9,30.2995
1275,44728.59103,1274.246624,58239025,31.321725,0.566771,0.567897,40.132591,2.272955,-0.433723,-0.432652,19.912166,56.790368,0.5035,0.005035,0,0.5035,-0.43314,0.01201,200,76.5276,0,7.7,42.4425,0,1.9,30.2995
1300,44728.59132,1299.246624,58239050,34.677638,0.591654,0.592537,43.774376,2.297607,-0.408807,-0.407966,19.912166,61.925213,0.538899,0.00538899,0,0.538899,-0.408323,0.0079,200,76.5239,0,7.7,42.4425,0,1.9,30.2995
1325,44728.59161,1324.246624,58239075,38.106895,0.616845,0.617353,47.483288,2.32226,-0.383409,-0.382953,19.912166,67.156929,0.574615,0.00574615,0,0.574615,-0.383224,0.00454,200,76.5216,0,7.7,42.4425,0,1.9,30.2995
1350,44728.5919,1349.246624,58239100,41.521162,0.641931,0.642053,51.15781,2.34494,-0.358667,-0.358432,19.912166,72.367559,0.61005,0.0061005,0,0.61005,-0.358589,0.00205,200,76.5206,0,7.7,42.4425,0,1.9,30.2995
1375,44728.59219,1374.246624,58239125,44.970995,0.666841,0.667022,54.882696,2.368606,-0.333719,-0.333681,19.912166,77.68907,0.645763,0.00645763,0,0.645763,-0.333556,0,200,76.5206,0,7.7,42.4425,0,1.9,30.2995
1400,44728.59248,1399.246624,58239150,48.446037,0.691997,0.692008,58.69341,2.396217,-0.308567,-0.308338,19.912166,83.004303,0.681341,0.00681341,0,0.681341,-0.308652,0,200,76.5206,0,7.7,42.4425,0,1.9,30.2995
1425,44728.59277,1424.246624,58239175,51.816781,0.716362,0.716732,62.407023,2.419884,-0.284018,-0.283521,19.912166,88.261105,0.716654,0.00716654,0,0.716654,-0.283964,-0.0196,200,76.5238,0,7.7,42.4425,0,1.9,30.2995
1450,44728.59306,1449.246624,58239200,55.28874,0.741348,0.742223,66.167884,2.444536,-0.259138,-0.258113,19.912166,93.566586,0.752532,0.00752532,0,0.752532,-0.258725,-0.00741,200,76.5273,0,7.7,42.4425,0,1.9,30.2995
1475,44728.59335,1474.246624,58239225,58.641299,0.766292,0.767845,69.820676,2.469188,-0.234196,-0.232836,19.912166,98.772178,0.788806,0.00788806,0,0.788806,-0.23336,-0.00996,200,76.531,0,7.7,42.4425,0,1.9,30.2995
1500,44728.59363,1499.246624,58239250,61.800227,0.791071,0.792691,73.328382,2.492855,-0.209396,-0.207658,19.912166,103.716597,0.824257,0.00824257,0,0.824257,-0.20861,-0.01169,200,76.5353,0,7.7,42.4425,0,1.9,30.2995
1525,44728.59392,1524.246624,58239275,64.839055,0.815516,0.817335,76.713221,2.515535,-0.184851,-0.182808,19.912166,108.500912,0.859397,0.00859397,0,0.859397,-0.184012,-0.01343,200,76.5403,0,7.8,42.4425,0,1.9,30.2995
1550,44728.59421,1549.246624,58239300,67.797978,0.840797,0.842611,80.001096,2.539201,-0.159726,-0.157728,19.912166,113.168133,0.895321,0.00895321,0,0.895321,-0.158854,-0.01589,200,76.5466,0,7.7,42.4425,0,1.9,30.2995
1575,44728.5945,1574.246624,58239325,70.5749,0.865393,0.867288,83.162935,2.56484,-0.134899,-0.132879,19.912166,117.627352,0.930785,0.00930785,0,0.930785,-0.134041,-0.01893,200,76.5538,0,7.7,42.4425,0,1.9,30.2995
1600,44728.59479,1599.246624,58239350,73.273938,0.891061,0.892531,86.2144,2.588506,-0.109405,-0.1077,19.912166,121.953921,0.966952,0.00966952,0,0.966952,-0.108704,-0.02284,200,76.5627,0,7.6,42.4425,0,1.9,30.2995
1625,44728.59508,1624.246624,58239375,75.679311,0.916056,0.917512,88.993669,2.613159,-0.084502,-0.082949,19.912166,125.869235,1.002591,0.01002591,0,1.002591,-0.083698,-0.02444,200,76.5728,0,7.6,42.4425,0,1.9,30.2995
1650,44728.59537,1649.246624,58239400,77.861045,0.940674,0.942398,91.561902,2.638797,-0.059835,-0.057968,19.912166,129.507165,1.038011,0.01038011,0,1.038011,-0.058971,-0.02971,200,76.5843,0,7.7,42.4425,0,1.9,30.2995
1675,44728.59566,1674.246624,58239425,75.212927,0.934842,0.935839,89.219298,2.629922,-0.06598,-0.0652,19.912166,126.242725,1.028826,0.01028826,0,1.028826,-0.065439,0.01479,200,76.5869,0,7.8,42.4425,0,1.9,30.2995
1700,44728.59595,1699.246624,58239450,70.268505,0.909962,0.910989,84.710432,2.60527,-0.090853,-0.089688,19.912166,119.861362,0.993365,0.00993365,0,0.993365,-0.090299,0.01902,200,76.577,0,7.7,42.4425,0,1.9,30.2995
1725,44728.59624,1724.246624,58239475,65.419344,0.884646,0.885728,80.253239,2.580618,-0.116075,-0.115162,19.912166,113.539859,0.957261,0.00957261,0,0.957261,-0.115554,0.01951,200,76.569,0,7.7,42.4425,0,1.9,30.2995
1750,44728.59653,1749.246624,58239500,60.714393,0.859673,0.861206,75.948564,2.554979,-0.141199,-0.139551,19.912166,107.461194,0.92185,0.0092185,0,0.92185,-0.140355,0.0194,200,76.561,0,7.7,42.4425,0,1.9,30.2995
1775,44728.59682,1774.246624,58239525,56.061859,0.834949,0.836346,71.734619,2.532299,-0.165942,-0.164631,19.912166,101.505124,0.886383,0.00886383,0,0.886383,-0.165122,0.0187,200,76.5531,0,7.7,42.4425,0,1.9,30.2995
1800,44728.59711,1799.246624,58239550,51.476947,0.810043,0.811155,67.581758,2.507646,-0.190754,-0.189711,19.912166,95.630659,0.850652,0.00850652,0,0.850652,-0.190128,0.01966,200,76.5449,0,7.7,42.4425,0,1.9,30.2995
1825,44728.5974,1824.246624,58239575,46.970354,0.78478,0.786135,63.514885,2.485952,-0.216134,-0.214922,19.912166,89.8716,0.814581,0.00814581,0,0.814581,-0.215422,0.01943,200,76.5366,0,7.8,42.4425,0,1.9,30.2995
1850,44728.59769,1849.246624,58239600,42.488228,0.759528,0.760545,59.451435,2.460314,-0.241602,-0.240758,19.912166,84.147694,0.778054,0.00778054,0,0.778054,-0.240964,0.01954,200,76.5285,0,7.7,42.4425,0,1.9,30.2995
1875,44728.59798,1874.246624,58239625,38.17043,0.734964,0.73555,55.666117,2.433689,-0.265866,-0.265344,19.912166,78.783008,0.743165,0.00743165,0,0.743165,-0.265326,0.01891,200,76.5203,0,7.7,42.4425,0,1.9,30.2995
1900,44728.59826,1899.246624,58239650,33.974011,0.7102,0.710848,51.944114,2.411995,-0.290806,-0.290292,19.912166,73.474205,0.707386,0.00707386,0,0.707386,-0.29042,0.01951,200,76.5121,0,7.7,42.4425,0,1.9,30.2995
1925,44728.59855,1924.246624,58239675,29.811949,0.684988,0.685707,48.316853,2.388328,-0.315902,-0.315011,19.912166,68.334012,0.671525,0.00671525,0,0.671525,-0.315461,0.02032,200,76.5037,0,7.7,42.4425,0,1.9,30.2995
1950,44728.59884,1949.246624,58239700,25.80281,0.659986,0.660891,44.799199,2.361704,-0.341063,-0.340156,19.912166,63.367868,0.635701,0.00635701,0,0.635701,-0.34064,0.01975,200,76.4954,0,7.7,42.4425,0,1.9,30.2995
1975,44728.59913,1974.246624,58239725,21.902164,0.634476,0.636356,41.335339,2.337051,-0.366964,-0.364907,19.912166,58.602453,0.60013,0.0060013,0,0.60013,-0.365761,0.01998,200,76.4871,0,7.7,42.4425,0,1.9,30.2995
2000,44728.59942,1999.246624,58239750,18.074767,0.608253,0.611364,38.123897,2.313385,-0.392624,-0.389658,19.912166,53.982102,0.563738,0.00563738,0,0.563738,-0.390973,0.0196,200,76.4789,0,7.7,42.4425,0,1.9,30.2995
2025,44728.59971,2024.246624,58239775,14.420165,0.583402,0.587342,34.98769,2.288732,-0.418021,-0.413916,19.912166,49.600362,0.528621,0.00528621,0,0.528621,-0.415687,0.01946,200,76.4708,0,7.7,42.4425,0,1.9,30.2995
2050,44728.6,2049.246624,58239800,10.911007,0.558553,0.562087,32.063279,2.267038,-0.442259,-0.4387,19.912166,45.37498,0.493199,0.00493199,0,0.493199,-0.440351,0.01972,200,76.4629,0,7.7,42.4425,0,1.9,30.2995
2075,44728.60029,2074.246624,58239825,7.33814,0.532946,0.536992,29.057653,2.242386,-0.468083,-0.464042,19.912166,41.195255,0.456788,0.00456788,0,0.456788,-0.465868,0.01864,200,76.4547,0,7.7,42.4425,0,1.9,30.2995
2100,44728.60058,2099.246624,58239850,4.041457,0.508117,0.511988,26.312389,2.216747,-0.492918,-0.489122,19.912166,37.263381,0.42123,0.0042123,0,0.42123,-0.490808,0.01795,200,76.4469,0,7.6,42.4425,0,1.9,30.2995
2125,44728.60087,2124.246624,58239875,0.804594,0.483135,0.487222,23.682866,2.194067,-0.517768,-0.513676,19.912166,33.534895,0.38566,0.0038566,0,0.38566,-0.515722,0.01809,200,76.4394,0,7.7,42.4425,0,1.9,30.2995
2150,44728.60116,2149.246624,58239900,-1.593281,0.464765,0.4689,21.8872,2.176317,-0.536175,-0.53205,19.912166,30.920776,0.359232,0.00359232,0,0.359232,-0.534136,0.01152,200,76.433,0,7.6,42.4425,0,1.9,30.2995
2175,44728.60145,2174.246624,58239925,-0.946989,0.465126,0.46934,23.093375,2.176317,-0.535426,-0.531228,19.912166,32.685538,0.360445,0.00360445,0,0.360445,-0.533279,4.92367,249.2,75.6982,0,7.7,42.4425,0,1.9,30.2995
2200,44728.60174,2199.246624,58239950,-0.37714,0.465196,0.469512,24.28211,2.176317,-0.535409,-0.5309,19.912166,34.334857,0.360441,0.00360441,0,0.360441,-0.533282,0.10888,300,74.8833,0,7.7,42.4425,0,1.9,30.2995
2225,44728.60203,2224.246624,58239975,2.447787,0.490299,0.494788,27.678076,2.199984,-0.510329,-0.505623,19.912166,39.158638,0.396499,0.00396499,0,0.396499,-0.508041,0.05322,300,74.8552,0,7.6,42.4425,0,1.9,30.2995
2250,44728.60232,2249.246624,58240000,5.325608,0.515494,0.51955,31.128552,2.225622,-0.485011,-0.48097,19.912166,44.043284,0.432218,0.00432218,0,0.432218,-0.482965,0.03289,300,74.8394,0,7.7,42.4425,0,1.9,30.2995
2275,44728.6026,2274.246624,58240025,8.290195,0.540718,0.544555,34.709277,2.249289,-0.459613,-0.455759,19.912166,49.11042,0.468452,0.00468452,0,0.468452,-0.457674,0.02339,300,74.8285,0,7.6,42.4425,0,1.9,30.2995
2300,44728.60289,2299.246624,58240050,11.248151,0.565529,0.569198,38.213901,2.270983,-0.435147,-0.431468,19.912166,54.007143,0.5032,0.005032,0,0.5032,-0.43335,0.01691,300,74.8207,0,7.7,42.4425,0,1.9,30.2995
2325,44728.60318,2324.246624,58240075,14.412918,0.590678,0.594438,41.965155,2.296621,-0.409755,-0.406093,19.912166,59.327621,0.539395,0.00539395,0,0.539395,-0.407958,0.01288,300,74.8148,0,7.7,42.4425,0,1.9,30.2995
2350,44728.60347,2349.246624,58240100,17.533055,0.616111,0.618565,45.556152,2.320288,-0.384536,-0.382098,19.912166,64.441791,0.574635,0.00574635,0,0.574635,-0.383285,0.00938,300,74.8106,0,7.6,42.4425,0,1.9,30.2995
2375,44728.60376,2374.246624,58240125,20.691193,0.641254,0.643297,49.270568,2.343954,-0.359365,-0.357413,19.912166,69.686679,0.610291,0.00610291,0,0.610291,-0.358422,0.00651,300,74.8076,0,7.7,42.4425,0,1.9,30.2995
2400,44728.60405,2399.246624,58240150,23.926166,0.666303,0.667803,53.096031,2.368606,-0.334283,-0.33276,19.912166,75.093203,0.645767,0.00645767,0,0.645767,-0.333553,0.00315,300,74.8059,0,7.7,42.4425,0,1.9,30.2995
2425,44728.60434,2424.246624,58240175,27.212931,0.691257,0.692467,56.924205,2.395231,-0.309229,-0.307911,19.912166,80.514358,0.681262,0.00681262,0,0.681262,-0.308707,0.00086,300,74.8052,0,7.7,42.4425,0,1.9,30.2995
2450,44728.60463,2449.246624,58240200,30.395433,0.715173,0.716541,60.622968,2.416925,-0.285371,-0.283981,19.912166,85.748911,0.715489,0.00715489,0,0.715489,-0.284748,0,300,74.8052,0,7.6,42.4425,0,1.9,30.2995
2475,44728.60492,2474.246624,58240225,33.899038,0.740975,0.741962,64.648539,2.440592,-0.259527,-0.258507,19.912166,91.436385,0.752163,0.00752163,0,0.752163,-0.259061,0,300,74.8052,0,7.7,42.4425,0,1.9,30.2995
2500,44728.60521,2499.246624,58240250,37.336787,0.76569,0.767473,68.559952,2.467216,-0.234811,-0.232935,19.912166,96.988122,0.788111,0.00788111,0,0.788111,-0.233961,-0.02131,300,74.8087,0,7.6,42.4425,0,1.9,30.2995
2525,44728.6055,2524.246624,58240275,40.687221,0.790266,0.792196,72.411725,2.489896,-0.210144,-0.208216,19.912166,102.433683,0.823367,0.00823367,0,0.823367,-0.209118,-0.00822,300,74.8131,0,7.7,42.4425,0,1.9,30.2995
2550,44728.60579,2549.246624,58240300,44.069474,0.814985,0.817167,76.293097,2.513563,-0.185461,-0.183005,19.912166,107.913942,0.858913,0.00858913,0,0.858913,-0.184291,-0.00938,300,74.8159,0,7.7,42.4425,0,1.9,30.2995
2575,44728.60608,2574.246624,58240325,47.547109,0.840108,0.842716,80.219,2.538215,-0.160362,-0.15763,19.912166,113.474249,0.89506,0.0089506,0,0.89506,-0.159049,-0.00993,300,74.8196,0,7.7,42.4425,0,1.9,30.2995
2600,44728.60637,2599.246624,58240350,50.858431,0.864644,0.867102,83.99901,2.560896,-0.135809,-0.13324,19.912166,118.812629,0.929973,0.00929973,0,0.929973,-0.134605,-0.01007,300,74.8232,0,7.6,42.4425,0,1.9,30.2995
2625,44728.60666,2624.246624,58240375,54.301636,0.88992,0.8923,87.874787,2.585548,-0.110504,-0.108226,19.912166,124.302176,0.966034,0.00966034,0,0.966034,-0.109338,-0.01201,300,74.8279,0,7.7,42.4425,0,1.9,30.2995
2650,44728.60694,2649.246624,58240400,57.58025,0.914519,0.91715,91.614895,2.611187,-0.085997,-0.083344,19.912166,129.60203,1.001288,0.01001288,0,1.001288,-0.084544,-0.01181,300,74.8327,0,7.7,42.4425,0,1.9,30.2995
2675,44728.60723,2674.246624,58240425,60.883728,0.939556,0.9423,95.350028,2.637811,-0.060833,-0.05787,19.912166,134.877089,1.03739,0.0103739,0,1.03739,-0.059405,-0.01268,300,74.8383,0,7.7,42.4425,0,1.9,30.2995
2700,44728.60752,2699.246624,58240450,64.090707,0.964658,0.967547,98.989604,2.659505,-0.035758,-0.032593,19.912166,140.029253,1.073283,0.01073283,0,1.073283,-0.034292,-0.01569,300,74.8445,0,7.7,42.4425,0,1.9,30.2995
2725,44728.60781,2724.246624,58240475,67.098274,0.989193,0.992291,102.406052,2.683172,-0.011105,-0.008039,19.912166,144.846241,1.108513,0.01108513,0,1.108513,-0.009568,-0.0161,300,74.851,0,7.6,42.4425,0,1.9,30.2995
2750,44728.6081,2749.246624,58240500,70.040746,1.014115,1.017402,105.748407,2.705852,0.01383,0.017139,19.912166,149.585255,1.144318,0.01144318,0,1.144318,0.015433,-0.01731,300,74.8582,0,7.7,42.4425,0,1.9,30.2995
2775,44728.60839,2774.246624,58240525,72.873875,1.039548,1.042771,109.051227,2.732477,0.039428,0.042877,19.912166,154.229419,1.180814,0.01180814,0,1.180814,0.041082,-0.02111,300,74.8665,0,7.7,42.4425,0,1.9,30.2995
2800,44728.60868,2799.246624,58240550,71.172902,1.039125,1.041686,107.632804,2.729518,0.038331,0.040872,19.912166,152.29386,1.179004,0.01179004,0,1.179004,0.039614,0.00773,300,74.8695,0,7.7,42.4425,0,1.9,30.2995
2825,44728.60897,2824.246624,58240575,66.041767,1.014346,1.016439,102.877902,2.702894,0.01348,0.01566,19.912166,145.590544,1.143253,0.01143253,0,1.143253,0.014597,0.01867,300,74.8567,0,7.7,42.4425,0,1.9,30.2995
2850,44728.60926,2849.246624,58240600,60.93722,0.988878,0.990871,98.199591,2.6812,-0.011869,-0.010011,19.912166,138.939001,1.106817,0.01106817,0,1.106817,-0.010914,0.01815,300,74.8493,0,7.8,42.4425,0,1.9,30.2995
2875,44728.60955,2874.246624,58240625,56.034787,0.963718,0.965646,93.664721,2.656547,-0.036981,-0.035124,19.912166,132.529605,1.070885,0.01070885,0,1.070885,-0.035929,0.01867,300,74.8419,0,7.7,42.4425,0,1.9,30.2995
2900,44728.60984,2899.246624,58240650,51.308047,0.939422,0.941022,89.324794,2.635839,-0.0613,-0.059809,19.912166,126.386175,1.035923,0.01035923,0,1.035923,-0.060445,0.01772,300,74.8348,0,7.6,42.4425,0,1.9,30.2995
2925,44728.61013,2924.246624,58240675,46.479637,0.913997,0.915826,84.904541,2.606256,-0.086744,-0.084889,19.912166,120.142322,0.999761,0.00999761,0,0.999761,-0.085807,0.01798,300,74.8275,0,7.7,42.4425,0,1.9,30.2995
2950,44728.61042,2949.246624,58240700,41.836193,0.889252,0.891203,80.643136,2.583576,-0.111591,-0.109804,19.912166,114.1171,0.964374,0.00964374,0,0.964374,-0.110509,0.01717,300,74.8205,0,7.7,42.4425,0,1.9,30.2995
2975,44728.61071,2974.246624,58240725,37.201755,0.864278,0.866481,76.429181,2.558923,-0.136551,-0.134292,19.912166,108.150104,0.928873,0.00928873,0,0.928873,-0.135428,0.01812,300,74.8131,0,7.7,42.4425,0,1.9,30.2995
3000,44728.611,2999.246624,58240750,32.66585,0.839231,0.841544,72.280833,2.535257,-0.161581,-0.159273,19.912166,102.271847,0.89326,0.0089326,0,0.89326,-0.160305,0.01711,300,74.8057,0,7.6,42.4425,0,1.9,30.2995
3025,44728.61129,3024.246624,58240775,28.145868,0.81402,0.816373,68.195615,2.510605,-0.186817,-0.184452,19.912166,96.48609,0.857175,0.00857175,0,0.857175,-0.185568,0.0176,300,74.7985,0,7.7,42.4425,0,1.9,30.2995
3050,44728.61157,3049.246624,58240800,23.854075,0.789379,0.791851,64.307231,2.48891,-0.211416,-0.208972,19.912166,90.998807,0.822121,0.00822121,0,0.822121,-0.210049,0.01676,300,74.7914,0,7.7,42.4425,0,1.9,30.2995
3075,44728.61186,3074.246624,58240825,19.390882,0.763664,0.766021,60.282934,2.463272,-0.237215,-0.235038,19.912166,85.304025,0.785209,0.00785209,0,0.785209,-0.236088,0.01789,300,74.7841,0,7.7,42.4425,0,1.9,30.2995
3100,44728.61215,3099.246624,58240850,15.213231,0.738958,0.7414,56.542523,2.437633,-0.261945,-0.259493,19.912166,80.012433,0.750029,0.00750029,0,0.750029,-0.260706,0.01731,300,74.777,0,7.7,42.4425,0,1.9,30.2995
3125,44728.61244,3124.246624,58240875,10.960646,0.713335,0.715616,52.744091,2.415939,-0.287474,-0.285231,19.912166,74.624037,0.7133,0.007133,0,0.7133,-0.286306,0.01754,300,74.7697,0,7.6,42.4425,0,1.9,30.2995
3150,44728.61273,3149.246624,58240900,6.922608,0.689541,0.690829,49.135034,2.391287,-0.311423,-0.310277,19.912166,69.530669,0.678332,0.00678332,0,0.678332,-0.310758,0.01795,300,74.7626,0,7.7,42.4425,0,1.9,30.2995
3175,44728.61302,3174.246624,58240925,2.927415,0.665265,0.665367,45.597495,2.364662,-0.335649,-0.335686,19.912166,64.52875,0.642968,0.00642968,0,0.642968,-0.335513,0.0172,300,74.7553,0,7.7,42.4425,0,1.9,30.2995
3200,44728.61331,3199.246624,58240950,-0.937657,0.641072,0.640324,42.207304,2.34001,-0.359918,-0.360601,19.912166,59.725974,0.607822,0.00607822,0,0.607822,-0.360235,0.01586,300,74.7483,0,7.6,42.4425,0,1.9,30.2995
3225,44728.6136,3224.246624,58240975,-4.603931,0.615454,0.615734,39.016459,2.317329,-0.385403,-0.384958,19.912166,55.203154,0.572063,0.00572063,0,0.572063,-0.385186,0.01531,300,74.7415,0,7.6,42.4425,0,1.9,30.2995
3250,44728.61389,3249.246624,58241000,-8.197719,0.588721,0.591625,35.87965,2.292677,-0.412241,-0.409314,19.912166,50.786177,0.535638,0.00535638,0,0.535638,-0.410653,0.01621,300,74.7348,0,7.6,42.4425,0,1.9,30.2995
3275,44728.61418,3274.246624,58241025,-11.621348,0.563382,0.567551,32.922526,2.269011,-0.437525,-0.433375,19.912166,46.581273,0.500272,0.00500272,0,0.500272,-0.43549,0.01569,300,74.7282,0,7.7,42.4425,0,1.9,30.2995
3300,44728.61447,3299.246624,58241050,-13.136763,0.550293,0.554801,31.755765,2.257177,-0.451674,-0.447509,19.912166,45.063478,0.481112,0.00481112,0,0.481112,-0.449137,1.54414,318.8,74.4576,0,7.6,42.4425,0,1.9,30.2995
3325,44728.61476,3324.246624,58241075,-12.179798,0.550752,0.554669,33.410487,2.258163,-0.449419,-0.445635,19.912166,47.243717,0.482857,0.00482857,0,0.482857,-0.447437,1.63938,378.1,73.6183,0,7.7,42.4425,0,1.9,30.2995
3350,44728.61505,3349.246624,58241100,-10.724817,0.560139,0.563686,35.276074,2.265066,-0.440446,-0.436892,19.912166,49.894853,0.495583,0.00495583,0,0.495583,-0.438682,0.07419,400,73.2802,0,7.6,42.4425,0,1.9,30.2995
3375,44728.61534,3374.246624,58241125,-7.507428,0.58526,0.588139,38.948893,2.291691,-0.41527,-0.412371,19.912166,55.082912,0.531012,0.00531012,0,0.531012,-0.41391,0.03483,400,73.2628,0,7.7,42.4425,0,1.9,30.2995
3400,44728.61563,3399.246624,58241150,-4.367893,0.610731,0.611598,42.582727,2.313385,-0.389646,-0.388771,19.912166,60.219687,0.566149,0.00566149,0,0.566149,-0.389266,0.02363,400,73.2517,0,7.7,42.4425,0,1.9,30.2995
3425,44728.61591,3424.246624,58241175,-0.930312,0.637191,0.63684,46.474911,2.338037,-0.363255,-0.363296,19.912166,65.731137,0.603024,0.00603024,0,0.603024,-0.363447,0.01679,400,73.244,0,7.8,42.4425,0,1.9,30.2995
3450,44728.6162,3449.246624,58241200,2.583809,0.661679,0.662196,50.433109,2.360718,-0.338853,-0.33825,19.912166,71.342015,0.638596,0.00638596,0,0.638596,-0.338566,0.01071,400,73.2388,0,7.7,42.4425,0,1.9,30.2995
3475,44728.61649,3474.246624,58241225,6.199507,0.686041,0.687672,54.502276,2.390301,-0.314434,-0.312775,19.912166,77.09101,0.674159,0.00674159,0,0.674159,-0.313586,0.00651,400,73.2352,0,7.7,42.4425,0,1.9,30.2995
3500,44728.61678,3499.246624,58241250,9.814389,0.71005,0.71296,58.530703,2.412981,-0.29046,-0.287367,19.912166,82.794121,0.709475,0.00709475,0,0.709475,-0.288958,0.00509,400,73.2326,0,7.7,42.4425,0,1.9,30.2995
3525,44728.61707,3524.246624,58241275,13.418813,0.735005,0.737932,62.599018,2.436647,-0.265345,-0.262485,19.912166,88.536769,0.745157,0.00745157,0,0.745157,-0.263868,0.0022,400,73.2314,0,7.7,42.4425,0,1.9,30.2995
3550,44728.61736,3549.246624,58241300,17.115301,0.760263,0.763234,66.66606,2.462286,-0.240189,-0.237208,19.912166,94.296289,0.781149,0.00781149,0,0.781149,-0.238786,0.00243,400,73.2308,0,7.7,42.4425,0,1.9,30.2995
3575,44728.61765,3574.246624,58241325,20.836935,0.785653,0.788658,70.827971,2.485952,-0.214757,-0.211536,19.912166,100.179427,0.817482,0.00817482,0,0.817482,-0.213353,0,400,73.2308,0,7.7,42.4425,0,1.9,30.2995
3600,44728.61794,3599.246624,58241350,24.441362,0.81005,0.81314,74.821099,2.508632,-0.190416,-0.187147,19.912166,105.837964,0.852372,0.00852372,0,0.852372,-0.188897,0,400,73.2308,0,7.7,42.4425,0,1.9,30.2995
3625,44728.61823,3624.246624,58241375,28.368841,0.836291,0.83936,79.085488,2.532299,-0.164359,-0.161213,19.912166,111.882751,0.889701,0.00889701,0,0.889701,-0.162876,-0.03205,400,73.2363,0,7.7,42.4425,0,1.9,30.2995
3650,44728.61852,3649.246624,58241400,31.920731,0.860205,0.863138,83.051827,2.556951,-0.140302,-0.13725,19.912166,117.478862,0.923946,0.00923946,0,0.923946,-0.138775,-0.00755,400,73.2407,0,7.7,42.4425,0,1.9,30.2995
3675,44728.61881,3674.246624,58241425,35.628514,0.885137,0.887736,87.139302,2.580618,-0.115378,-0.112499,19.912166,123.250109,0.959215,0.00959215,0,0.959215,-0.114043,-0.00779,400,73.2433,0,7.7,42.4425,0,1.9,30.2995
3700,44728.6191,3699.246624,58241450,39.395087,0.910186,0.912787,91.250808,2.60527,-0.090296,-0.087617,19.912166,129.080658,0.995097,0.00995097,0,0.995097,-0.089022,-0.0077,400,73.2461,0,7.7,42.4425,0,1.9,30.2995
3725,44728.61939,3724.246624,58241475,43.119681,0.935215,0.937662,95.309521,2.630909,-0.065262,-0.062734,19.912166,134.813648,1.030744,0.01030744,0,1.030744,-0.064031,-0.00805,400,73.2495,0,7.7,42.4425,0,1.9,30.2995
3750,44728.61968,3749.246624,58241500,46.858882,0.96025,0.96256,99.370899,2.654575,-0.040235,-0.037786,19.912166,140.569733,1.066516,0.01066516,0,1.066516,-0.039017,-0.00918,400,73.2532,0,7.7,42.4425,0,1.9,30.2995
3775,44728.61997,3774.246624,58241525,50.541172,0.985129,0.987515,103.370377,2.679227,-0.015296,-0.012838,19.912166,146.232502,1.102193,0.01102193,0,1.102193,-0.014055,-0.0121,400,73.2576,0,7.7,42.4425,0,1.9,30.2995
3800,44728.62026,3799.246624,58241550,54.265347,1.010419,1.013201,107.413205,2.701908,0.009964,0.012998,19.912166,151.93394,1.138565,0.01138565,0,1.138565,0.011451,-0.01094,400,73.2621,0,7.7,42.4425,0,1.9,30.2995
3825,44728.62054,3824.246624,58241575,57.906192,1.035198,1.038524,111.344646,2.727546,0.034763,0.037979,19.912166,157.506324,1.17428,0.0117428,0,1.17428,0.03641,-0.01332,400,73.2671,0,7.7,42.4425,0,1.9,30.2995
3850,44728.62083,3849.246624,58241600,61.45918,1.059915,1.063858,115.17079,2.750226,0.059528,0.063519,19.912166,162.913428,1.210105,0.01210105,0,1.210105,0.061483,-0.01358,400,73.2727,0,7.8,42.4425,0,1.9,30.2995
3875,44728.62112,3874.246624,58241625,64.861331,1.083959,1.089115,118.876611,2.773893,0.083583,0.088862,19.912166,168.157386,1.245379,0.01245379,0,1.245379,0.086163,-0.01419,400,73.2787,0,7.7,42.4425,0,1.9,30.2995
3900,44728.62141,3899.246624,58241650,68.158406,1.108324,1.114376,122.440914,2.80249,0.107947,0.113941,19.912166,173.20706,1.28064,0.0128064,0,1.28064,0.110853,-0.01534,400,73.2851,0,7.7,42.4425,0,1.9,30.2995
3925,44728.6217,3924.246624,58241675,71.314113,1.13305,1.139737,125.871083,2.828128,0.132778,0.139416,19.912166,178.045252,1.316659,0.01316659,0,1.316659,0.136167,-0.0172,400,73.2924,0,7.7,42.4425,0,1.9,30.2995
3950,44728.62199,3949.246624,58241700,74.3469,1.158452,1.165754,129.180042,2.853767,0.158239,0.165514,19.912166,182.740924,1.353381,0.01353381,0,1.353381,0.161801,-0.02174,400,73.301,0,7.7,42.4425,0,1.9,30.2995
3975,44728.62228,3974.246624,58241725,76.932293,1.183185,1.190173,132.034913,2.876447,0.182933,0.189937,19.912166,186.790631,1.388575,0.01388575,0,1.388575,0.186476,-0.02024,400,73.3097,0,7.7,42.4425,0,1.9,30.2995
4000,44728.62257,3999.246624,58241750,74.299442,1.178187,1.185099,129.62228,2.87053,0.177537,0.184217,19.912166,183.394659,1.380851,0.01380851,0,1.380851,0.181014,0.00845,400,73.308,0,7.7,42.4425,0,1.9,30.2995
4025,44728.62286,4024.246624,58241775,69.13356,1.15367,1.159626,124.743767,2.846864,0.15294,0.158743,19.912166,176.502768,1.345074,0.01345074,0,1.345074,0.155961,0.01778,400,73.2962,0,7.6,42.4425,0,1.9,30.2995
4050,44728.62315,4049.246624,58241800,64.085739,1.128895,1.134063,119.993807,2.821225,0.128151,0.1334,19.912166,169.768305,1.309165,0.01309165,0,1.309165,0.130733,0.01873,400,73.2889,0,7.6,42.4425,0,1.9,30.2995
4075,44728.62344,4074.246624,58241825,59.035784,1.103902,1.108297,115.221708,2.794601,0.103151,0.107433,19.912166,163.029164,1.27292,0.0127292,0,1.27292,0.105454,0.01885,400,73.2817,0,7.7,42.4425,0,1.9,30.2995
4100,44728.62373,4099.246624,58241850,54.339429,1.080611,1.084053,110.81923,2.769948,0.079915,0.083208,19.912166,156.788828,1.238969,0.01238969,0,1.238969,0.081688,0.01639,400,73.2749,0,7.7,42.4425,0,1.9,30.2995
4125,44728.62402,4124.246624,58241875,49.428984,1.055775,1.058506,106.201669,2.746282,0.055081,0.0578,19.912166,150.265658,1.20303,0.0120303,0,1.20303,0.056472,0.01778,400,73.2676,0,7.7,42.4425,0,1.9,30.2995
4150,44728.62431,4149.246624,58241900,44.715636,1.03135,1.033672,101.82716,2.72163,0.030591,0.032818,19.912166,144.072621,1.167747,0.01167747,0,1.167747,0.031703,0.01526,400,73.2606,0,7.7,42.4425,0,1.9,30.2995
4175,44728.6246,4174.246624,58241925,39.884892,1.005364,1.007498,97.292557,2.694019,0.004621,0.00672,19.912166,137.657098,1.130419,0.01130419,0,1.130419,0.005643,0.01705,400,73.2534,0,7.7,42.4425,0,1.9,30.2995
4200,44728.62488,4199.246624,58241950,35.393025,0.981326,0.98318,93.116587,2.673311,-0.0194,-0.01767,19.912166,131.757117,1.09587,0.0109587,0,1.09587,-0.018481,0.01534,400,73.2466,0,7.7,42.4425,0,1.9,30.2995
4225,44728.62517,4224.246624,58241975,30.854613,0.956799,0.958479,88.91674,2.65063,-0.044109,-0.042388,19.912166,125.810493,1.060554,0.01060554,0,1.060554,-0.04335,0.0163,400,73.2397,0,7.7,42.4425,0,1.9,30.2995
4250,44728.62546,4249.246624,58242000,26.144246,0.930796,0.932419,84.586824,2.626964,-0.070044,-0.068388,19.912166,119.688725,1.023459,0.01023459,0,1.023459,-0.069153,0.0174,400,73.2326,0,7.6,42.4425,0,1.9,30.2995
4275,44728.62575,4274.246624,58242025,21.773683,0.906333,0.908196,80.558611,2.601326,-0.094448,-0.092613,19.912166,113.987539,0.988712,0.00988712,0,0.988712,-0.093466,0.01711,400,73.2255,0,7.7,42.4425,0,1.9,30.2995
4300,44728.62604,4299.246624,58242050,17.402256,0.881863,0.883908,76.570902,2.576673,-0.118894,-0.11674,19.912166,108.336898,0.953948,0.00953948,0,0.953948,-0.117914,0.01679,400,73.2189,0,7.7,42.4425,0,1.9,30.2995
4325,44728.62633,4324.246624,58242075,13.00166,0.856801,0.858716,72.546849,2.551035,-0.144012,-0.142049,19.912166,102.651223,0.917848,0.00917848,0,0.917848,-0.143117,0.01725,400,73.2118,0,7.6,42.4425,0,1.9,30.2995
4350,44728.62662,4349.246624,58242100,8.680723,0.83176,0.833631,68.62819,2.52934,-0.169099,-0.167129,19.912166,97.10476,0.882122,0.00882122,0,0.882122,-0.168121,0.01679,400,73.2049,0,7.7,42.4425,0,1.9,30.2995
4375,44728.62691,4374.246624,58242125,4.379656,0.806505,0.808617,64.740149,2.504688,-0.194328,-0.192275,19.912166,91.60276,0.846236,0.00846236,0,0.846236,-0.193256,0.01531,400,73.1983,0,7.7,42.4425,0,1.9,30.2995
4400,44728.6272,4399.246624,58242150,0.282661,0.782078,0.783971,61.059872,2.481022,-0.218765,-0.216763,19.912166,86.404341,0.811239,0.00811239,0,0.811239,-0.217836,0.01508,400,73.1916,0,7.7,42.4425,0,1.9,30.2995
4425,44728.62749,4424.246624,58242175,-3.850669,0.756748,0.758865,57.361399,2.457355,-0.243996,-0.241941,19.912166,81.162558,0.775293,0.00775293,0,0.775293,-0.242846,0.01604,400,73.1848,0,7.7,42.4425,0,1.9,30.2995
4450,44728.62778,4449.246624,58242200,-7.85583,0.732021,0.73391,53.785621,2.432703,-0.268818,-0.266791,19.912166,76.097559,0.739818,0.00739818,0,0.739818,-0.26771,0.01505,400,73.1782,0,7.7,42.4425,0,1.9,30.2995
4475,44728.62807,4474.246624,58242225,-11.729906,0.707693,0.709275,50.3136,2.410023,-0.293165,-0.291706,19.912166,71.19389,0.704714,0.00704714,0,0.704714,-0.29229,0.0145,400,73.1716,0,7.6,42.4425,0,1.9,30.2995
4500,44728.62836,4499.246624,58242250,-15.792734,0.681771,0.68331,46.745681,2.38537,-0.319068,-0.317509,19.912166,66.14673,0.667644,0.00667644,0,0.667644,-0.318167,0.01668,400,73.1649,0,7.7,42.4425,0,1.9,30.2995
4525,44728.62865,4524.246624,58242275,-19.369542,0.65826,0.659783,43.620221,2.359732,-0.342713,-0.341241,19.912166,61.713403,0.633898,0.00633898,0,0.633898,-0.341765,0.01485,400,73.1585,0,7.7,42.4425,0,1.9,30.2995
4550,44728.62894,4549.246624,58242300,-23.11203,0.632921,0.63429,40.327577,2.336065,-0.368005,-0.366682,19.912166,57.071394,0.597696,0.00597696,0,0.597696,-0.367294,0.015,400,73.152,0,7.7,42.4425,0,1.9,30.2995
4575,44728.62923,4574.246624,58242325,-24.596037,0.620486,0.621475,39.305114,2.324232,-0.38091,-0.379304,19.912166,55.488208,0.578863,0.00578863,0,0.578863,-0.380362,0.99967,423.3,72.8274,0,7.7,42.4425,0,1.9,30.2995
4600,44728.62951,4599.246624,58242350,-22.656863,0.624211,0.625351,41.70116,2.329163,-0.376366,-0.375458,19.912166,59.071245,0.58547,0.0058547,0,0.58547,-0.37584,4.49159,495.4,71.8869,0,7.7,42.4425,0,1.9,30.2995
4625,44728.6298,4624.246624,58242375,-20.461149,0.639286,0.640787,44.393021,2.341982,-0.36112,-0.359516,19.912166,62.78355,0.60741,0.0060741,0,0.60741,-0.360403,0.05059,500,71.7869,0,7.7,42.4425,0,1.9,30.2995
4650,44728.63009,4649.246624,58242400,-16.909109,0.664448,0.666386,48.38235,2.366634,-0.336214,-0.334207,19.912166,68.430029,0.643259,0.00643259,0,0.643259,-0.335309,0.02887,500,71.7733,0,7.7,42.4425,0,1.9,30.2995
4675,44728.63038,4674.246624,58242425,-13.482966,0.688667,0.690442,52.272078,2.393259,-0.311797,-0.309817,19.912166,73.928534,0.677969,0.00677969,0,0.677969,-0.31093,0.01917,500,71.7645,0,7.6,42.4425,0,1.9,30.2995
4700,44728.63067,4699.246624,58242450,-9.539727,0.715626,0.717468,56.705206,2.418897,-0.28446,-0.282568,19.912166,80.18177,0.717032,0.00717032,0,0.717032,-0.283576,0.01236,500,71.7585,0,7.7,42.4425,0,1.9,30.2995
4725,44728.63096,4724.246624,58242475,-6.114009,0.739178,0.741435,60.500326,2.440592,-0.261321,-0.258935,19.912166,85.573146,0.750585,0.00750585,0,0.750585,-0.260181,0.00862,500,71.7545,0,7.7,42.4425,0,1.9,30.2995
4750,44728.63125,4749.246624,58242500,-2.304808,0.764783,0.767181,64.715652,2.46623,-0.235683,-0.23323,19.912166,91.544601,0.787232,0.00787232,0,0.787232,-0.234481,0.0035,500,71.7518,0,7.7,42.4425,0,1.9,30.2995
4775,44728.63154,4774.246624,58242525,1.279146,0.788909,0.791351,68.723702,2.487924,-0.211529,-0.209203,19.912166,97.196274,0.821729,0.00821729,0,0.821729,-0.21038,0.00373,500,71.75,0,7.7,42.4425,0,1.9,30.2995
4800,44728.63183,4799.246624,58242550,5.116129,0.814505,0.817018,72.92562,2.511591,-0.186214,-0.18363,19.912166,103.168113,0.858087,0.00858087,0,0.858087,-0.184876,0.00046,500,71.7491,0,7.7,42.4425,0,1.9,30.2995
4825,44728.63212,4824.246624,58242575,8.789248,0.838605,0.841013,77.010656,2.535257,-0.16188,-0.159273,19.912166,108.93554,0.892781,0.00892781,0,0.892781,-0.160643,0,500,71.749,0,7.7,42.4425,0,1.9,30.2995
4850,44728.63241,4849.246624,58242600,12.729453,0.864271,0.866743,81.316099,2.559909,-0.136146,-0.133635,19.912166,115.022203,0.929466,0.00929466,0,0.929466,-0.134944,-0.00002,500,71.749,0,7.7,42.4425,0,1.9,30.2995
4875,44728.6327,4874.246624,58242625,16.466997,0.888752,0.891336,85.41969,2.584562,-0.111769,-0.109147,19.912166,120.816564,0.964447,0.00964447,0,0.964447,-0.11046,-0.00002,500,71.749,0,7.7,42.4425,0,1.9,30.2995
4900,44728.63299,4899.246624,58242650,20.431256,0.914183,0.916751,89.738276,2.6102,-0.086091,-0.083442,19.912166,126.919614,1.001024,0.01001024,0,1.001024,-0.084817,-0.0156,500,71.7591,0,7.7,42.4425,0,1.9,30.2995
4925,44728.63328,4924.246624,58242675,24.184273,0.938803,0.9414,93.801213,2.633867,-0.061648,-0.058987,19.912166,132.687533,1.036081,0.01036081,0,1.036081,-0.060334,-0.00796,500,71.7621,0,7.7,42.4425,0,1.9,30.2995
4950,44728.63357,4949.246624,58242700,28.047587,0.963552,0.966052,97.956922,2.657533,-0.036832,-0.034335,19.912166,138.566643,1.071352,0.01071352,0,1.071352,-0.035644,-0.00689,500,71.7644,0,7.7,42.4425,0,1.9,30.2995
4975,44728.63385,4974.246624,58242725,32.015414,0.989087,0.991658,102.257196,2.682186,-0.011196,-0.008696,19.912166,144.628886,1.108028,0.01108028,0,1.108028,-0.009952,-0.00776,500,71.7675,0,7.7,42.4425,0,1.9,30.2995
5000,44728.63414,4999.246624,58242750,35.951872,1.01388,1.016912,106.497778,2.70388,0.013947,0.017041,19.912166,150.605574,1.14411,0.0114411,0,1.14411,0.015409,-0.00732,500,71.7711,0,7.7,42.4425,0,1.9,30.2995
5025,44728.63443,5024.246624,58242775,39.808138,1.038879,1.041925,110.57632,2.729518,0.03857,0.04166,19.912166,156.399133,1.179462,0.01179462,0,1.179462,0.040084,-0.01143,500,71.7747,0,7.7,42.4425,0,1.9,30.2995
5050,44728.63472,5049.246624,58242800,43.655586,1.063227,1.066665,114.668488,2.753185,0.062892,0.06628,19.912166,162.201831,1.214529,0.01214529,0,1.214529,0.064629,-0.01395,500,71.7787,0,7.7,42.4425,0,1.9,30.2995
5075,44728.63501,5074.246624,58242825,47.597852,1.087905,1.091917,118.854869,2.777837,0.087671,0.091721,19.912166,168.121779,1.25023,0.0125023,0,1.25023,0.089547,-0.00807,500,71.7831,0,7.7,42.4425,0,1.9,30.2995
5100,44728.6353,5099.246624,58242850,51.5772,1.112762,1.117752,123.04419,2.805448,0.112374,0.11736,19.912166,174.050353,1.28632,0.0128632,0,1.28632,0.114834,-0.01303,500,71.7882,0,7.7,42.4425,0,1.9,30.2995
5125,44728.63559,5124.246624,58242875,55.466477,1.137252,1.143146,127.146079,2.8301,0.137027,0.142933,19.912166,179.851397,1.322073,0.01322073,0,1.322073,0.139867,-0.01045,500,71.7928,0,7.7,42.4425,0,1.9,30.2995
5150,44728.63588,5149.246624,58242900,59.387777,1.162816,1.169327,131.278279,2.857711,0.162481,0.169064,19.912166,185.70331,1.358861,0.01358861,0,1.358861,0.165636,-0.01691,500,71.7988,0,7.7,42.4425,0,1.9,30.2995
5175,44728.63617,5174.246624,58242925,62.91987,1.187049,1.193526,135.006079,2.880391,0.186845,0.193388,19.912166,190.975949,1.393764,0.01393764,0,1.393764,0.190092,-0.01349,500,71.804,0,7.7,42.4425,0,1.9,30.2995
5200,44728.63646,5199.246624,58242950,66.291257,1.212559,1.217731,138.592033,2.903072,0.21226,0.217383,19.912166,196.061069,1.429129,0.01429129,0,1.429129,0.2148,-0.01343,500,71.8095,0,7.7,42.4425,0,1.9,30.2995
5225,44728.63675,5224.246624,58242975,69.730539,1.238301,1.242578,142.207547,2.927724,0.237983,0.2422,19.912166,201.168915,1.465065,0.01465065,0,1.465065,0.239955,-0.01656,500,71.816,0,7.6,42.4425,0,1.9,30.2995
5250,44728.63704,5249.246624,58243000,72.94034,1.263313,1.267833,145.618985,2.95139,0.262893,0.267576,19.912166,205.991963,1.500953,0.01500953,0,1.500953,0.265087,-0.01778,500,71.8227,0,7.7,42.4425,0,1.9,30.2995
5275,44728.63733,5274.246624,58243025,75.886959,1.288597,1.292435,148.772926,2.976043,0.288306,0.292195,19.912166,210.462038,1.53679,0.0153679,0,1.53679,0.290162,-0.01928,500,71.8306,0,7.7,42.4425,0,1.9,30.2995
5300,44728.63762,5299.246624,58243050,78.72598,1.314711,1.318202,151.778072,2.998723,0.314329,0.3179,19.912166,214.726969,1.573789,0.01573789,0,1.573789,0.316096,-0.02142,500,71.8395,0,7.7,42.4425,0,1.9,30.2995
5325,44728.63791,5324.246624,58243075,81.190308,1.33966,1.342535,154.44985,3.023376,0.33926,0.342158,19.912166,218.497336,1.608974,0.01608974,0,1.608974,0.340692,-0.02255,500,71.8489,0,7.7,42.4425,0,1.9,30.2995
5350,44728.63819,5349.246624,58243100,83.516054,1.364608,1.366691,156.973333,3.048028,0.364373,0.36635,19.912166,222.065951,1.644157,0.01644157,0,1.644157,0.365291,-0.02852,500,71.8594,0,7.7,42.4425,0,1.9,30.2995
5375,44728.63848,5374.246624,58243125,85.773754,1.390126,1.391935,159.437224,3.071694,0.389931,0.391824,19.912166,225.54072,1.680508,0.01680508,0,1.680508,0.390765,-0.02939,500,71.8712,0,7.7,42.4425,0,1.9,30.2995
5400,44728.63877,5399.246624,58243150,87.723644,1.414588,1.416197,161.626824,3.095361,0.414581,0.41605,19.912166,228.637177,1.715528,0.01715528,0,1.715528,0.415287,-0.02895,500,71.8839,0,7.7,42.4425,0,1.9,30.2995
5425,44728.63906,5424.246624,58243175,89.66387,1.440016,1.442171,163.787801,3.122972,0.439858,0.442181,19.912166,231.697322,1.751997,0.01751997,0,1.751997,0.440808,-0.03501,500,71.8976,0,7.7,42.4425,0,1.9,30.2995
5450,44728.63935,5449.246624,58243200,91.155827,1.463676,1.466489,165.501859,3.146638,0.463325,0.466275,19.912166,234.131866,1.786156,0.01786156,0,1.786156,0.464721,-0.03411,500,71.9123,0,7.6,42.4425,0,1.9,30.2995
5475,44728.63964,5474.246624,58243225,92.674476,1.488432,1.492269,167.280024,3.170304,0.488191,0.492341,19.912166,236.647666,1.822444,0.01822444,0,1.822444,0.490151,-0.03877,500,71.9278,0,7.7,42.4425,0,1.9,30.2995
5500,44728.63993,5499.246624,58243250,93.909387,1.513256,1.517164,168.774361,3.196929,0.512983,0.517158,19.912166,238.758979,1.857803,0.01857803,0,1.857803,0.514922,-0.03906,500,71.9448,0,7.6,42.4425,0,1.9,30.2995
5525,44728.64022,5524.246624,58243275,95.044639,1.539314,1.54285,170.166692,3.220595,0.539047,0.542764,19.912166,240.7323,1.894782,0.01894782,0,1.894782,0.540757,-0.04581,500,71.9629,0,7.6,42.4425,0,1.9,30.2995
5550,44728.64051,5549.246624,58243300,95.869588,1.56486,1.568456,171.287203,3.24722,0.564624,0.568206,19.912166,242.32184,1.931333,0.01931333,0,1.931333,0.566473,-0.04911,500,71.9819,0,7.7,42.4425,0,1.9,30.2995
5575,44728.6408,5574.246624,58243325,96.348883,1.589465,1.593112,172.079033,3.271872,0.589213,0.59299,19.912166,243.439815,1.966559,0.01966559,0,1.966559,0.590974,-0.04714,500,72.0016,0,7.7,42.4425,0,1.9,30.2995
5600,44728.64109,5599.246624,58243350,96.626794,1.613908,1.617897,172.698852,3.295539,0.61373,0.617609,19.912166,244.317547,2.001804,0.02001804,0,2.001804,0.615624,-0.05041,500,72.0217,0,7.7,42.4425,0,1.9,30.2995
5625,44728.64138,5624.246624,58243375,96.602481,1.638476,1.642529,173.05263,3.318219,0.638341,0.642459,19.912166,244.81445,2.036981,0.02036981,0,2.036981,0.640359,-0.05316,500,72.0435,0,7.7,42.4425,0,2.2,30.2995
5650,44728.64167,5649.246624,58243400,96.407306,1.663266,1.667816,173.227082,3.342871,0.663111,0.667868,19.912166,245.051224,2.072965,0.02072965,0,2.072965,0.665507,-0.0545,500,72.0662,0,7.6,42.4425,0,1.9,30.2995
5675,44728.64196,5674.246624,58243425,95.733601,1.688421,1.693679,172.960611,3.369496,0.688209,0.693441,19.912166,244.691309,2.109092,0.02109092,0,2.109092,0.690774,-0.0593,500,72.0908,0,7.6,42.4425,0,1.9,30.2995
5700,44728.64225,5699.246624,58243450,94.696574,1.714226,1.719867,172.331565,3.395135,0.714089,0.719869,19.912166,243.810499,2.146354,0.02146354,0,2.146354,0.716858,-0.06159,500,72.1165,0,7.7,42.4425,0,1.9,30.2995
5725,44728.64254,5724.246624,58243475,93.107111,1.738976,1.744639,171.213739,3.422745,0.738752,0.744686,19.912166,242.218349,2.181641,0.02181641,0,2.181641,0.741558,-0.05719,500,72.141,0,7.7,42.4425,0,1.9,30.2995
5750,44728.64282,5749.246624,58243500,90.33908,1.763819,1.769724,168.910534,3.443453,0.763585,0.769634,19.912166,238.965696,2.217379,0.02217379,0,2.217379,0.766575,-0.06796,500,72.1675,0,7.6,42.4425,0,1.9,30.2995
5775,44728.64311,5774.246624,58243525,85.571784,1.787961,1.795773,164.635029,3.468106,0.787846,0.795865,19.912166,232.927787,2.253284,0.02253284,0,2.253284,0.791752,-0.07541,500,72.1979,0,7.7,42.4425,0,1.9,30.2995
5800,44728.6434,5799.246624,58243550,77.959704,1.812579,1.819303,157.542911,3.491772,0.812233,0.81894,19.912166,222.906325,2.287379,0.02287379,0,2.287379,0.815575,-0.07286,500,72.2279,0,7.7,42.4425,0,1.9,30.2995
5812,44728.64354,5811.246624,58243562,76.151743,1.824337,1.831006,156.015898,3.501633,0.824123,0.830773,19.912166,220.731735,2.30429,0.0230429,0,2.30429,0.827413,-0.04427,500,72.2376,0,7.7,42.4425,0,2.2,30.2995