File: PB21_TRI_16622.csv
Index,Date,Time,Counter,FbLoad,Lvdt1,Lvdt2,Force(kN),Potm,LVDT1,LVDT2,Chain,Stress [MPa],Strain Ax. [%],Strain Ax [-],Strain Rad. [%],Strain Vol. [%],Gemidd,IFlow,IPress,IVol,FlowA,PressA,VolA,FlowB,PressB,VolB
0,44728.66546,0,58245456,-81.443398,0.111458,0.10567,0.76101,1.748351,-0.890523,-0.896511,19.912166,1.10792,-0.153633,-0.00153633,0,-0.153633,-0.893517,-0.01071,5,81.0411,0,7.7,42.4425,0,2.3,30.2995
19,44728.66567,18.679913,58245474,-80.540392,0.110556,0.104764,0.77398,1.750323,-0.889643,-0.895755,19.912166,1.159723,-0.151069,-0.00151069,0,-0.151069,-0.891339,-0.0057,5,81.0428,0,7.7,42.4425,0,2.3,30.2995
38,44728.66589,37.679913,58245493,-78.293504,0.155699,0.149274,2.044172,1.792725,-0.84538,-0.852662,19.912166,2.899217,-0.089903,-0.00089903,0,-0.089903,-0.848415,-0.19055,20,80.3409,0,7.7,42.4425,0,2.3,30.2995
57,44728.66611,56.679913,58245512,-74.993953,0.199781,0.192467,4.438969,1.835127,-0.800384,-0.807434,19.912166,6.313026,-0.026428,-0.00026428,0,-0.026428,-0.80409,3.24344,55.2,79.4514,0,7.7,42.4425,0,2.3,30.2995
76,44728.66633,75.679913,58245531,-72.266347,0.226692,0.219214,6.12241,1.861752,-0.774662,-0.781401,19.912166,8.704251,0.010833,0.00010833,0,0.010833,-0.77831,-0.06718,80,78.8951,0,7.7,42.4425,0,2.3,30.2995
95,44728.66655,94.679913,58245550,-69.841203,0.245747,0.238217,7.615468,1.879502,-0.755143,-0.761975,19.912166,10.814902,0.038419,0.00038419,0,0.038419,-0.758809,0.26208,100,78.4841,0,7.6,42.4425,0,2.3,30.2995
114,44728.66677,113.679913,58245569,-67.794206,0.258817,0.251186,8.73984,1.889363,-0.741723,-0.74909,19.912166,12.369914,0.057378,0.00057378,0,0.057378,-0.745519,0.05172,100,78.4673,0,7.7,42.4425,0,2.3,30.2995
133,44728.66699,132.679913,58245588,-65.255779,0.278289,0.270521,10.265275,1.908099,-0.7224,-0.730255,19.912166,14.552531,0.084723,0.00084723,0,0.084723,-0.726284,0.03339,100,78.4556,0,7.7,42.4425,0,2.3,30.2995
152,44728.66721,151.679913,58245607,-62.668894,0.297614,0.289578,11.904473,1.925848,-0.703059,-0.711289,19.912166,16.792845,0.111871,0.00111871,0,0.111871,-0.707344,0.02449,100,78.4474,0,7.7,42.4425,0,2.3,30.2995
171,44728.66743,170.679913,58245626,-60.053866,0.316431,0.308447,13.559161,1.94557,-0.684025,-0.691929,19.912166,19.170387,0.139197,0.00139197,0,0.139197,-0.688166,0.01867,100,78.4411,0,7.7,42.4425,0,2.3,30.2995
190,44728.66765,189.679913,58245645,-57.327739,0.335785,0.327451,15.303096,1.962334,-0.664879,-0.673292,19.912166,21.67817,0.166386,0.00166386,0,0.166386,-0.669152,0.0143,100,78.4363,0,7.6,42.4425,0,2.3,30.2995
209,44728.66787,208.679913,58245664,-54.510371,0.354728,0.346454,17.113688,1.98107,-0.645825,-0.654819,19.912166,24.285267,0.193524,0.00193524,0,0.193524,-0.650124,0.01033,100,78.4328,0,7.6,42.4425,0,2.3,30.2995
228,44728.66809,227.679913,58245683,-51.635679,0.373808,0.365356,18.99893,1.997834,-0.626839,-0.635459,19.912166,26.950081,0.220692,0.00220692,0,0.220692,-0.63111,0.00677,100,78.4303,0,7.6,42.4425,0,2.3,30.2995
247,44728.66831,246.679913,58245702,-48.719903,0.392855,0.384298,21.035334,2.018542,-0.607781,-0.616098,19.912166,29.713403,0.247933,0.00247933,0,0.247933,-0.61202,0.00437,100,78.4288,0,7.6,42.4425,0,2.3,30.2995
266,44728.66853,265.679913,58245721,-45.737514,0.411859,0.403221,23.060227,2.035305,-0.588702,-0.597067,19.912166,32.617568,0.275199,0.00275199,0,0.275199,-0.592951,0.00228,100,78.428,0,7.7,42.4425,0,2.3,30.2995
285,44728.66875,284.679913,58245740,-42.713929,0.430874,0.422009,25.084916,2.053055,-0.569817,-0.578725,19.912166,35.452748,0.301893,0.00301893,0,0.301893,-0.574134,0.00002,100,78.4279,0,7.7,42.4425,0,2.3,30.2995
304,44728.66897,303.679913,58245759,-39.64512,0.449745,0.440906,27.210135,2.073763,-0.550712,-0.559628,19.912166,38.516865,0.329442,0.00329442,0,0.329442,-0.554981,0,100,78.4279,0,7.7,42.4425,0,2.3,30.2995
323,44728.66919,322.679913,58245778,-36.456164,0.468991,0.460093,29.374477,2.089541,-0.531626,-0.540662,19.912166,41.590028,0.356324,0.00356324,0,0.356324,-0.536166,0,100,78.4279,0,7.7,42.4425,0,2.3,30.2995
342,44728.66941,341.679913,58245797,-33.310546,0.487883,0.479031,31.592933,2.104332,-0.512702,-0.521795,19.912166,44.714352,0.383437,0.00383437,0,0.383437,-0.517185,0,100,78.4279,0,7.7,42.4425,0,2.3,30.2995
361,44728.66963,360.679913,58245816,-30.112719,0.506783,0.497937,33.871538,2.126026,-0.49375,-0.502467,19.912166,47.908278,0.410726,0.00410726,0,0.410726,-0.498082,-0.01317,100,78.4312,0,7.7,42.4425,0,2.3,30.2995
380,44728.66985,379.679913,58245835,-26.885177,0.525891,0.517009,36.174523,2.14279,-0.474538,-0.483337,19.912166,51.144798,0.437788,0.00437788,0,0.437788,-0.479139,-0.00889,100,78.434,0,7.7,42.4425,0,2.3,30.2995
399,44728.67007,398.679913,58245854,-23.634039,0.544854,0.536004,38.45631,2.159554,-0.455558,-0.464535,19.912166,54.375756,0.465165,0.00465165,0,0.465165,-0.459975,-0.00984,100,78.4371,0,7.8,42.4425,0,2.3,30.2995
418,44728.67029,417.679913,58245873,-20.55785,0.563437,0.554934,40.639259,2.17829,-0.43706,-0.44603,19.912166,57.398522,0.491361,0.00491361,0,0.491361,-0.441304,-0.01175,100,78.4406,0,7.7,42.4425,0,2.3,30.2995
437,44728.67051,436.679913,58245892,-17.369612,0.582445,0.573904,42.933103,2.197025,-0.417982,-0.426406,19.912166,60.704445,0.519097,0.00519097,0,0.519097,-0.422149,-0.01306,100,78.4447,0,7.7,42.4425,0,2.3,30.2995
456,44728.67073,455.679913,58245911,-14.224626,0.6011,0.592995,45.07656,2.217733,-0.399216,-0.407572,19.912166,63.780032,0.546017,0.00546017,0,0.546017,-0.403357,-0.01456,100,78.4493,0,7.7,42.4425,0,2.3,30.2995
475,44728.67095,474.679913,58245930,-11.097118,0.620514,0.612165,47.351392,2.235483,-0.380119,-0.388212,19.912166,66.994513,0.573356,0.00573356,0,0.573356,-0.384241,-0.01856,100,78.4548,0,7.7,42.4425,0,2.3,30.2995
494,44728.67117,493.679913,58245949,-7.956386,0.639575,0.631129,49.538177,2.255205,-0.360922,-0.369607,19.912166,70.150344,0.600724,0.00600724,0,0.600724,-0.365083,-0.0196,100,78.4608,0,7.6,42.4425,0,2.3,30.2995
513,44728.67139,512.679913,58245968,-4.981131,0.658351,0.650002,51.753101,2.273941,-0.342111,-0.350148,19.912166,73.181947,0.627685,0.00627685,0,0.627685,-0.346261,-0.02145,100,78.4676,0,7.7,42.4425,0,2.3,30.2995
532,44728.67161,531.679913,58245987,-2.034961,0.677271,0.669031,53.791888,2.292677,-0.323112,-0.331051,19.912166,76.10778,0.654798,0.00654798,0,0.654798,-0.327225,-0.02626,100,78.4752,0,7.7,42.4425,0,2.3,30.2995
551,44728.67183,550.679913,58246006,0.818669,0.696048,0.687843,55.773287,2.311413,-0.304282,-0.312118,19.912166,78.932174,0.681704,0.00681704,0,0.681704,-0.308235,-0.02782,100,78.4841,0,7.6,42.4425,0,2.3,30.2995
570,44728.67205,569.679913,58246025,3.764626,0.71519,0.707142,57.692183,2.330149,-0.285579,-0.293317,19.912166,81.69586,0.708787,0.00708787,0,0.708787,-0.289794,-0.03113,100,78.494,0,7.7,42.4425,0,2.3,30.2995
589,44728.67227,588.679913,58246044,6.407195,0.734024,0.726131,59.654305,2.348884,-0.266326,-0.274088,19.912166,84.405138,0.736241,0.00736241,0,0.736241,-0.270221,-0.03663,100,78.5048,0,7.7,42.4425,0,2.3,30.2995
608,44728.67249,607.679913,58246063,9.033098,0.752918,0.745096,61.402329,2.366634,-0.247465,-0.255549,19.912166,86.957303,0.763222,0.00763222,0,0.763222,-0.251404,-0.0388,100,78.5167,0,7.7,42.4425,0,2.3,30.2995
627,44728.67271,626.679913,58246082,11.543539,0.772148,0.764407,63.19165,2.386356,-0.228467,-0.235926,19.912166,89.364411,0.790405,0.00790405,0,0.790405,-0.232526,-0.04439,100,78.5301,0,7.6,42.4425,0,2.3,30.2995
646,44728.67293,645.679913,58246101,14.011614,0.790609,0.783047,64.763527,2.405092,-0.209565,-0.21719,19.912166,91.665395,0.81748,0.0081748,0,0.81748,-0.213287,-0.05062,100,78.5454,0,7.7,42.4425,0,2.3,30.2995
665,44728.67315,664.679913,58246120,16.246524,0.809474,0.802138,66.190244,2.422842,-0.191189,-0.198224,19.912166,93.699908,0.84419,0.0084419,0,0.84419,-0.194657,-0.05282,100,78.562,0,7.7,42.4425,0,2.3,30.2995
684,44728.67337,683.679913,58246139,14.751068,0.801415,0.793901,63.976032,2.413967,-0.199485,-0.207198,19.912166,90.472018,0.83201,0.0083201,0,0.83201,-0.203183,-0.00011,100,78.5676,0,7.7,42.4425,0,2.3,30.2995
703,44728.67359,702.679913,58246158,12.343445,0.782715,0.774916,60.799079,2.395231,-0.218294,-0.225736,19.912166,86.075843,0.805029,0.00805029,0,0.805029,-0.222115,0.02571,100,78.5599,0,7.7,42.4425,0,2.3,30.2995
722,44728.67381,721.679913,58246177,10.022725,0.763724,0.756002,57.756285,2.375509,-0.23698,-0.244636,19.912166,81.70523,0.778135,0.00778135,0,0.778135,-0.240785,0.0192,100,78.5539,0,7.6,42.4425,0,2.3,30.2995
741,44728.67403,740.679913,58246196,7.735959,0.744674,0.737001,54.720331,2.358745,-0.256264,-0.264325,19.912166,77.379271,0.750473,0.00750473,0,0.750473,-0.260259,0.0194,100,78.5478,0,7.7,42.4425,0,2.3,30.2995
760,44728.67425,759.679913,58246215,5.512481,0.725842,0.717814,51.800107,2.34001,-0.275138,-0.283193,19.912166,73.282211,0.723605,0.00723605,0,0.723605,-0.279065,0.01948,100,78.5415,0,7.6,42.4425,0,2.3,30.2995
779,44728.67447,778.679913,58246234,3.323598,0.70684,0.698776,48.889078,2.323246,-0.293974,-0.302158,19.912166,69.242002,0.696493,0.00696493,0,0.696493,-0.298095,0.02047,100,78.535,0,7.7,42.4425,0,2.3,30.2995
798,44728.67469,797.679913,58246253,1.163247,0.687671,0.679479,46.172111,2.302538,-0.313251,-0.321157,19.912166,65.23834,0.668959,0.00668959,0,0.668959,-0.317254,0.0205,100,78.5284,0,7.7,42.4425,0,2.3,30.2995
817,44728.67491,816.679913,58246272,-0.884804,0.668622,0.660419,43.364345,2.28676,-0.332319,-0.340616,19.912166,61.475152,0.642006,0.00642006,0,0.642006,-0.336186,0.02116,100,78.5219,0,7.7,42.4425,0,2.3,30.2995
836,44728.67513,835.679913,58246291,-2.843413,0.650135,0.641505,40.79177,2.269011,-0.35097,-0.359516,19.912166,57.748242,0.615119,0.00615119,0,0.615119,-0.355337,0.02111,100,78.5151,0,7.7,42.4425,0,2.3,30.2995
855,44728.67535,854.679913,58246310,-4.875287,0.630705,0.622319,38.224746,2.247316,-0.370263,-0.379666,19.912166,54.059407,0.587356,0.00587356,0,0.587356,-0.374378,0.02281,100,78.5079,0,7.6,42.4425,0,2.3,30.2995
874,44728.67557,873.679913,58246329,-6.643227,0.612183,0.603116,35.786835,2.232525,-0.388802,-0.398401,19.912166,50.657989,0.560738,0.00560738,0,0.560738,-0.393073,0.02195,100,78.501,0,7.7,42.4425,0,2.3,30.2995
893,44728.67579,892.679913,58246348,-8.528576,0.593336,0.584039,33.410667,2.211817,-0.407701,-0.41694,19.912166,47.232252,0.533214,0.00533214,0,0.533214,-0.412466,0.02363,100,78.4936,0,7.6,42.4425,0,2.3,30.2995
912,44728.67601,911.679913,58246367,-10.258526,0.574247,0.56511,31.060712,2.196039,-0.426826,-0.43607,19.912166,43.990071,0.506144,0.00506144,0,0.506144,-0.431341,0.02308,100,78.4863,0,7.7,42.4425,0,2.3,30.2995
931,44728.67623,930.679913,58246386,-12.041332,0.554432,0.545647,28.881209,2.174345,-0.445763,-0.454675,19.912166,40.768593,0.478449,0.00478449,0,0.478449,-0.450676,0.02444,100,78.4787,0,7.7,42.4425,0,2.3,30.2995
950,44728.67645,949.679913,58246405,-13.568932,0.536204,0.527156,26.715646,2.156595,-0.464839,-0.473443,19.912166,37.812348,0.451848,0.00451848,0,0.451848,-0.469297,0.02426,100,78.4712,0,7.7,42.4425,0,2.3,30.2995
969,44728.67667,968.679913,58246424,-15.237281,0.51708,0.507767,24.63186,2.138846,-0.483796,-0.493034,19.912166,34.801912,0.424512,0.00424512,0,0.424512,-0.488406,0.02383,100,78.4638,0,7.6,42.4425,0,2.3,30.2995
988,44728.67689,987.679913,58246443,-16.709797,0.497849,0.489236,22.630842,2.12011,-0.503233,-0.511934,19.912166,31.995663,0.397229,0.00397229,0,0.397229,-0.507615,0.02458,100,78.4559,0,7.6,42.4425,0,2.3,30.2995
1007,44728.67711,1006.679913,58246462,-18.206245,0.478838,0.46981,20.735222,2.10236,-0.522073,-0.531261,19.912166,29.280618,0.370074,0.00370074,0,0.370074,-0.526514,0.02339,100,78.4486,0,7.6,42.4425,0,2.3,30.2995
1026,44728.67733,1025.679913,58246481,-19.615483,0.459723,0.450724,18.865677,2.08461,-0.541126,-0.550293,19.912166,26.655799,0.342836,0.00342836,0,0.342836,-0.545605,0.02386,100,78.4409,0,7.6,42.4425,0,2.3,30.2995
1045,44728.67755,1044.679913,58246500,-18.211914,0.4569,0.44776,19.967335,2.083624,-0.543472,-0.551509,19.912166,27.965288,0.337804,0.00337804,0,0.337804,-0.549127,1.43232,138.3,77.7719,0,7.7,42.4425,0,2.3,30.2995
1064,44728.67777,1063.679913,58246519,-15.937502,0.459539,0.450332,21.771422,2.083624,-0.540398,-0.54957,19.912166,30.611367,0.343171,0.00343171,0,0.343171,-0.544783,2.96648,196.2,76.7832,0,7.6,42.4425,0,2.3,30.2995
1083,44728.67799,1082.679913,58246538,-13.984358,0.472228,0.463144,23.346006,2.097429,-0.529077,-0.537934,19.912166,33.082671,0.360314,0.00360314,0,0.360314,-0.533517,0.08916,200,76.6894,0,7.7,42.4425,0,2.3,30.2995
1102,44728.67821,1101.679913,58246557,-11.08829,0.490372,0.481505,25.820677,2.117151,-0.51011,-0.518738,19.912166,36.568585,0.387407,0.00387407,0,0.387407,-0.514405,0.05041,200,76.6717,0,7.7,42.4425,0,2.3,30.2995
1121,44728.67843,1120.679913,58246576,-8.300636,0.509288,0.50065,28.34712,2.131943,-0.491045,-0.499673,19.912166,40.044006,0.414671,0.00414671,0,0.414671,-0.495312,0.03498,200,76.6595,0,7.6,42.4425,0,2.3,30.2995
1140,44728.67865,1139.679913,58246595,-5.533074,0.528282,0.519412,30.734628,2.148707,-0.472651,-0.481102,19.912166,43.375141,0.440536,0.00440536,0,0.440536,-0.476618,0.0256,200,76.6508,0,7.7,42.4425,0,2.3,30.2995
1159,44728.67887,1158.679913,58246614,-2.570783,0.54712,0.538152,33.436101,2.167442,-0.453248,-0.461972,19.912166,47.220748,0.468139,0.00468139,0,0.468139,-0.458065,0.02012,200,76.6441,0,7.7,42.4425,0,2.3,30.2995
1178,44728.67909,1177.679913,58246633,0.472438,0.565612,0.556723,36.025513,2.188151,-0.434491,-0.442841,19.912166,50.909581,0.494698,0.00494698,0,0.494698,-0.439301,0.01552,200,76.6388,0,7.7,42.4425,0,2.3,30.2995
1197,44728.67931,1196.679913,58246652,3.35948,0.585019,0.57615,38.67425,2.2059,-0.415796,-0.424401,19.912166,54.636757,0.522098,0.00522098,0,0.522098,-0.420631,0.01164,200,76.635,0,7.7,42.4425,0,2.3,30.2995
1216,44728.67953,1215.679913,58246671,6.441789,0.604429,0.595586,41.572691,2.222664,-0.395865,-0.404417,19.912166,58.728027,0.550467,0.00550467,0,0.550467,-0.400263,0.00865,200,76.632,0,7.7,42.4425,0,2.3,30.2995
1235,44728.67975,1234.679913,58246690,9.424624,0.623531,0.614688,44.230041,2.242386,-0.376876,-0.385977,19.912166,62.594323,0.577418,0.00577418,0,0.577418,-0.380983,0.0059,200,76.63,0,7.7,42.4425,0,2.3,30.2995
1254,44728.67997,1253.679913,58246709,12.400838,0.642306,0.633336,46.952863,2.261122,-0.357976,-0.367142,19.912166,66.419095,0.604441,0.00604441,0,0.604441,-0.362317,0.00312,200,76.6288,0,7.7,42.4425,0,2.3,30.2995
1273,44728.68019,1272.679913,58246728,15.304612,0.660855,0.652057,49.685562,2.276899,-0.339386,-0.347913,19.912166,70.296063,0.631116,0.00631116,0,0.631116,-0.343809,0.00153,200,76.6282,0,7.7,42.4425,0,2.3,30.2995
1292,44728.68041,1291.679913,58246747,18.356633,0.680439,0.67161,52.361136,2.295635,-0.320619,-0.330295,19.912166,74.086838,0.657893,0.00657893,0,0.657893,-0.325065,0,200,76.6282,0,7.7,42.4425,0,2.3,30.2995
1311,44728.68063,1310.679913,58246766,21.3989,0.699136,0.690343,55.247477,2.313385,-0.301291,-0.310935,19.912166,78.200717,0.685621,0.00685621,0,0.685621,-0.305721,0,200,76.6282,0,7.6,42.4425,0,2.3,30.2995
1330,44728.68085,1329.679913,58246785,24.446186,0.717961,0.709372,58.032719,2.333107,-0.282422,-0.290818,19.912166,82.052763,0.712266,0.00712266,0,0.712266,-0.287004,0,200,76.6282,0,7.6,42.4425,0,2.3,30.2995
1349,44728.68107,1348.679913,58246804,27.365936,0.737275,0.728541,60.842593,2.351843,-0.263018,-0.271721,19.912166,85.998877,0.739942,0.00739942,0,0.739942,-0.267631,-0.01001,200,76.6332,0,7.6,42.4425,0,2.3,30.2995
1368,44728.68129,1367.679913,58246823,30.309813,0.755932,0.747409,63.573197,2.375509,-0.244276,-0.252558,19.912166,89.890754,0.767024,0.00767024,0,0.767024,-0.248755,-0.00891,200,76.6356,0,7.7,42.4425,0,2.3,30.2995
1387,44728.68151,1386.679913,58246842,33.110303,0.775653,0.767058,66.304835,2.388328,-0.225272,-0.233493,19.912166,93.73975,0.794045,0.00794045,0,0.794045,-0.229785,-0.00854,200,76.6383,0,7.6,42.4425,0,2.3,30.2995
1406,44728.68173,1405.679913,58246861,36.089798,0.794448,0.785967,69.039259,2.407064,-0.206168,-0.214823,19.912166,97.651866,0.821444,0.00821444,0,0.821444,-0.210579,-0.01143,200,76.6417,0,7.6,42.4425,0,2.3,30.2995
1425,44728.68194,1424.679913,58246880,38.648693,0.813504,0.804969,71.664436,2.422842,-0.18703,-0.196416,19.912166,101.51186,0.848871,0.00848871,0,0.848871,-0.190983,-0.01262,200,76.6459,0,7.7,42.4425,0,2.3,30.2995
1444,44728.68216,1443.679913,58246899,41.774113,0.832432,0.824304,74.367319,2.44355,-0.1681,-0.176201,19.912166,105.166492,0.875849,0.00875849,0,0.875849,-0.172071,-0.01329,200,76.6502,0,7.6,42.4425,0,2.3,30.2995
1463,44728.68238,1462.679913,58246918,44.443158,0.851375,0.843099,76.882371,2.460314,-0.149232,-0.157531,19.912166,108.900429,0.903391,0.00903391,0,0.903391,-0.15317,-0.01598,200,76.6551,0,7.6,42.4425,0,2.3,30.2995
1482,44728.6826,1481.679913,58246937,47.044649,0.870435,0.862426,79.465315,2.482008,-0.130129,-0.138072,19.912166,112.384019,0.930694,0.00930694,0,0.930694,-0.134025,-0.01752,200,76.6603,0,7.6,42.4425,0,2.3,30.2995
1501,44728.68282,1500.679913,58246956,49.427285,0.890059,0.882223,81.941532,2.498771,-0.110735,-0.118285,19.912166,115.891397,0.958277,0.00958277,0,0.958277,-0.114731,-0.01922,200,76.6663,0,7.7,42.4425,0,2.3,30.2995
1520,44728.68304,1519.679913,58246975,52.09818,0.908831,0.900815,84.317634,2.516521,-0.09154,-0.099483,19.912166,119.241483,0.985455,0.00985455,0,0.985455,-0.095469,-0.02073,200,76.6731,0,7.7,42.4425,0,2.3,30.2995
1539,44728.68326,1538.679913,58246994,54.402092,0.927527,0.919547,86.529301,2.535257,-0.072943,-0.080681,19.912166,122.377304,1.012306,0.01012306,0,1.012306,-0.076948,-0.02319,200,76.6799,0,7.7,42.4425,0,2.3,30.2995
1558,44728.68348,1557.679913,58247013,56.605668,0.946465,0.938168,88.653162,2.553007,-0.054132,-0.061485,19.912166,125.405008,1.039055,0.01039055,0,1.039055,-0.058252,-0.02638,200,76.6879,0,7.7,42.4425,0,2.3,30.2995
1577,44728.6837,1576.679913,58247032,58.866871,0.965889,0.957894,90.818172,2.571743,-0.034495,-0.042552,19.912166,128.405303,1.067134,0.01067134,0,1.067134,-0.03865,-0.03014,200,76.697,0,7.7,42.4425,0,2.3,30.2995
1596,44728.68392,1595.679913,58247051,35.620509,0.833346,0.824828,67.249349,2.442564,-0.168888,-0.177943,19.912166,95.248912,0.87587,0.0087587,0,0.87587,-0.172784,0.17314,200,76.6656,0,7.7,42.4425,0,2.3,30.2995
1615,44728.68414,1614.679913,58247070,7.837446,0.644903,0.634427,39.503245,2.25915,-0.357741,-0.36895,19.912166,55.934136,0.604005,0.00604005,0,0.604005,-0.362787,0.19037,200,76.6061,0,7.6,42.4425,0,2.3,30.2995
1634,44728.68436,1633.679913,58247089,-7.149259,0.513526,0.504893,24.719722,2.13786,-0.487096,-0.4954,19.912166,34.798766,0.419336,0.00419336,0,0.419336,-0.491291,0.10573,200,76.5604,0,7.7,42.4425,0,2.3,30.2995
1653,44728.68458,1652.679913,58247108,-5.567157,0.514372,0.505854,26.281672,2.139832,-0.485513,-0.492113,19.912166,37.357354,0.423175,0.00423175,0,0.423175,-0.489368,4.7586,254.2,75.7181,0,7.7,42.4425,0,2.3,30.2995
1672,44728.6848,1671.679913,58247127,-4.279551,0.516858,0.508301,28.093502,2.141804,-0.480499,-0.490535,19.912166,38.843192,0.423508,0.00423508,0,0.423508,-0.486273,0.80217,299.6,75.0182,0,7.7,42.4425,0,2.3,30.2995
1691,44728.68502,1690.679913,58247146,-2.538326,0.527512,0.519065,29.175495,2.148707,-0.472735,-0.481792,19.912166,41.302619,0.440738,0.00440738,0,0.440738,-0.476742,0.05806,300,74.9821,0,7.7,42.4425,0,2.3,30.2995
1710,44728.68524,1709.679913,58247165,0.029228,0.546045,0.537573,31.818496,2.168429,-0.453892,-0.462136,19.912166,45.074595,0.467923,0.00467923,0,0.467923,-0.458044,0.04535,300,74.9662,0,7.6,42.4425,0,2.3,30.2995
1729,44728.68546,1728.679913,58247184,2.689802,0.565792,0.55694,34.378152,2.188151,-0.435296,-0.443302,19.912166,48.73527,0.494579,0.00494579,0,0.494579,-0.439847,0.03278,300,74.9553,0,7.7,42.4425,0,2.3,30.2995
1748,44728.68568,1747.679913,58247203,5.446092,0.585271,0.576326,37.241613,2.2059,-0.415173,-0.424533,19.912166,52.702627,0.52266,0.0052266,0,0.52266,-0.419728,0.02412,300,74.9469,0,7.6,42.4425,0,2.3,30.2995
1767,44728.6859,1766.679913,58247222,8.160947,0.604497,0.595167,40.064516,2.224636,-0.396079,-0.404811,19.912166,56.58813,0.549895,0.00549895,0,0.549895,-0.400664,0.01931,300,74.9404,0,7.7,42.4425,0,2.3,30.2995
1786,44728.68612,1785.679913,58247241,10.924462,0.623469,0.613916,42.800122,2.242386,-0.37703,-0.386568,19.912166,60.502323,0.576668,0.00576668,0,0.576668,-0.381923,0.01633,300,74.935,0,7.7,42.4425,0,2.3,30.2995
1805,44728.68634,1804.679913,58247260,13.71474,0.642907,0.633189,45.649485,2.260136,-0.357724,-0.367602,19.912166,64.599607,0.604296,0.00604296,0,0.604296,-0.362583,0.01317,300,74.9308,0,7.7,42.4425,0,2.3,30.2995
1824,44728.68656,1823.679913,58247279,16.509127,0.661994,0.652314,48.521446,2.277885,-0.338583,-0.348078,19.912166,68.687982,0.631677,0.00631677,0,0.631677,-0.343495,0.00944,300,74.9276,0,7.6,42.4425,0,2.3,30.2995
1843,44728.68678,1842.679913,58247298,19.260173,0.680523,0.67053,51.336628,2.297607,-0.319835,-0.329703,19.912166,72.663952,0.658243,0.00658243,0,0.658243,-0.32482,0.00744,300,74.925,0,7.6,42.4425,0,2.3,30.2995
1862,44728.687,1861.679913,58247317,22.101248,0.699936,0.690105,54.274537,2.315357,-0.300491,-0.31054,19.912166,76.720791,0.686059,0.00686059,0,0.686059,-0.305349,0.00547,300,74.9232,0,7.7,42.4425,0,2.3,30.2995
1881,44728.68722,1880.679913,58247336,24.867469,0.718795,0.70894,57.222181,2.333107,-0.281614,-0.291443,19.912166,80.795432,0.712374,0.00712374,0,0.712374,-0.28678,0.00263,300,74.9223,0,7.7,42.4425,0,2.3,30.2995
1900,44728.68744,1899.679913,58247355,27.781671,0.737535,0.728055,60.266188,2.350857,-0.262686,-0.271984,19.912166,85.148752,0.740044,0.00740044,0,0.740044,-0.267367,0.00066,300,74.922,0,7.6,42.4425,0,2.3,30.2995
1919,44728.68766,1918.679913,58247374,30.551845,0.75599,0.746968,63.126652,2.371565,-0.244357,-0.253281,19.912166,89.103828,0.766295,0.00766295,0,0.766295,-0.249183,0.00014,300,74.9219,0,7.7,42.4425,0,2.3,30.2995
1938,44728.68788,1937.679913,58247393,33.586853,0.775734,0.766888,66.17072,2.388328,-0.224665,-0.233855,19.912166,93.629285,0.795091,0.00795091,0,0.795091,-0.229027,0,300,74.9219,0,7.7,42.4425,0,2.3,30.2995
1957,44728.6881,1956.679913,58247412,36.420317,0.794979,0.785892,69.098347,2.409036,-0.205777,-0.214889,19.912166,97.820352,0.822026,0.00822026,0,0.822026,-0.210355,0,300,74.9219,0,7.7,42.4425,0,2.3,30.2995
1976,44728.68832,1975.679913,58247431,39.300744,0.81387,0.804949,72.125666,2.423828,-0.186637,-0.195364,19.912166,101.993799,0.849149,0.00849149,0,0.849149,-0.191119,-0.0278,300,74.9265,0,7.6,42.4425,0,2.3,30.2995
1995,44728.68854,1994.679913,58247450,42.049,0.832713,0.823841,75.005581,2.44355,-0.167486,-0.176431,19.912166,106.161824,0.876478,0.00876478,0,0.876478,-0.172056,-0.00779,300,74.9294,0,7.6,42.4425,0,2.3,30.2995
2014,44728.68876,2013.679913,58247469,44.941893,0.851941,0.843073,77.993849,2.463272,-0.1484,-0.1574,19.912166,110.295982,0.903843,0.00903843,0,0.903843,-0.152696,-0.00813,300,74.9318,0,7.7,42.4425,0,2.3,30.2995
2033,44728.68898,2032.679913,58247488,47.661744,0.871045,0.86214,80.714962,2.482994,-0.129645,-0.138499,19.912166,114.434956,0.931112,0.00931112,0,0.931112,-0.133898,-0.0068,300,74.9343,0,7.7,42.4425,0,2.3,30.2995
2052,44728.6892,2051.679913,58247507,50.342024,0.889937,0.880822,83.756396,2.498771,-0.110381,-0.119402,19.912166,118.435892,0.957782,0.00957782,0,0.957782,-0.115015,-0.00912,300,74.9371,0,7.7,42.4425,0,2.3,30.2995
2071,44728.68942,2070.679913,58247526,53.073114,0.908871,0.899915,86.610455,2.515535,-0.091465,-0.100535,19.912166,122.56104,0.985118,0.00985118,0,0.985118,-0.095963,-0.01112,300,74.9402,0,7.6,42.4425,0,2.3,30.2995
2090,44728.68964,2089.679913,58247545,55.784207,0.927553,0.918613,89.437642,2.536243,-0.072845,-0.081602,19.912166,126.546132,1.011934,0.01011934,0,1.011934,-0.077224,-0.01077,300,74.9438,0,7.7,42.4425,0,2.3,30.2995
2109,44728.68986,2108.679913,58247564,58.502025,0.946857,0.937901,92.279098,2.553007,-0.053455,-0.062406,19.912166,130.606886,1.039445,0.01039445,0,1.039445,-0.058099,-0.01175,300,74.9476,0,7.7,42.4425,0,2.3,30.2995
2128,44728.69008,2127.679913,58247583,61.076671,0.965925,0.95708,95.198458,2.570757,-0.03433,-0.043341,19.912166,134.52737,1.066655,0.01066655,0,1.066655,-0.038852,-0.01265,300,74.9519,0,7.7,42.4425,0,2.4,30.2995
2147,44728.6903,2146.679913,58247602,63.683859,0.98489,0.976395,97.912031,2.588506,-0.01556,-0.023915,19.912166,138.44416,1.093817,0.01093817,0,1.093817,-0.019894,-0.01534,300,74.9564,0,7.7,42.4425,0,2.3,30.2995
2166,44728.69052,2165.679913,58247621,66.067003,1.003026,0.994894,100.383127,2.608228,0.002538,-0.005245,19.912166,142.043753,1.120077,0.01120077,0,1.120077,-0.001536,-0.01552,300,74.9614,0,7.7,42.4425,0,2.3,30.2995
2185,44728.69074,2184.679913,58247640,68.488329,1.022133,1.014185,103.111041,2.62795,0.021859,0.014214,19.912166,145.8597,1.147905,0.01147905,0,1.147905,0.017901,-0.01578,300,74.9665,0,7.7,42.4425,0,2.3,30.2995
2204,44728.69096,2203.679913,58247659,70.83562,1.041305,1.033497,105.490756,2.644714,0.040961,0.03318,19.912166,149.242554,1.175027,0.01175027,0,1.175027,0.036929,-0.01836,300,74.9722,0,7.7,42.4425,0,2.3,30.2995
2223,44728.69118,2222.679913,58247678,73.009943,1.060278,1.052773,107.932575,2.66345,0.05975,0.05162,19.912166,152.672894,1.202247,0.01202247,0,1.202247,0.056137,-0.01992,300,74.9791,0,7.7,42.4425,0,2.3,30.2995
2242,44728.6914,2241.679913,58247697,75.072984,1.079105,1.071753,110.184866,2.683172,0.078422,0.071243,19.912166,155.943965,1.229047,0.01229047,0,1.229047,0.074815,-0.02206,300,74.9858,0,7.7,42.4425,0,2.3,30.2995
2261,44728.69162,2260.679913,58247716,77.06024,1.097913,1.090668,112.420305,2.699935,0.097777,0.090538,19.912166,159.054151,1.256841,0.01256841,0,1.256841,0.094198,-0.02452,300,74.9936,0,7.7,42.4425,0,2.4,30.2995
2280,44728.69184,2279.679913,58247735,78.846948,1.116968,1.109977,114.420375,2.720643,0.116598,0.109734,19.912166,161.834608,1.283637,0.01283637,0,1.283637,0.112956,-0.028,300,75.0025,0,7.7,42.4425,0,2.3,30.2995
2299,44728.69206,2298.679913,58247754,69.069709,1.073237,1.064894,104.547618,2.675283,0.070805,0.061941,19.912166,148.016587,1.21828,0.0121828,0,1.21828,0.066842,0.06136,300,74.9952,0,7.7,42.4425,0,2.3,30.2995
2318,44728.69228,2317.679913,58247773,36.745765,0.884278,0.874874,72.334615,2.490883,-0.118779,-0.128277,19.912166,102.503234,0.94714,0.0094714,0,0.94714,-0.123104,0.16874,300,74.9413,0,7.7,42.4425,0,2.3,30.2995
2337,44728.6925,2336.679913,58247792,8.768564,0.693859,0.683203,44.600417,2.307468,-0.308979,-0.31981,19.912166,63.28652,0.674702,0.00674702,0,0.674702,-0.313299,0.17656,300,74.8862,0,7.7,42.4425,0,2.3,30.2995
2356,44728.69272,2355.679913,58247811,-4.458198,0.589392,0.579463,31.90164,2.207872,-0.4149,-0.42496,19.912166,44.374688,0.5191,0.005191,0,0.5191,-0.421888,0.06058,300,74.8494,0,7.7,42.4425,0,2.3,30.2995
2375,44728.69294,2374.679913,58247830,-3.768877,0.587456,0.577875,32.112247,2.202942,-0.418257,-0.428543,19.912166,46.758927,0.524468,0.00524468,0,0.524468,-0.418479,1.60764,328.6,74.4379,0,7.7,42.4425,0,2.3,30.2995
2394,44728.69316,2393.679913,58247849,-3.855556,0.588001,0.578063,33.239741,2.206886,-0.416041,-0.424303,19.912166,46.659751,0.51908,0.0051908,0,0.51908,-0.421247,0.45582,360,73.9842,0,7.7,42.4425,0,2.4,30.2995
2413,44728.69338,2412.679913,58247868,-3.504506,0.586711,0.576851,35.34792,2.209845,-0.407744,-0.421969,19.912166,48.323232,0.523414,0.00523414,0,0.523414,-0.417756,3.02277,396.3,73.4564,0,7.7,42.4425,0,2.4,30.2995
2432,44728.6936,2431.679913,58247887,-0.308094,0.604808,0.595053,37.156954,2.222664,-0.396382,-0.406685,19.912166,52.620976,0.549173,0.00549173,0,0.549173,-0.401169,0.05806,400,73.3909,0,7.7,42.4425,0,2.4,30.2995
2451,44728.69382,2450.679913,58247906,2.199117,0.623553,0.613926,40.001551,2.2414,-0.377515,-0.386897,19.912166,56.544196,0.575706,0.00575706,0,0.575706,-0.382596,0.03585,400,73.3782,0,7.7,42.4425,0,2.4,30.2995
2470,44728.69404,2469.679913,58247925,4.838083,0.641926,0.632451,42.804839,2.260136,-0.358745,-0.367898,19.912166,60.547497,0.603152,0.00603152,0,0.603152,-0.363797,0.02571,400,73.3693,0,7.7,42.4425,0,2.4,30.2995
2489,44728.69426,2488.679913,58247944,7.383589,0.661236,0.651486,45.697351,2.278872,-0.339407,-0.348768,19.912166,64.705793,0.630527,0.00630527,0,0.630527,-0.344221,0.01946,400,73.3627,0,7.7,42.4425,0,2.4,30.2995
2508,44728.69448,2507.679913,58247963,10.133698,0.680573,0.671047,48.824196,2.296621,-0.319727,-0.329375,19.912166,69.029051,0.658703,0.00658703,0,0.658703,-0.324477,0.01555,400,73.3573,0,7.7,42.4425,0,2.4,30.2995
2527,44728.6947,2526.679913,58247982,12.873539,0.699326,0.689849,51.613003,2.315357,-0.301421,-0.30962,19.912166,73.010891,0.685079,0.00685079,0,0.685079,-0.306362,0.01219,400,73.3535,0,7.7,42.4425,0,2.4,30.2995
2546,44728.69492,2545.679913,58248001,15.435593,0.718513,0.708725,54.71043,2.333107,-0.281857,-0.290555,19.912166,77.296402,0.712569,0.00712569,0,0.712569,-0.286548,0.00915,400,73.3504,0,7.7,42.4425,0,2.4,30.2995
2565,44728.69514,2564.679913,58248020,18.075665,0.737428,0.728048,57.74612,2.352829,-0.262773,-0.27205,19.912166,81.442147,0.739716,0.00739716,0,0.739716,-0.267624,0.00781,400,73.348,0,7.7,42.4425,0,2.4,30.2995
2584,44728.69536,2583.679913,58248039,20.828038,0.756512,0.747339,60.735206,2.371565,-0.243723,-0.253347,19.912166,85.876313,0.767211,0.00767211,0,0.767211,-0.248453,0.00457,400,73.3464,0,7.7,42.4425,0,2.4,30.2995
2603,44728.69558,2602.679913,58248058,23.541827,0.775045,0.766258,63.79308,2.390301,-0.225021,-0.233592,19.912166,90.151056,0.794166,0.00794166,0,0.794166,-0.229674,0.00335,400,73.3454,0,7.6,42.4425,0,2.4,30.2995
2622,44728.6958,2621.679913,58248077,26.283034,0.79426,0.785405,66.80418,2.40805,-0.206285,-0.214527,19.912166,94.352227,0.821166,0.00821166,0,0.821166,-0.210774,0.00205,400,73.3449,0,7.6,42.4425,0,2.4,30.2995
2641,44728.69602,2640.679913,58248096,28.688234,0.813237,0.804445,69.723059,2.4258,-0.187209,-0.196252,19.912166,98.735889,0.848602,0.00848602,0,0.848602,-0.191569,0.0002,400,73.3447,0,7.7,42.4425,0,2.4,30.2995
2660,44728.69624,2659.679913,58248115,31.641011,0.831989,0.822935,72.881827,2.444536,-0.168181,-0.17768,19.912166,103.035875,0.875152,0.00875152,0,0.875152,-0.172685,0,400,73.3447,0,7.7,42.4425,0,2.4,30.2995
2679,44728.69646,2678.679913,58248134,34.201823,0.851612,0.842772,75.837214,2.4613,-0.149403,-0.15832,19.912166,107.266153,0.902527,0.00902527,0,0.902527,-0.153821,0,400,73.3447,0,7.7,42.4425,0,2.4,30.2995
2698,44728.69668,2697.679913,58248153,37.068185,0.870389,0.861133,78.983707,2.482008,-0.129914,-0.139091,19.912166,111.645584,0.929839,0.00929839,0,0.929839,-0.134703,-0.00524,400,73.3461,0,7.7,42.4425,0,2.4,30.2995
2717,44728.6969,2716.679913,58248172,39.843133,0.889463,0.880327,81.946422,2.498771,-0.111185,-0.120224,19.912166,115.854744,0.956799,0.00956799,0,0.956799,-0.115882,-0.01479,400,73.3531,0,7.6,42.4425,0,2.4,30.2995
2736,44728.69712,2735.679913,58248191,42.546725,0.908605,0.899337,85.007657,2.515535,-0.091825,-0.101126,19.912166,120.325366,0.984534,0.00984534,0,0.984534,-0.096417,-0.00697,400,73.3552,0,7.6,42.4425,0,2.4,30.2995
2755,44728.69734,2754.679913,58248210,45.196209,0.927263,0.918057,87.990406,2.534271,-0.073187,-0.082226,19.912166,124.58147,1.011291,0.01011291,0,1.011291,-0.077762,-0.00726,400,73.3572,0,7.7,42.4425,0,2.4,30.2995
2774,44728.69756,2773.679913,58248229,47.940034,0.946533,0.937302,91.124334,2.553993,-0.053853,-0.062866,19.912166,128.837983,1.038654,0.01038654,0,1.038654,-0.058661,-0.00668,400,73.3596,0,7.7,42.4425,0,2.4,30.2995
2793,44728.69778,2792.679913,58248248,50.628213,0.965432,0.956222,94.090548,2.571743,-0.035003,-0.044327,19.912166,132.977299,1.065567,0.01065567,0,1.065567,-0.039574,-0.00831,400,73.3622,0,7.7,42.4425,0,2.4,30.2995
2812,44728.698,2811.679913,58248267,53.320211,0.984243,0.975176,97.106109,2.588506,-0.015954,-0.025296,19.912166,137.405452,1.092688,0.01092688,0,1.092688,-0.020532,-0.0097,400,73.3652,0,7.7,42.4425,0,2.4,30.2995
2831,44728.69822,2830.679913,58248286,55.991589,1.003261,0.994178,99.976097,2.607242,0.002946,-0.006527,19.912166,141.66631,1.120014,0.01120014,0,1.120014,-0.00158,-0.00903,400,73.3683,0,7.6,42.4425,0,2.4,30.2995
2850,44728.69844,2849.679913,58248305,58.512529,1.022052,1.013035,103.090157,2.62795,0.021883,0.013064,19.912166,145.804686,1.147007,0.01147007,0,1.147007,0.017385,-0.01184,400,73.3718,0,7.7,42.4425,0,2.4,30.2995
2869,44728.69866,2868.679913,58248324,60.824852,1.04108,1.032063,106.013953,2.642742,0.040954,0.031701,19.912166,149.922269,1.173974,0.01173974,0,1.173974,0.036391,-0.01158,400,73.3754,0,7.7,42.4425,0,2.4,30.2995
2888,44728.69888,2887.679913,58248343,63.946303,1.059956,1.051445,109.041103,2.66345,0.059653,0.050963,19.912166,154.128301,1.201251,0.01201251,0,1.201251,0.055417,-0.01346,400,73.3793,0,7.7,42.4425,0,2.4,30.2995
2907,44728.6991,2906.679913,58248362,66.601912,1.078797,1.071264,111.903704,2.683172,0.078024,0.070882,19.912166,158.363565,1.228577,0.01228577,0,1.228577,0.074433,-0.01427,400,73.3836,0,7.7,42.4425,0,2.4,30.2995
2926,44728.69932,2925.679913,58248381,69.152768,1.097105,1.090335,114.863464,2.699935,0.096719,0.090374,19.912166,162.552657,1.255527,0.01255527,0,1.255527,0.093278,-0.01352,400,73.3879,0,7.7,42.4425,0,2.4,30.2995
2945,44728.69954,2944.679913,58248400,71.75073,1.116244,1.109856,117.75329,2.720643,0.115714,0.109668,19.912166,166.552955,1.282868,0.01282868,0,1.282868,0.112417,-0.01552,400,73.3927,0,7.7,42.4425,0,2.4,30.2995
2964,44728.69976,2963.679913,58248419,74.17938,1.134862,1.128901,120.543179,2.742338,0.13469,0.128338,19.912166,170.492448,1.309899,0.01309899,0,1.309899,0.131625,-0.0152,400,73.3975,0,7.7,42.4425,0,2.4,30.2995
2983,44728.69998,2982.679913,58248438,76.485295,1.153802,1.147505,123.123334,2.756143,0.153352,0.147173,19.912166,174.225967,1.336882,0.01336882,0,1.336882,0.15027,-0.01581,400,73.4027,0,7.7,42.4425,0,2.4,30.2995
3002,44728.7002,3001.679913,58248457,78.597085,1.172842,1.1661,125.636316,2.775865,0.172501,0.16604,19.912166,177.785001,1.363935,0.01363935,0,1.363935,0.169152,-0.01789,400,73.408,0,7.7,42.4425,0,2.4,30.2995
3021,44728.70042,3020.679913,58248476,80.691117,1.192543,1.184785,128.145935,2.792629,0.192423,0.184842,19.912166,181.247279,1.391458,0.01391458,0,1.391458,0.188512,-0.01812,400,73.414,0,7.6,42.4425,0,2.4,30.2995
3040,44728.70064,3039.679913,58248495,82.651464,1.211644,1.203624,130.491435,2.813337,0.211892,0.203545,19.912166,184.537483,1.418689,0.01418689,0,1.418689,0.207559,-0.02128,400,73.4201,0,7.7,42.4425,0,2.4,30.2995
3059,44728.70086,3058.679913,58248514,84.528472,1.230838,1.222201,132.528628,2.833059,0.23033,0.221919,19.912166,187.612141,1.445279,0.01445279,0,1.445279,0.226105,-0.02334,400,73.4271,0,7.7,42.4425,0,2.4,30.2995
3078,44728.70108,3077.679913,58248533,86.294554,1.249653,1.241442,134.769928,2.852781,0.249711,0.240819,19.912166,190.558205,1.472437,0.01472437,0,1.472437,0.245067,-0.02504,400,73.4348,0,7.7,42.4425,0,2.4,30.2995
3097,44728.7013,3096.679913,58248552,87.966358,1.268797,1.260397,136.684704,2.869544,0.268414,0.260114,19.912166,193.478934,1.499958,0.01499958,0,1.499958,0.264438,-0.02531,400,73.4431,0,7.6,42.4425,0,2.4,30.2995
3116,44728.70152,3115.679913,58248571,66.989141,1.161773,1.15475,115.815053,2.76206,0.159511,0.152333,19.912166,163.997852,1.346014,0.01346014,0,1.346014,0.156368,0.19116,400,73.4138,0,7.7,42.4425,0,2.4,30.2995
3135,44728.70174,3134.679913,58248590,34.396452,0.974364,0.964737,83.422213,2.575687,-0.02852,-0.038444,19.912166,118.243288,1.075693,0.01075693,0,1.075693,-0.033189,0.16527,400,73.3617,0,7.7,42.4425,0,2.4,30.2995
3154,44728.70196,3153.679913,58248609,5.472645,0.783591,0.773793,54.974383,2.395231,-0.218701,-0.229023,19.912166,77.910861,0.803393,0.00803393,0,0.803393,-0.223391,0.16593,400,73.3096,0,7.6,42.4425,0,2.4,30.2995
3173,44728.70218,3172.679913,58248628,-10.357381,0.659812,0.650128,39.696903,2.278872,-0.340153,-0.349787,19.912166,55.75039,0.627311,0.00627311,0,0.627311,-0.345335,0.0911,400,73.2704,0,7.7,42.4425,0,2.4,30.2995
3192,44728.7024,3191.679913,58248647,-9.416202,0.663272,0.652996,40.872311,2.279858,-0.337818,-0.349688,19.912166,57.290007,0.62911,0.0062911,0,0.62911,-0.343172,3.8041,434.3,72.8233,0,7.6,42.4425,0,2.4,30.2995
3211,44728.70262,3210.679913,58248666,-9.05659,0.6625,0.652164,41.645698,2.274927,-0.338343,-0.351825,19.912166,58.726916,0.629608,0.00629608,0,0.629608,-0.34391,0.72745,469.1,72.334,0,7.7,42.4425,0,2.4,30.2995
3230,44728.70284,3229.679913,58248685,-8.286261,0.665019,0.654624,42.848022,2.282816,-0.335729,-0.346138,19.912166,60.682139,0.63542,0.0063542,0,0.63542,-0.340909,-0.07297,500,71.9135,0,7.6,42.4425,0,2.4,30.2995
3249,44728.70306,3248.679913,58248704,-5.628172,0.68426,0.674462,45.914078,2.29958,-0.316063,-0.327074,19.912166,64.901004,0.663437,0.00663437,0,0.663437,-0.321105,0.04685,500,71.8956,0,7.7,42.4425,0,2.4,30.2995
3268,44728.70328,3267.679913,58248723,-3.147238,0.702739,0.693099,48.775932,2.317329,-0.297519,-0.307418,19.912166,69.090377,0.690575,0.00690575,0,0.690575,-0.302037,0.02927,500,71.8855,0,7.7,42.4425,0,2.4,30.2995
3287,44728.7035,3286.679913,58248742,-0.66531,0.721477,0.711751,51.843256,2.337051,-0.278486,-0.287959,19.912166,73.371788,0.717684,0.00717684,0,0.717684,-0.283211,0.02122,500,71.8784,0,7.8,42.4425,0,2.4,30.2995
3306,44728.70372,3305.679913,58248761,2.121992,0.74079,0.73139,54.802903,2.353815,-0.259929,-0.268467,19.912166,77.582992,0.744494,0.00744494,0,0.744494,-0.264516,0.01572,500,71.8729,0,7.7,42.4425,0,2.4,30.2995
3325,44728.70394,3324.679913,58248780,4.84111,0.759782,0.750955,57.918783,2.375509,-0.240911,-0.249534,19.912166,81.929094,0.771619,0.00771619,0,0.771619,-0.245457,0.01274,500,71.8687,0,7.6,42.4425,0,2.4,30.2995
3344,44728.70416,3343.679913,58248799,7.429891,0.778718,0.769699,61.010005,2.392273,-0.221741,-0.230535,19.912166,86.24823,0.799042,0.00799042,0,0.799042,-0.226356,0.00944,500,71.8656,0,7.7,42.4425,0,2.4,30.2995
3363,44728.70438,3362.679913,58248818,10.189912,0.797807,0.788924,64.172934,2.411009,-0.202498,-0.211208,19.912166,90.582807,0.826341,0.00826341,0,0.826341,-0.206838,0.00726,500,71.8632,0,7.7,42.4425,0,2.4,30.2995
3382,44728.7046,3381.679913,58248837,12.844185,0.816725,0.807919,67.063719,2.427772,-0.183702,-0.192801,19.912166,95.02213,0.853462,0.00853462,0,0.853462,-0.188206,0.00544,500,71.8614,0,7.7,42.4425,0,2.4,30.2995
3401,44728.70482,3400.679913,58248856,15.514102,0.835893,0.82705,70.28514,2.445522,-0.164476,-0.173243,19.912166,99.419206,0.881103,0.00881103,0,0.881103,-0.168786,0.00243,500,71.8604,0,7.7,42.4425,0,2.4,30.2995
3420,44728.70504,3419.679913,58248875,18.142923,0.854891,0.845753,73.240608,2.465244,-0.145481,-0.154671,19.912166,103.684479,0.907849,0.00907849,0,0.907849,-0.150018,0.00141,500,71.8598,0,7.6,42.4425,0,2.4,30.2995
3439,44728.70526,3438.679913,58248894,20.863622,0.873964,0.864856,76.353316,2.48398,-0.126397,-0.135738,19.912166,108.074964,0.935108,0.00935108,0,0.935108,-0.130932,0.00034,500,71.8595,0,7.6,42.4425,0,2.4,30.2995
3458,44728.70548,3457.679913,58248913,23.481159,0.892917,0.883676,79.406821,2.50173,-0.107546,-0.116674,19.912166,112.418824,0.96219,0.0096219,0,0.96219,-0.112108,0,500,71.8595,0,7.7,42.4425,0,2.4,30.2995
3477,44728.70569,3476.679913,58248932,26.222078,0.91179,0.90289,82.521823,2.519479,-0.088616,-0.097346,19.912166,116.838333,0.989309,0.00989309,0,0.989309,-0.093126,0,500,71.8595,0,7.7,42.4425,0,2.4,30.2995
3496,44728.70591,3495.679913,58248951,28.919922,0.930613,0.921599,85.673968,2.536243,-0.069796,-0.078676,19.912166,121.194187,1.016148,0.01016148,0,1.016148,-0.074271,0,500,71.8595,0,7.7,42.4425,0,2.4,30.2995
3515,44728.70613,3514.679913,58248970,31.57951,0.949693,0.940424,88.772661,2.553993,-0.05066,-0.059776,19.912166,125.538188,1.043456,0.01043456,0,1.043456,-0.05516,-0.03787,500,71.8678,0,7.7,42.4425,0,2.4,30.2995
3534,44728.70635,3533.679913,58248989,34.32628,0.968753,0.959539,91.880348,2.573715,-0.031595,-0.040843,19.912166,129.934117,1.07032,0.0107032,0,1.07032,-0.036164,-0.00628,500,71.8715,0,7.6,42.4425,0,2.4,30.2995
3553,44728.70657,3552.679913,58249008,37.010735,0.987667,0.978339,94.991163,2.590478,-0.012666,-0.021844,19.912166,134.290863,1.09737,0.0109737,0,1.09737,-0.017452,-0.00651,500,71.8734,0,7.7,42.4425,0,2.4,30.2995
3572,44728.70679,3571.679913,58249027,39.789693,1.006977,0.997603,98.123701,2.611187,0.006754,-0.002911,19.912166,138.90778,1.125002,0.01125002,0,1.125002,0.001911,-0.00712,500,71.8754,0,7.7,42.4425,0,2.4,30.2995
3591,44728.70701,3590.679913,58249046,42.377342,1.025651,1.016362,101.220634,2.628936,0.025271,0.016219,19.912166,143.123106,1.151711,0.01151711,0,1.151711,0.020711,-0.0068,500,71.8778,0,7.7,42.4425,0,2.4,30.2995
3610,44728.70723,3609.679913,58249065,45.164264,1.044487,1.035378,104.25697,2.647672,0.044201,0.035316,19.912166,147.521655,1.178842,0.01178842,0,1.178842,0.039739,-0.00944,500,71.8803,0,7.7,42.4425,0,2.4,30.2995
3629,44728.70745,3628.679913,58249084,47.860121,1.063185,1.054597,107.437375,2.665422,0.063038,0.054808,19.912166,151.870301,1.206026,0.01206026,0,1.206026,0.058628,-0.00822,500,71.883,0,7.7,42.4425,0,2.4,30.2995
3648,44728.70767,3647.679913,58249103,50.65671,1.082148,1.074195,110.434643,2.684158,0.081551,0.073577,19.912166,156.17989,1.233115,0.01233115,0,1.233115,0.077581,-0.01088,500,71.8862,0,7.6,42.4425,0,2.4,30.2995
3667,44728.70789,3666.679913,58249122,53.392695,1.100655,1.093556,113.631827,2.702894,0.100356,0.093102,19.912166,160.702924,1.260301,0.01260301,0,1.260301,0.096692,-0.0121,500,71.8896,0,7.7,42.4425,0,2.4,30.2995
3686,44728.70811,3685.679913,58249141,56.078047,1.119335,1.112557,116.682365,2.722616,0.119015,0.112232,19.912166,165.014464,1.287425,0.01287425,0,1.287425,0.1157,-0.01172,500,71.8929,0,7.6,42.4425,0,2.4,30.2995
3705,44728.70833,3704.679913,58249160,58.77073,1.138094,1.131766,119.68489,2.741352,0.137869,0.131297,19.912166,169.325075,1.314676,0.01314676,0,1.314676,0.13471,-0.01007,500,71.8967,0,7.7,42.4425,0,2.4,30.2995
3724,44728.70855,3723.679913,58249179,61.393886,1.157239,1.150829,122.7743,2.758115,0.157145,0.150986,19.912166,173.626502,1.341913,0.01341913,0,1.341913,0.153749,-0.00984,500,71.9002,0,7.7,42.4425,0,2.4,30.2995
3743,44728.70877,3742.679913,58249198,64.026402,1.176737,1.169617,125.707185,2.777837,0.176475,0.169031,19.912166,177.711739,1.368951,0.01368951,0,1.368951,0.172676,-0.01259,500,71.9044,0,7.7,42.4425,0,2.4,30.2995
3762,44728.70899,3761.679913,58249217,66.574418,1.196009,1.187829,128.580602,2.794601,0.195894,0.187899,19.912166,181.893672,1.3961,0.013961,0,1.3961,0.191966,-0.01201,500,71.9086,0,7.7,42.4425,0,2.4,30.2995
3781,44728.70921,3780.679913,58249236,69.184187,1.215422,1.206878,131.522003,2.815309,0.215067,0.206569,19.912166,186.045953,1.423445,0.01423445,0,1.423445,0.210821,-0.01352,500,71.9128,0,7.7,42.4425,0,2.4,30.2995
3800,44728.70943,3799.679913,58249255,71.713646,1.234131,1.225671,134.380224,2.836017,0.233995,0.225305,19.912166,190.175769,1.450414,0.01450414,0,1.450414,0.229699,-0.01581,500,71.9175,0,7.6,42.4425,0,2.4,30.2995
3819,44728.70965,3818.679913,58249274,74.279725,1.253436,1.245476,137.325024,2.853767,0.253143,0.245093,19.912166,194.323841,1.478307,0.01478307,0,1.478307,0.249255,-0.01505,500,71.922,0,7.6,42.4425,0,2.4,30.2995
3838,44728.70987,3837.679913,58249293,76.678817,1.271972,1.26443,140.046081,2.872503,0.271628,0.264059,19.912166,198.034638,1.504781,0.01504781,0,1.504781,0.267756,-0.01494,500,71.927,0,7.7,42.4425,0,2.4,30.2995
3857,44728.71009,3856.679913,58249312,78.972602,1.290899,1.283464,142.668177,2.890252,0.290412,0.282992,19.912166,201.77041,1.531762,0.01531762,0,1.531762,0.286755,-0.01589,500,71.9319,0,7.7,42.4425,0,2.4,30.2995
3876,44728.71031,3875.679913,58249331,81.27583,1.309797,1.302543,145.394772,2.908002,0.309682,0.302286,19.912166,205.622733,1.559197,0.01559197,0,1.559197,0.305905,-0.01691,500,71.9375,0,7.7,42.4425,0,2.4,30.2995
3895,44728.71053,3894.679913,58249350,83.42422,1.328901,1.321356,147.887318,2.927724,0.328898,0.321252,19.912166,209.092504,1.586471,0.01586471,0,1.586471,0.324964,-0.01992,500,71.9435,0,7.6,42.4425,0,2.4,30.2995
3914,44728.71075,3913.679913,58249369,85.386396,1.348176,1.339889,150.208755,2.944488,0.348202,0.340218,19.912166,212.435627,1.613644,0.01613644,0,1.613644,0.343961,-0.01975,500,71.9493,0,7.6,42.4425,0,2.4,30.2995
3933,44728.71097,3932.679913,58249388,87.220138,1.367832,1.358637,152.366197,2.962237,0.367574,0.358198,19.912166,215.582815,1.640784,0.01640784,0,1.640784,0.362913,-0.02215,500,71.9559,0,7.7,42.4425,0,2.4,30.2995
3952,44728.71119,3951.679913,58249407,88.905963,1.387243,1.376999,154.409634,2.981959,0.386889,0.376934,19.912166,218.428431,1.667768,0.01667768,0,1.667768,0.381847,-0.02235,500,71.963,0,7.7,42.4425,0,2.4,30.2995
3971,44728.71141,3970.679913,58249426,90.489675,1.406407,1.395931,156.345983,3.000695,0.406187,0.395867,19.912166,221.123359,1.694938,0.01694938,0,1.694938,0.401101,-0.02588,500,71.9709,0,7.7,42.4425,0,2.4,30.2995
3990,44728.71163,3989.679913,58249445,91.93127,1.42543,1.414655,158.091202,3.018445,0.424953,0.414505,19.912166,223.659226,1.721762,0.01721762,0,1.721762,0.419509,-0.02869,500,71.9796,0,7.7,42.4425,0,2.4,30.2995
4009,44728.71185,4008.679913,58249464,93.298635,1.444227,1.433852,159.850827,3.038167,0.44419,0.433767,19.912166,226.114862,1.749263,0.01749263,0,1.749263,0.439058,-0.0313,500,71.9892,0,7.7,42.4425,0,2.4,30.2995
4028,44728.71207,4027.679913,58249483,94.517814,1.463477,1.453223,161.419479,3.058875,0.463226,0.45293,19.912166,228.302623,1.776581,0.01776581,0,1.776581,0.458175,-0.03272,500,71.9996,0,7.7,42.4425,0,2.4,30.2995
4047,44728.71229,4046.679913,58249502,95.611474,1.482302,1.472263,162.766029,3.075639,0.481877,0.472027,19.912166,230.400873,1.803822,0.01803822,0,1.803822,0.476772,-0.03434,500,72.0103,0,7.7,42.4425,0,2.4,30.2995
4066,44728.71251,4065.679913,58249521,96.57134,1.500987,1.491832,164.227451,3.095361,0.500784,0.491552,19.912166,232.338524,1.830971,0.01830971,0,1.830971,0.496089,-0.03634,500,72.0217,0,7.7,42.4425,0,2.4,30.2995
4085,44728.71273,4084.679913,58249540,97.442627,1.51933,1.51116,165.362513,3.116069,0.518974,0.510847,19.912166,234.090836,1.858038,0.01858038,0,1.858038,0.514954,-0.03773,500,72.0337,0,7.7,42.4425,0,2.4,30.2995
4104,44728.71295,4103.679913,58249559,98.128611,1.538154,1.530649,166.455002,3.134805,0.537866,0.530076,19.912166,235.490259,1.885251,0.01885251,0,1.885251,0.534085,-0.04291,500,72.0468,0,7.7,42.4425,0,2.4,30.2995
4123,44728.71317,4122.679913,58249578,98.581717,1.556878,1.549571,167.407215,3.154527,0.556881,0.549207,19.912166,236.740571,1.912167,0.01912167,0,1.912167,0.553186,-0.0395,500,72.06,0,7.7,42.4425,0,2.4,30.2995
4142,44728.71339,4141.679913,58249597,98.991964,1.575846,1.568538,168.241024,3.173263,0.57578,0.568633,19.912166,237.886984,1.939274,0.01939274,0,1.939274,0.571939,-0.04477,500,72.0736,0,7.7,42.4425,0,2.4,30.2995
4161,44728.71361,4160.679913,58249616,99.300549,1.595034,1.587996,168.778154,3.192984,0.594769,0.58773,19.912166,238.849879,1.966865,0.01966865,0,1.966865,0.59116,-0.04601,500,72.0881,0,7.7,42.4425,0,2.4,30.2995
4180,44728.71383,4179.679913,58249635,99.171609,1.613657,1.606994,169.045231,3.21172,0.613223,0.606466,19.912166,239.301534,1.993601,0.01993601,0,1.993601,0.609912,-0.0472,500,72.103,0,7.7,42.4425,0,2.4,30.2995
4199,44728.71405,4198.679913,58249654,98.857006,1.632322,1.626265,169.245595,3.231442,0.632036,0.625827,19.912166,239.41479,2.020652,0.02020652,0,2.020652,0.629013,-0.05088,500,72.1194,0,7.7,42.4425,0,2.4,30.2995
4218,44728.71427,4217.679913,58249673,98.302341,1.650908,1.645901,169.098157,3.248206,0.650629,0.645746,19.912166,239.274411,2.048108,0.02048108,0,2.048108,0.648162,-0.05557,500,72.1369,0,7.7,42.4425,0,2.4,30.2995
4237,44728.71449,4236.679913,58249692,97.076173,1.668927,1.665261,168.258143,3.268914,0.668714,0.664877,19.912166,238.189809,2.075026,0.02075026,0,2.075026,0.666904,-0.05872,500,72.1551,0,7.6,42.4425,0,2.4,30.2995
4256,44728.71471,4255.679913,58249711,95.318364,1.688208,1.685041,167.08851,3.290608,0.688099,0.685289,19.912166,236.250565,2.102745,0.02102745,0,2.102745,0.686331,-0.06275,500,72.1754,0,7.7,42.4425,0,2.4,30.2995
4275,44728.71493,4274.679913,58249730,92.061104,1.706868,1.703836,164.21879,3.309344,0.706886,0.703992,19.912166,232.351415,2.129932,0.02129932,0,2.129932,0.705365,-0.0741,500,72.1979,0,7.7,42.4425,0,2.4,30.2995
4294,44728.71515,4293.679913,58249749,85.409304,1.725084,1.723248,157.917165,3.329066,0.72491,0.723123,19.912166,223.574902,2.156777,0.02156777,0,2.156777,0.724154,-0.0891,500,72.2263,0,7.7,42.4425,0,2.4,30.2995
4300,44728.71522,4299.679913,58249755,82.91464,1.730325,1.729885,155.657196,3.33301,0.73021,0.72973,19.912166,220.276446,2.165187,0.02165187,0,2.165187,0.73004,-0.08977,500,72.2348,0,7.7,42.4425,0,2.4,30.2995