File: PB5_TRI_26422.csv
Index,Date,Time,Counter,Lvdt1,Lvdt2,Force(kN),Potm,LVDT1,LVDT2,Stress [MPa],Strain Ax. [%],Strain Ax [-],Strain Rad. [%],Gemidd,IFlow,IPress,IVol,FlowA,PressA,VolA,FlowB,PressB,VolB
0,44677.61453,0,78254627,0.2834,0.299335,6.360051,23.399233,-0.7173,-0.701527,8.997269,0.003587,0.00003587,0,-0.709414,0.02525,80,70.1808,0,0,0,0,0,0
44,44677.61504,43.568248,78254670,0.301311,0.316725,7.68751,23.415997,-0.70114,-0.685486,10.89786,0.026867,0.00026867,0,-0.693207,0.05143,98.8,69.8137,0,0,0,0,0,0
88,44677.61554,87.568248,78254714,0.30528,0.320063,8.247202,23.420927,-0.695363,-0.68049,11.66189,0.034007,0.00034007,0,-0.68798,0.02768,100,69.7597,0,0,0,0,0,0
132,44677.61605,131.568248,78254758,0.327895,0.341916,10.09787,23.441636,-0.672923,-0.658796,14.287225,0.065772,0.00065772,0,-0.665806,0.01653,100,69.7454,0,0,0,0,0,0
176,44677.61656,175.568248,78254802,0.349617,0.36419,11.982525,23.462344,-0.651161,-0.636445,16.955136,0.097104,0.00097104,0,-0.643778,0.01152,100,69.7356,0,0,0,0,0,0
220,44677.61707,219.568248,78254846,0.370345,0.38602,13.908108,23.482066,-0.630303,-0.614553,19.671633,0.127763,0.00127763,0,-0.622418,0.00862,100,69.7286,0,0,0,0,0,0
264,44677.61758,263.568248,78254890,0.392166,0.40861,15.997327,23.502775,-0.608517,-0.59207,22.620415,0.159408,0.00159408,0,-0.600235,0.00599,100,69.7236,0,0,0,0,0,0
308,44677.61809,307.568248,78254934,0.411744,0.433356,17.981865,23.521511,-0.58898,-0.567352,25.431155,0.191039,0.00191039,0,-0.578125,0.00411,100,69.7197,0,0,0,0,0,0
352,44677.6186,351.568248,78254978,0.434549,0.4542,20.425219,23.543205,-0.566149,-0.546546,28.885186,0.222239,0.00222239,0,-0.556285,0.00222,100,69.7176,0,0,0,0,0,0
396,44677.61911,395.568248,78255022,0.457846,0.475275,23.004055,23.565886,-0.542859,-0.525345,32.532479,0.25383,0.0025383,0,-0.534171,0.00115,100,69.7164,0,0,0,0,0,0
440,44677.61962,439.568248,78255066,0.480485,0.496481,25.628034,23.586594,-0.520187,-0.503979,36.259991,0.285228,0.00285228,0,-0.512086,0.00115,100,69.7157,0,0,0,0,0,0
484,44677.62013,483.568248,78255110,0.502439,0.518461,28.324967,23.607302,-0.498327,-0.482187,40.068912,0.316568,0.00316568,0,-0.490254,0,100,69.7157,0,0,0,0,0,0
528,44677.62064,527.568248,78255154,0.524648,0.540307,31.137654,23.628997,-0.475943,-0.460164,44.039137,0.348106,0.00348106,0,-0.468132,0,100,69.7157,0,0,0,0,0,0
572,44677.62115,571.568248,78255198,0.547254,0.561994,34.008712,23.650691,-0.453352,-0.43847,48.119685,0.379759,0.00379759,0,-0.44602,0,100,69.7157,0,0,0,0,0,0
616,44677.62166,615.568248,78255242,0.570276,0.584439,36.949549,23.673372,-0.430669,-0.416381,52.356503,0.412185,0.00412185,0,-0.42342,-0.00524,100,69.719,0,0,0,0,0,0
660,44677.62216,659.568248,78255286,0.591922,0.605921,40.007478,23.69408,-0.408667,-0.39472,56.591353,0.443059,0.00443059,0,-0.40171,-0.00388,100,69.7217,0,0,0,0,0,0
704,44677.62267,703.568248,78255330,0.61422,0.628135,43.030327,23.715775,-0.386385,-0.372599,60.874479,0.474828,0.00474828,0,-0.37948,-0.00503,100,69.7247,0,0,0,0,0,0
748,44677.62318,747.568248,78255374,0.635316,0.649941,45.90856,23.735497,-0.365256,-0.350609,64.943623,0.505508,0.00505508,0,-0.35801,-0.00344,100,69.7278,0,0,0,0,0,0
792,44677.62369,791.568248,78255418,0.657926,0.672749,49.078887,23.760149,-0.342626,-0.327567,69.42683,0.53797,0.0053797,0,-0.335264,-0.00605,100,69.732,0,0,0,0,0,0
836,44677.6242,835.568248,78255462,0.679518,0.694878,52.04558,23.779872,-0.321049,-0.30584,73.620219,0.569227,0.00569227,0,-0.313326,-0.00613,100,69.7362,0,0,0,0,0,0
880,44677.62471,879.568248,78255506,0.7005,0.717791,54.99783,23.801566,-0.300025,-0.282601,77.7978,0.600617,0.00600617,0,-0.29142,-0.0075,100,69.7412,0,0,0,0,0,0
924,44677.62522,923.568248,78255550,0.721464,0.739903,57.8716,23.822274,-0.279081,-0.260742,81.858546,0.631357,0.00631357,0,-0.269944,-0.00862,100,69.7467,0,0,0,0,0,0
968,44677.62573,967.568248,78255594,0.743067,0.761738,60.831338,23.842983,-0.25754,-0.238785,86.04845,0.662325,0.00662325,0,-0.248209,-0.00909,100,69.7531,0,0,0,0,0,0
1012,44677.62624,1011.568248,78255638,0.766064,0.784437,63.972781,23.867636,-0.234511,-0.216171,90.502059,0.694975,0.00694975,0,-0.22537,-0.01224,100,69.7613,0,0,0,0,0,0
1056,44677.62675,1055.568248,78255682,0.787553,0.806228,66.818034,23.887358,-0.213044,-0.19428,94.516011,0.725935,0.00725935,0,-0.203697,-0.01271,100,69.7701,0,0,0,0,0,0
1100,44677.62726,1099.568248,78255726,0.81,0.828822,69.761985,23.910038,-0.190558,-0.171764,98.686792,0.758113,0.00758113,0,-0.181127,-0.01708,100,69.7805,0,0,0,0,0,0
1144,44677.62777,1143.568248,78255770,0.830421,0.849722,72.281541,23.931733,-0.170168,-0.150859,102.245088,0.787617,0.00787617,0,-0.16052,-0.01436,100,69.7918,0,0,0,0,0,0
1188,44677.62828,1187.568248,78255814,0.853448,0.873319,75.099444,23.955399,-0.147078,-0.127159,106.246947,0.820967,0.00820967,0,-0.137128,-0.02261,100,69.806,0,0,0,0,0,0
1232,44677.62879,1231.568248,78255858,0.874856,0.895265,77.545556,23.979066,-0.12567,-0.105137,109.696911,0.851942,0.00851942,0,-0.115493,-0.02421,100,69.8211,0,0,0,0,0,0
1276,44677.62929,1275.568248,78255902,0.865434,0.885785,74.893494,23.973149,-0.135203,-0.114998,105.967021,0.838349,0.00838349,0,-0.124979,0.01074,100,69.8241,0,0,0,0,0,0
1320,44677.6298,1319.568248,78255946,0.842899,0.862427,70.640788,23.952441,-0.157918,-0.138302,99.945461,0.805429,0.00805429,0,-0.148129,0.0108,100,69.8149,0,0,0,0,0,0
1364,44677.63031,1363.568248,78255990,0.820783,0.840043,66.623083,23.929761,-0.179981,-0.160654,94.274373,0.773663,0.00773663,0,-0.170313,0.01062,100,69.8075,0,0,0,0,0,0
1408,44677.63082,1407.568248,78256034,0.799957,0.819117,62.948314,23.908066,-0.200839,-0.181658,89.066048,0.74383,0.0074383,0,-0.191171,0.01077,100,69.8002,0,0,0,0,0,0
1452,44677.63133,1451.568248,78256078,0.778055,0.797492,59.201285,23.88933,-0.222643,-0.203089,83.765957,0.712822,0.00712822,0,-0.212981,0.01083,100,69.7923,0,0,0,0,0,0
1496,44677.63184,1495.568248,78256122,0.756439,0.776037,55.550427,23.868622,-0.24426,-0.224816,78.592674,0.682077,0.00682077,0,-0.234398,0.00949,100,69.7843,0,0,0,0,0,0
1540,44677.63235,1539.568248,78256166,0.734037,0.753974,51.839283,23.845941,-0.266806,-0.246707,73.34206,0.650148,0.00650148,0,-0.256746,0.01149,100,69.7761,0,0,0,0,0,0
1584,44677.63286,1583.568248,78256210,0.711944,0.731721,48.33898,23.825233,-0.288833,-0.268927,68.389591,0.618555,0.00618555,0,-0.278864,0.0101,100,69.7681,0,0,0,0,0,0
1628,44677.63337,1627.568248,78256254,0.691592,0.710046,45.193409,23.805511,-0.30925,-0.290654,63.947175,0.588446,0.00588446,0,-0.299912,0.01077,100,69.7605,0,0,0,0,0,0
1672,44677.63388,1671.568248,78256298,0.670534,0.687202,42.050553,23.78283,-0.330245,-0.313597,59.503359,0.557224,0.00557224,0,-0.321795,0.00935,100,69.7527,0,0,0,0,0,0
1716,44677.63439,1715.568248,78256342,0.648015,0.664614,38.805524,23.761136,-0.352714,-0.336212,54.905066,0.524985,0.00524985,0,-0.344362,0.01117,100,69.7443,0,0,0,0,0,0
1760,44677.6349,1759.568248,78256386,0.623654,0.639434,35.356752,23.737469,-0.377101,-0.361226,50.028585,0.489522,0.00489522,0,-0.369127,0.0161,100,69.7353,0,0,0,0,0,0
1804,44677.63541,1803.568248,78256430,0.604099,0.61926,32.68978,23.718733,-0.396851,-0.381408,46.25631,0.460934,0.00460934,0,-0.389224,0.01077,100,69.7274,0,0,0,0,0,0
1848,44677.63591,1847.568248,78256474,0.580818,0.596122,29.716655,23.695066,-0.419972,-0.404647,42.042724,0.428035,0.00428035,0,-0.412228,0.01326,100,69.7188,0,0,0,0,0,0
1892,44677.63642,1891.568248,78256518,0.561218,0.576729,27.274788,23.677316,-0.439604,-0.42427,38.590345,0.400098,0.00400098,0,-0.431858,0.00941,100,69.7116,0,0,0,0,0,0
1936,44677.63693,1935.568248,78256562,0.539093,0.554747,24.634651,23.655622,-0.461792,-0.445964,34.860064,0.368501,0.00368501,0,-0.453984,0.00949,100,69.7035,0,0,0,0,0,0
1980,44677.63744,1979.568248,78256606,0.515996,0.532741,22.020889,23.631955,-0.48479,-0.467987,31.157046,0.336374,0.00336374,0,-0.47639,0.01097,100,69.6956,0,0,0,0,0,0
2024,44677.63795,2023.568248,78256650,0.492479,0.509526,19.429184,23.609275,-0.508342,-0.491324,27.492768,0.302928,0.00302928,0,-0.499802,0.01045,100,69.6874,0,0,0,0,0,0
2068,44677.63846,2067.568248,78256694,0.478158,0.494785,18.042197,23.592511,-0.52251,-0.505984,25.524702,0.282344,0.00282344,0,-0.514273,0.00402,100,69.6818,0,0,0,0,0,0
2112,44677.63897,2111.568248,78256738,0.47877,0.495192,19.382975,23.592511,-0.521036,-0.504472,27.63207,0.285522,0.00285522,0,-0.512136,1.23838,148.6,68.8311,0,0,0,0,0,0
2156,44677.63948,2155.568248,78256782,0.478421,0.494721,20.347051,23.590538,-0.522232,-0.506116,28.826273,0.282498,0.00282498,0,-0.514104,0.14595,200,67.9127,0,0,0,0,0,0
2200,44677.63999,2199.568248,78256826,0.497745,0.513849,23.015668,23.609275,-0.502918,-0.486723,32.555424,0.31001,0.0031001,0,-0.494845,0.04393,200,67.8687,0,0,0,0,0,0
2244,44677.6405,2243.568248,78256870,0.519638,0.535474,25.983744,23.631955,-0.480972,-0.465029,36.757963,0.341091,0.00341091,0,-0.473007,0.02664,200,67.8456,0,0,0,0,0,0
2288,44677.64101,2287.568248,78256914,0.542369,0.557209,29.131886,23.65365,-0.458246,-0.4434,41.198555,0.372849,0.00372849,0,-0.450851,0.0174,200,67.8307,0,0,0,0,0,0
2332,44677.64152,2331.568248,78256958,0.565273,0.579718,32.4382,23.67633,-0.435321,-0.420851,45.890819,0.40532,0.0040532,0,-0.428128,0.01282,200,67.8204,0,0,0,0,0,0
2376,44677.64203,2375.568248,78257002,0.586631,0.600582,35.577304,23.696052,-0.414031,-0.399946,50.326345,0.435461,0.00435461,0,-0.407051,0.00912,200,67.8132,0,0,0,0,0,0
2420,44677.64254,2419.568248,78257046,0.608382,0.622303,38.876478,23.717747,-0.392224,-0.378219,54.990894,0.466539,0.00466539,0,-0.385272,0.00642,200,67.808,0,0,0,0,0,0
2464,44677.64304,2463.568248,78257090,0.630668,0.644993,42.312122,23.736483,-0.370078,-0.355506,59.850393,0.49861,0.0049861,0,-0.362821,0.00425,200,67.8049,0,0,0,0,0,0
2508,44677.64355,2507.568248,78257134,0.6519,0.666999,45.682556,23.758177,-0.348706,-0.333516,64.620101,0.529539,0.00529539,0,-0.341092,0.0022,200,67.8029,0,0,0,0,0,0
2552,44677.64406,2551.568248,78257178,0.674619,0.690293,49.351674,23.779872,-0.3259,-0.309916,69.792591,0.562537,0.00562537,0,-0.317971,0.00124,200,67.802,0,0,0,0,0,0
2596,44677.64457,2595.568248,78257222,0.695147,0.712748,52.658211,23.799594,-0.30543,-0.287926,74.484511,0.593145,0.00593145,0,-0.29665,0,200,67.802,0,0,0,0,0,0
2640,44677.64508,2639.568248,78257266,0.716395,0.735096,56.098661,23.822274,-0.284301,-0.265246,79.356009,0.624246,0.00624246,0,-0.274944,0,200,67.802,0,0,0,0,0,0
2684,44677.64559,2683.568248,78257310,0.737801,0.756631,59.634326,23.841997,-0.262778,-0.243716,84.360892,0.654912,0.00654912,0,-0.253402,-0.00874,200,67.8038,0,0,0,0,0,0
2728,44677.6461,2727.568248,78257354,0.75994,0.77805,63.31973,23.863691,-0.240635,-0.222449,89.573429,0.686156,0.00686156,0,-0.231531,-0.00286,200,67.8078,0,0,0,0,0,0
2772,44677.64661,2771.568248,78257398,0.782157,0.800362,67.019348,23.886372,-0.218404,-0.200098,94.801688,0.717921,0.00717921,0,-0.20937,-0.00359,200,67.811,0,0,0,0,0,0
2816,44677.64712,2815.568248,78257442,0.80453,0.823252,70.767695,23.90708,-0.195888,-0.177352,100.105097,0.750314,0.00750314,0,-0.186637,-0.00419,200,67.8147,0,0,0,0,0,0
2860,44677.64763,2859.568248,78257486,0.826281,0.84519,74.356892,23.928774,-0.17429,-0.155395,105.187173,0.781489,0.00781489,0,-0.164797,-0.00411,200,67.8186,0,0,0,0,0,0
2904,44677.64814,2903.568248,78257530,0.847988,0.86724,77.949128,23.953427,-0.152554,-0.133207,110.267782,0.812726,0.00812726,0,-0.142936,-0.00445,200,67.8232,0,0,0,0,0,0
2948,44677.64865,2947.568248,78257574,0.870757,0.890755,81.71429,23.974135,-0.129631,-0.10987,115.597166,0.845907,0.00845907,0,-0.119649,-0.00842,200,67.8285,0,0,0,0,0,0
2992,44677.64916,2991.568248,78257618,0.892501,0.912294,85.218991,23.998788,-0.107999,-0.088274,120.560222,0.876678,0.00876678,0,-0.098177,-0.00955,200,67.8337,0,0,0,0,0,0
3036,44677.64966,3035.568248,78257662,0.9137,0.933421,88.58337,24.016538,-0.086828,-0.066975,125.314084,0.906989,0.00906989,0,-0.076959,-0.00744,200,67.8394,0,0,0,0,0,0
3080,44677.65017,3079.568248,78257706,0.937933,0.957167,92.345109,24.040205,-0.062671,-0.043407,130.641044,0.94114,0.0094114,0,-0.053056,-0.01242,200,67.8467,0,0,0,0,0,0
3124,44677.65068,3123.568248,78257750,0.95898,0.978087,95.527298,24.061899,-0.041417,-0.02237,135.135773,0.971337,0.00971337,0,-0.031916,-0.00987,200,67.8536,0,0,0,0,0,0
3168,44677.65119,3167.568248,78257794,0.981821,1.00015,98.866014,24.083594,-0.01871,-0.000347,139.85869,1.003301,0.01003301,0,-0.00951,-0.01358,200,67.8613,0,0,0,0,0,0
3212,44677.6517,3211.568248,78257838,1.003051,1.020969,101.849044,24.105288,0.002498,0.020591,144.077451,1.033288,0.01033288,0,0.011556,-0.01201,200,67.8697,0,0,0,0,0,0
3256,44677.65221,3255.568248,78257882,1.026013,1.043901,105.057974,24.128955,0.025641,0.043534,148.613901,1.066349,0.01066349,0,0.034632,-0.01497,200,67.8798,0,0,0,0,0,0
3300,44677.65272,3299.568248,78257926,1.047669,1.06498,107.742524,24.150649,0.04715,0.064636,152.416968,1.09668,0.0109668,0,0.055891,-0.01818,200,67.891,0,0,0,0,0,0
3344,44677.65323,3343.568248,78257970,1.055392,1.073399,107.759711,24.162483,0.054808,0.072887,152.461016,1.108152,0.01108152,0,0.063852,0,200,67.8994,0,0,0,0,0,0
3388,44677.65374,3387.568248,78258014,1.033824,1.051729,103.323952,24.143747,0.033264,0.051061,146.186912,1.077289,0.01077289,0,0.042167,0.00946,200,67.8907,0,0,0,0,0,0
3432,44677.65425,3431.568248,78258058,1.011902,1.029528,98.923453,24.119094,0.010981,0.02848,139.995077,1.045313,0.01045313,0,0.01981,0.01007,200,67.8835,0,0,0,0,0,0
3476,44677.65476,3475.568248,78258102,0.988218,1.00608,94.472591,24.097399,-0.012321,0.005668,133.657899,1.012127,0.01012127,0,-0.003363,0.01204,200,67.876,0,0,0,0,0,0
3520,44677.65527,3519.568248,78258146,0.967206,0.985662,90.531104,24.076691,-0.033502,-0.014876,128.081587,0.982333,0.00982333,0,-0.024219,0.01083,200,67.8689,0,0,0,0,0,0
3564,44677.65578,3563.568248,78258190,0.944115,0.962788,86.256157,24.053024,-0.056566,-0.037753,122.040027,0.949526,0.00949526,0,-0.047161,0.01285,200,67.8614,0,0,0,0,0,0
3608,44677.65629,3607.568248,78258234,0.924107,0.943203,82.627828,24.03626,-0.076573,-0.057508,116.893083,0.921183,0.00921183,0,-0.067024,0.00755,200,67.8546,0,0,0,0,0,0
3652,44677.65679,3651.568248,78258278,0.901577,0.920743,78.533895,24.014566,-0.099078,-0.079925,111.109157,0.889151,0.00889151,0,-0.089443,0.00929,200,67.8469,0,0,0,0,0,0
3696,44677.6573,3695.568248,78258322,0.880219,0.899519,74.736482,23.993858,-0.120529,-0.101126,105.747164,0.858575,0.00858575,0,-0.11085,0.00958,200,67.8396,0,0,0,0,0,0
3740,44677.65781,3739.568248,78258366,0.858594,0.877272,70.968326,23.972163,-0.142207,-0.123609,100.405096,0.827193,0.00827193,0,-0.132758,0.00805,200,67.8324,0,0,0,0,0,0
3784,44677.65832,3783.568248,78258410,0.836363,0.854561,67.190501,23.949483,-0.16436,-0.146125,95.065681,0.795245,0.00795245,0,-0.155221,0.00822,200,67.8248,0,0,0,0,0,0
3828,44677.65883,3827.568248,78258454,0.814685,0.832361,63.544851,23.927788,-0.186138,-0.168247,89.905226,0.763711,0.00763711,0,-0.177286,0.00831,200,67.8174,0,0,0,0,0,0
3872,44677.65934,3871.568248,78258498,0.792948,0.810508,60.023492,23.904122,-0.207833,-0.190302,84.9248,0.732736,0.00732736,0,-0.198936,0.00784,200,67.8102,0,0,0,0,0,0
3916,44677.65985,3915.568248,78258542,0.768754,0.786202,56.134405,23.882427,-0.231918,-0.214659,79.414951,0.697939,0.00697939,0,-0.223294,0.01106,200,67.8023,0,0,0,0,0,0
3960,44677.66036,3959.568248,78258586,0.748589,0.766354,53.000243,23.861719,-0.252186,-0.234414,74.988552,0.669366,0.00669366,0,-0.243296,0.01187,200,67.7953,0,0,0,0,0,0
4004,44677.66087,4003.568248,78258630,0.726432,0.744595,49.604172,23.840024,-0.274277,-0.256239,70.179035,0.638193,0.00638193,0,-0.265103,0.01007,200,67.7882,0,0,0,0,0,0
4048,44677.66138,4047.568248,78258674,0.703875,0.721163,46.249492,23.81833,-0.296873,-0.279413,65.438553,0.60528,0.0060528,0,-0.288156,0.00996,200,67.7808,0,0,0,0,0,0
4092,44677.66189,4091.568248,78258718,0.684798,0.700388,43.476024,23.799594,-0.315934,-0.300285,61.509583,0.576742,0.00576742,0,-0.308192,0.00897,200,67.7749,0,0,0,0,0,0
4136,44677.6624,4135.568248,78258762,0.65961,0.673929,39.841717,23.773955,-0.341269,-0.326942,56.373361,0.539806,0.00539806,0,-0.334104,0.00987,200,67.7681,0,0,0,0,0,0
4180,44677.66291,4179.568248,78258806,0.639359,0.653334,37.124447,23.754233,-0.361431,-0.347519,52.521815,0.510691,0.00510691,0,-0.354368,0.00825,200,67.761,0,0,0,0,0,0
4224,44677.66341,4223.568248,78258850,0.619451,0.632821,34.452967,23.734511,-0.381344,-0.367832,48.745035,0.481739,0.00481739,0,-0.374675,0.0092,200,67.7552,0,0,0,0,0,0
4268,44677.66392,4267.568248,78258894,0.596789,0.609902,31.510668,23.71183,-0.403985,-0.390841,44.584913,0.449383,0.00449383,0,-0.397431,0.007,200,67.7487,0,0,0,0,0,0
4312,44677.66443,4311.568248,78258938,0.575073,0.588207,28.804091,23.692108,-0.425736,-0.412535,40.758301,0.418176,0.00418176,0,-0.419129,0.00602,200,67.7427,0,0,0,0,0,0
4356,44677.66494,4355.568248,78258982,0.552277,0.565513,26.088068,23.6714,-0.448536,-0.43538,36.911933,0.385624,0.00385624,0,-0.441937,0.00657,200,67.7368,0,0,0,0,0,0
4400,44677.66545,4399.568248,78259026,0.545476,0.558561,26.356927,23.660552,-0.454296,-0.441034,37.177427,0.376638,0.00376638,0,-0.447963,3.40851,235.2,67.2081,0,0,0,0,0,0
4444,44677.66596,4443.568248,78259070,0.550686,0.563431,28.168865,23.663511,-0.450794,-0.437845,39.922083,0.382742,0.00382742,0,-0.444037,-0.08514,300,66.1755,0,0,0,0,0,0
4488,44677.66647,4487.568248,78259114,0.572414,0.584755,31.60715,23.683233,-0.428181,-0.415822,44.708035,0.414109,0.00414109,0,-0.422076,0.04178,300,66.1311,0,0,0,0,0,0
4532,44677.66698,4531.568248,78259158,0.59436,0.60619,34.876662,23.7069,-0.406393,-0.394457,49.334534,0.444964,0.00444964,0,-0.400365,0.02406,300,66.1096,0,0,0,0,0,0
4576,44677.66749,4575.568248,78259202,0.616581,0.628438,38.298531,23.725636,-0.383994,-0.372171,54.177269,0.476827,0.00476827,0,-0.378073,0.01584,300,66.0956,0,0,0,0,0,0
4620,44677.668,4619.568248,78259246,0.637677,0.650253,41.600706,23.745358,-0.362913,-0.350214,58.849828,0.507473,0.00507473,0,-0.356601,0.01172,300,66.0857,0,0,0,0,0,0
4664,44677.66851,4663.568248,78259290,0.659213,0.672153,45.042206,23.767052,-0.341355,-0.328487,63.713891,0.538464,0.00538464,0,-0.334838,0.0086,300,66.0789,0,0,0,0,0,0
4708,44677.66902,4707.568248,78259334,0.681404,0.695252,48.62236,23.788747,-0.319231,-0.305215,68.771104,0.570849,0.00570849,0,-0.312258,0.00483,300,66.0744,0,0,0,0,0,0
4752,44677.66953,4751.568248,78259378,0.7025,0.718539,52.128324,23.808469,-0.298009,-0.281779,73.735282,0.602608,0.00602608,0,-0.290026,0.00405,300,66.0712,0,0,0,0,0,0
4796,44677.67004,4795.568248,78259422,0.722965,0.739643,55.497265,23.829177,-0.27761,-0.260973,78.505651,0.632311,0.00632311,0,-0.269214,0.00249,300,66.069,0,0,0,0,0,0
4840,44677.67054,4839.568248,78259466,0.745556,0.762256,59.295999,23.848899,-0.255067,-0.238292,83.883606,0.664537,0.00664537,0,-0.24665,0.00118,300,66.0686,0,0,0,0,0,0
4884,44677.67105,4883.568248,78259510,0.768158,0.784457,63.154939,23.873552,-0.232383,-0.216039,89.337839,0.696605,0.00696605,0,-0.224196,0,300,66.0684,0,0,0,0,0,0
4928,44677.67156,4927.568248,78259554,0.790769,0.807321,67.027673,23.894261,-0.209851,-0.193392,94.816463,0.728892,0.00728892,0,-0.20155,0,300,66.0684,0,0,0,0,0,0
4972,44677.67207,4971.568248,78259598,0.810871,0.827698,70.493596,23.914969,-0.189581,-0.172783,99.720965,0.757973,0.00757973,0,-0.181237,-0.00715,300,66.07,0,0,0,0,0,0
5016,44677.67258,5015.568248,78259642,0.832853,0.849976,74.301175,23.937649,-0.167686,-0.150398,105.109797,0.789649,0.00789649,0,-0.159097,0,300,66.0759,0,0,0,0,0,0
5060,44677.67309,5059.568248,78259686,0.854964,0.872613,78.14853,23.958358,-0.14546,-0.127784,110.537414,0.821684,0.00821684,0,-0.136668,-0.00532,300,66.0787,0,0,0,0,0,0
5104,44677.6736,5103.568248,78259730,0.877704,0.896062,82.10167,23.982024,-0.122719,-0.104479,116.143534,0.854711,0.00854711,0,-0.113525,-0.00674,300,66.0818,0,0,0,0,0,0
5148,44677.67411,5147.568248,78259774,0.898843,0.916957,85.745932,24.003719,-0.101722,-0.08364,121.304314,0.884539,0.00884539,0,-0.092688,-0.00715,300,66.0853,0,0,0,0,0,0
5192,44677.67462,5191.568248,78259818,0.920735,0.938689,89.575081,24.022455,-0.079835,-0.061814,126.719348,0.915757,0.00915757,0,-0.070792,-0.00095,300,66.0888,0,0,0,0,0,0
5236,44677.67513,5235.568248,78259862,0.942374,0.959927,93.350531,24.045135,-0.058106,-0.040613,132.050035,0.946389,0.00946389,0,-0.049305,-0.00454,300,66.0931,0,0,0,0,0,0
5280,44677.67564,5279.568248,78259906,0.965969,0.983227,97.418654,24.067816,-0.034478,-0.017177,137.804676,0.979911,0.00979911,0,-0.025837,-0.00834,300,66.0982,0,0,0,0,0,0
5324,44677.67615,5323.568248,78259950,0.988676,1.005186,101.253877,24.08951,-0.011898,0.004715,143.237234,1.011745,0.01011745,0,-0.003614,-0.0112,300,66.1034,0,0,0,0,0,0
5368,44677.67666,5367.568248,78259994,1.010785,1.027214,105.024712,24.111205,0.010383,0.02677,148.576051,1.04344,0.0104344,0,0.018625,-0.00883,300,66.1084,0,0,0,0,0,0
5412,44677.67716,5411.568248,78260038,1.032629,1.048818,108.710782,24.133885,0.032199,0.048399,153.785975,1.07452,0.0107452,0,0.040328,-0.00967,300,66.1141,0,0,0,0,0,0
5456,44677.67767,5455.568248,78260082,1.054077,1.070003,112.224127,24.15558,0.05356,0.069435,158.755104,1.10487,0.0110487,0,0.061557,-0.00839,300,66.1201,0,0,0,0,0,0
5500,44677.67818,5499.568248,78260126,1.076169,1.092209,115.869801,24.176288,0.075729,0.091656,163.913415,1.136526,0.01136526,0,0.083684,-0.01201,300,66.1264,0,0,0,0,0,0
5544,44677.67869,5543.568248,78260170,1.096388,1.112769,119.08596,24.196997,0.09593,0.112396,168.467943,1.165716,0.01165716,0,0.10415,-0.00723,300,66.133,0,0,0,0,0,0
5588,44677.6792,5587.568248,78260214,1.11906,1.13593,122.665546,24.217705,0.11859,0.13557,173.530161,1.198494,0.01198494,0,0.127094,-0.01175,300,66.1403,0,0,0,0,0,0
5632,44677.67971,5631.568248,78260258,1.141743,1.159413,126.122853,24.242358,0.14141,0.15894,178.424361,1.231508,0.01231508,0,0.150203,-0.01459,300,66.1485,0,0,0,0,0,0
5676,44677.68022,5675.568248,78260302,1.161984,1.179824,129.011467,24.263066,0.161573,0.179287,182.508462,1.260538,0.01260538,0,0.170459,-0.01045,300,66.1567,0,0,0,0,0,0
5720,44677.68073,5719.568248,78260346,1.184916,1.202291,132.13431,24.287719,0.184454,0.202033,186.926968,1.292888,0.01292888,0,0.193231,-0.01282,300,66.1663,0,0,0,0,0,0
5764,44677.68124,5763.568248,78260390,1.186388,1.204697,131.229065,24.293635,0.1858,0.204235,185.661359,1.295412,0.01295412,0,0.194936,0,300,66.1713,0,0,0,0,0,0
5808,44677.68175,5807.568248,78260434,1.163196,1.182258,126.39579,24.274899,0.162549,0.181785,178.819111,1.262873,0.01262873,0,0.172084,0.00695,300,66.1596,0,0,0,0,0,0
5852,44677.68226,5851.568248,78260478,1.142651,1.16177,122.178102,24.252219,0.142061,0.161143,172.85601,1.233594,0.01233594,0,0.151667,0.00793,300,66.1532,0,0,0,0,0,0
5896,44677.68277,5895.568248,78260522,1.12023,1.138678,117.642833,24.230524,0.119609,0.138068,166.437801,1.201112,0.01201112,0,0.128854,0.00752,300,66.1463,0,0,0,0,0,0
5940,44677.68328,5939.568248,78260566,1.09869,1.116572,113.370349,24.209816,0.098034,0.116078,160.3986,1.169834,0.01169834,0,0.107032,0.00671,300,66.1398,0,0,0,0,0,0
5984,44677.68379,5983.568248,78260610,1.076816,1.094129,109.11077,24.188122,0.076224,0.093431,154.368998,1.138296,0.01138296,0,0.084955,0.00779,300,66.1332,0,0,0,0,0,0
6028,44677.68429,6027.568248,78260654,1.054603,1.071454,104.834808,24.164455,0.05392,0.070915,148.32283,1.106035,0.01106035,0,0.062373,0.01048,300,66.1264,0,0,0,0,0,0
6072,44677.6848,6071.568248,78260698,1.034038,1.050689,100.932888,24.146705,0.033259,0.050009,142.799521,1.076452,0.01076452,0,0.041664,0.00819,300,66.1199,0,0,0,0,0,0
6116,44677.68531,6115.568248,78260742,1.00883,1.025454,96.221751,24.12008,0.008129,0.024831,136.125155,1.040421,0.01040421,0,0.016397,0.01172,300,66.1125,0,0,0,0,0,0
6160,44677.68582,6159.568248,78260786,0.989261,1.005815,92.662895,24.101344,-0.011497,0.00501,131.105838,1.01244,0.0101244,0,-0.003101,0.00706,300,66.1064,0,0,0,0,0,0
6204,44677.68633,6203.568248,78260830,0.965715,0.982943,88.459134,24.077677,-0.035,-0.017768,125.145727,0.979289,0.00979289,0,-0.026346,0.01236,300,66.0993,0,0,0,0,0,0
6248,44677.68684,6247.568248,78260874,0.941805,0.9593,84.220203,24.05401,-0.05892,-0.041402,119.149761,0.945219,0.00945219,0,-0.050199,0.01146,300,66.0923,0,0,0,0,0,0
6292,44677.68735,6291.568248,78260918,0.921087,0.939088,80.630795,24.035274,-0.079605,-0.061485,114.077189,0.916139,0.00916139,0,-0.070533,0.00926,300,66.0859,0,0,0,0,0,0
6336,44677.68786,6335.568248,78260962,0.901101,0.91922,77.126306,24.016538,-0.09973,-0.081536,109.125918,0.887612,0.00887612,0,-0.090524,0.00747,300,66.0795,0,0,0,0,0,0
6380,44677.68837,6379.568248,78261006,0.876365,0.894768,72.933264,23.991885,-0.124322,-0.10609,103.184482,0.85255,0.0085255,0,-0.115067,0.0108,300,66.0723,0,0,0,0,0,0
6424,44677.68888,6423.568248,78261050,0.855478,0.873115,69.420085,23.970191,-0.145239,-0.127488,98.220119,0.822158,0.00822158,0,-0.136341,0.01016,300,66.0664,0,0,0,0,0,0
6468,44677.68939,6467.568248,78261094,0.832477,0.849951,65.854033,23.946524,-0.167554,-0.150103,93.109507,0.789907,0.00789907,0,-0.158917,0.01062,300,66.0597,0,0,0,0,0,0
6512,44677.6899,6511.568248,78261138,0.812326,0.828935,62.364938,23.92483,-0.188368,-0.171599,88.233961,0.759771,0.00759771,0,-0.180012,0.01048,300,66.0537,0,0,0,0,0,0
6556,44677.69041,6555.568248,78261182,0.790646,0.807213,58.916974,23.902149,-0.210098,-0.193458,83.364236,0.728704,0.00728704,0,-0.201759,0.00666,300,66.0477,0,0,0,0,0,0
6600,44677.69091,6599.568248,78261226,0.769152,0.785741,55.591455,23.884399,-0.231557,-0.215086,78.648723,0.698055,0.00698055,0,-0.223214,0.00883,300,66.0418,0,0,0,0,0,0
6644,44677.69142,6643.568248,78261270,0.745008,0.762096,51.890742,23.858761,-0.255722,-0.23849,73.413034,0.663852,0.00663852,0,-0.247156,0.00944,300,66.0352,0,0,0,0,0,0
6688,44677.69193,6687.568248,78261314,0.724151,0.741196,48.722506,23.839038,-0.276799,-0.259658,68.943482,0.63383,0.0063383,0,-0.268175,0.0068,300,66.0296,0,0,0,0,0,0
6732,44677.69244,6731.568248,78261358,0.702182,0.718304,45.541941,23.81833,-0.298641,-0.282338,64.432404,0.601937,0.00601937,0,-0.290514,0.0059,300,66.0238,0,0,0,0,0,0
6776,44677.69295,6775.568248,78261402,0.682229,0.696285,42.702486,23.798608,-0.318569,-0.304591,60.416968,0.571889,0.00571889,0,-0.311551,0.00625,300,66.0186,0,0,0,0,0,0
6820,44677.69346,6819.568248,78261446,0.659692,0.673033,39.579274,23.774941,-0.341113,-0.327633,55.998608,0.539196,0.00539196,0,-0.334478,0.00628,300,66.0128,0,0,0,0,0,0
6864,44677.69397,6863.568248,78261490,0.637916,0.65107,36.633127,23.754233,-0.362888,-0.34959,51.831217,0.507927,0.00507927,0,-0.356315,0.00637,300,66.0075,0,0,0,0,0,0
6908,44677.69448,6907.568248,78261534,0.616282,0.628613,33.93276,23.730566,-0.384225,-0.371974,48.008608,0.476802,0.00476802,0,-0.378091,0.00851,300,66.002,0,0,0,0,0,0
6952,44677.69499,6951.568248,78261578,0.603802,0.616041,32.638638,23.716761,-0.396577,-0.384497,46.147798,0.458968,0.00458968,0,-0.390574,1.38773,308.2,65.8837,0,0,0,0,0,0
6996,44677.6955,6995.568248,78261622,0.601866,0.614285,32.825115,23.715775,-0.400665,-0.388014,46.321954,0.453473,0.00453473,0,-0.394449,0.02316,345.5,65.3376,0,0,0,0,0,0
7040,44677.69601,7039.568248,78261666,0.608877,0.62092,35.44922,23.721691,-0.391076,-0.379074,50.229495,0.466718,0.00466718,0,-0.385149,-0.08514,400,64.5512,0,0,0,0,0,0
7084,44677.69652,7083.568248,78261710,0.629741,0.642037,38.859179,23.741413,-0.369964,-0.357709,54.861776,0.496575,0.00496575,0,-0.363991,0.03402,400,64.5138,0,0,0,0,0,0
7128,44677.69703,7127.568248,78261754,0.652283,0.664864,42.342206,23.761136,-0.348127,-0.335587,59.880318,0.528498,0.00528498,0,-0.341904,0.02061,400,64.4957,0,0,0,0,0,0
7172,44677.69754,7171.568248,78261798,0.674302,0.686969,45.863338,23.781844,-0.326302,-0.313531,64.874174,0.559886,0.00559886,0,-0.319909,0.0143,400,64.484,0,0,0,0,0,0
7216,44677.69804,7215.568248,78261842,0.694924,0.709247,49.23874,23.802552,-0.305775,-0.291377,69.652173,0.590452,0.00590452,0,-0.298484,0.00894,400,64.4757,0,0,0,0,0,0
7260,44677.69855,7259.568248,78261886,0.716169,0.732149,52.788495,23.823261,-0.284466,-0.268434,74.674197,0.621931,0.00621931,0,-0.276424,0.00857,400,64.4701,0,0,0,0,0,0
7304,44677.69906,7303.568248,78261930,0.737581,0.753958,56.395907,23.842983,-0.263021,-0.24651,79.761963,0.652835,0.00652835,0,-0.254809,0.00295,400,64.4662,0,0,0,0,0,0
7348,44677.69957,7347.568248,78261974,0.759822,0.775825,60.291912,23.865663,-0.240395,-0.224356,85.243909,0.68483,0.0068483,0,-0.232453,0.00083,400,64.4639,0,0,0,0,0,0
7392,44677.70008,7391.568248,78262018,0.781296,0.797341,63.93114,23.886372,-0.219224,-0.20322,90.441742,0.715175,0.00715175,0,-0.21128,0.00063,400,64.4625,0,0,0,0,0,0
7436,44677.70059,7435.568248,78262062,0.803205,0.819583,67.746894,23.908066,-0.197286,-0.180902,95.83625,0.746771,0.00746771,0,-0.189097,0.00066,400,64.4619,0,0,0,0,0,0
7480,44677.7011,7479.568248,78262106,0.82462,0.841203,71.484215,23.928774,-0.175982,-0.159405,101.120244,0.77736,0.0077736,0,-0.167728,0,400,64.4619,0,0,0,0,0,0
7524,44677.70161,7523.568248,78262150,0.847094,0.864116,75.447064,23.951455,-0.153466,-0.136363,106.732107,0.809845,0.00809845,0,-0.14496,0,400,64.4619,0,0,0,0,0,0
7568,44677.70212,7567.568248,78262194,0.868449,0.886268,79.235839,23.972163,-0.1321,-0.114209,112.091193,0.840934,0.00840934,0,-0.123217,-0.00136,400,64.4672,0,0,0,0,0,0
7612,44677.70263,7611.568248,78262238,0.889946,0.907764,83.063987,23.99583,-0.11059,-0.092613,117.503674,0.871636,0.00871636,0,-0.101706,-0.0077,400,64.472,0,0,0,0,0,0
7656,44677.70314,7655.568248,78262282,0.911548,0.929249,87.007316,24.017524,-0.088661,-0.070952,123.046121,0.902668,0.00902668,0,-0.079918,-0.00367,400,64.474,0,0,0,0,0,0
7700,44677.70365,7699.568248,78262326,0.934838,0.952099,91.116684,24.039219,-0.065644,-0.04837,128.891135,0.935411,0.00935411,0,-0.057,-0.00002,400,64.4773,0,0,0,0,0,0
7744,44677.70416,7743.568248,78262370,0.956619,0.973761,94.978691,24.060913,-0.043914,-0.026775,134.36268,0.966427,0.00966427,0,-0.035344,0,400,64.4798,0,0,0,0,0,0
7788,44677.70466,7787.568248,78262414,0.97889,0.995574,98.934379,24.080635,-0.021515,-0.004851,139.959476,0.997994,0.00997994,0,-0.013227,-0.00781,400,64.4837,0,0,0,0,0,0
7832,44677.70517,7831.568248,78262458,1.000522,1.016757,102.724679,24.10233,0.000027,0.016219,145.316531,1.028596,0.01028596,0,0.008169,-0.00234,400,64.4868,0,0,0,0,0,0
7876,44677.70568,7875.568248,78262502,1.023898,1.039837,106.858035,24.125997,0.0234,0.039392,151.162778,1.061712,0.01061712,0,0.03138,-0.00014,400,64.4909,0,0,0,0,0,0
7920,44677.70619,7919.568248,78262546,1.047913,1.06382,111.154633,24.151635,0.047431,0.063289,157.314626,1.096135,0.01096135,0,0.055443,-0.00579,400,64.497,0,0,0,0,0,0
7964,44677.7067,7963.568248,78262590,1.068334,1.084448,114.761359,24.171358,0.067827,0.083931,162.349752,1.125391,0.01125391,0,0.075921,0,400,64.5,0,0,0,0,0,0
8008,44677.70721,8007.568248,78262634,1.090347,1.106579,118.655024,24.192066,0.089798,0.106053,167.857908,1.156934,0.01156934,0,0.098031,-0.00477,400,64.5053,0,0,0,0,0,0
8052,44677.70772,8051.568248,78262678,1.113784,1.130413,122.867892,24.215733,0.113285,0.129949,173.818008,1.190631,0.01190631,0,0.121616,-0.01586,400,64.5113,0,0,0,0,0,0
8096,44677.70823,8095.568248,78262722,1.133468,1.150543,126.238136,24.235455,0.132935,0.149967,178.589908,1.21907,0.0121907,0,0.141507,-0.01248,400,64.5158,0,0,0,0,0,0
8140,44677.70874,8139.568248,78262766,1.155163,1.172665,130.102651,24.257149,0.154705,0.17222,184.056666,1.25038,0.0125038,0,0.163399,-0.01057,400,64.5212,0,0,0,0,0,0
8184,44677.70925,8183.568248,78262810,1.176545,1.19372,133.748121,24.278844,0.176112,0.193289,189.213862,1.280784,0.01280784,0,0.184697,-0.00561,400,64.5272,0,0,0,0,0,0
8228,44677.70976,8227.568248,78262854,1.200155,1.216322,137.6118,24.30251,0.19969,0.215773,194.682242,1.313802,0.01313802,0,0.207822,-0.00709,400,64.5338,0,0,0,0,0,0
8272,44677.71027,8271.568248,78262898,1.222574,1.23838,141.234021,24.325191,0.222122,0.237993,199.795665,1.345619,0.01345619,0,0.230082,-0.0112,400,64.5402,0,0,0,0,0,0
8316,44677.71078,8315.568248,78262942,1.243222,1.258926,144.448321,24.346885,0.24286,0.258832,204.318786,1.375023,0.01375023,0,0.250784,-0.00961,400,64.5466,0,0,0,0,0,0
8360,44677.71129,8359.568248,78262986,1.26507,1.281167,147.740663,24.366608,0.264692,0.280789,209.000618,1.406544,0.01406544,0,0.272748,-0.00831,400,64.5539,0,0,0,0,0,0
8404,44677.71179,8403.568248,78263030,1.286953,1.30369,150.872403,24.389288,0.286487,0.303503,213.437319,1.438241,0.01438241,0,0.294951,-0.01117,400,64.562,0,0,0,0,0,0
8448,44677.7123,8447.568248,78263074,1.308987,1.327134,154.095751,24.411969,0.309076,0.3273,217.938351,1.471288,0.01471288,0,0.318173,-0.01039,400,64.5709,0,0,0,0,0,0
8492,44677.71281,8491.568248,78263118,1.305177,1.32373,152.005789,24.415913,0.304678,0.32306,215.051824,1.465452,0.01465452,0,0.313922,0.01717,400,64.5721,0,0,0,0,0,0
8536,44677.71332,8535.568248,78263162,1.282145,1.299888,147.062741,24.392247,0.281627,0.299525,208.055819,1.432077,0.01432077,0,0.290495,0.01239,400,64.5594,0,0,0,0,0,0
8580,44677.71383,8579.568248,78263206,1.259392,1.276357,142.33737,24.371538,0.258855,0.275925,201.364633,1.398835,0.01398835,0,0.267328,0.013,400,64.5527,0,0,0,0,0,0
8624,44677.71434,8623.568248,78263250,1.239821,1.256608,138.367398,24.351816,0.239246,0.256301,195.758989,1.370758,0.01370758,0,0.247678,0.01068,400,64.547,0,0,0,0,0,0
8668,44677.71485,8667.568248,78263294,1.21875,1.235544,134.121758,24.332094,0.218165,0.235034,189.756418,1.340696,0.01340696,0,0.226635,0.0081,400,64.5409,0,0,0,0,0,0
8712,44677.71536,8711.568248,78263338,1.196186,1.213393,129.716956,24.310399,0.195527,0.212814,183.515684,1.308625,0.01308625,0,0.204209,0.00674,400,64.5343,0,0,0,0,0,0
8756,44677.71587,8755.568248,78263382,1.174313,1.19205,125.50785,24.286733,0.173752,0.191449,177.562709,1.277892,0.01277892,0,0.182675,0.00999,400,64.5279,0,0,0,0,0,0
8800,44677.71638,8799.568248,78263426,1.152709,1.170727,121.283696,24.266024,0.15215,0.17005,171.578459,1.247147,0.01247147,0,0.161156,0.00741,400,64.5218,0,0,0,0,0,0
8844,44677.71689,8843.568248,78263470,1.130799,1.148079,116.956146,24.24433,0.130132,0.147534,165.470058,1.215214,0.01215214,0,0.138861,0.00735,400,64.5153,0,0,0,0,0,0
8888,44677.7174,8887.568248,78263514,1.109193,1.125603,112.829981,24.219677,0.108535,0.125019,159.619382,1.183902,0.01183902,0,0.116887,0.00816,400,64.5087,0,0,0,0,0,0
8932,44677.71791,8931.568248,78263558,1.086281,1.101892,108.410505,24.19601,0.085482,0.100991,153.394005,1.150295,0.01150295,0,0.093273,0.00674,400,64.5023,0,0,0,0,0,0
8976,44677.71841,8975.568248,78263602,1.065462,1.080744,104.609555,24.180233,0.064869,0.080085,147.991297,1.120613,0.01120613,0,0.072508,0.00419,400,64.496,0,0,0,0,0,0
9020,44677.71892,9019.568248,78263646,1.041758,1.056707,100.139982,24.153608,0.040829,0.055597,141.694094,1.086047,0.01086047,0,0.04833,0.00721,400,64.49,0,0,0,0,0,0
9064,44677.71943,9063.568248,78263690,1.019881,1.034946,96.195454,24.132899,0.019141,0.0341,136.098532,1.055135,0.01055135,0,0.026725,0.01109,400,64.4831,0,0,0,0,0,0
9108,44677.71994,9107.568248,78263734,0.998319,1.013015,92.37105,24.109233,-0.002363,0.012373,130.681531,1.024169,0.01024169,0,0.005067,0.0101,400,64.4767,0,0,0,0,0,0
9152,44677.72045,9151.568248,78263778,0.977759,0.992821,88.791853,24.090497,-0.022994,-0.007842,125.622966,0.995044,0.00995044,0,-0.015399,0.00489,400,64.4713,0,0,0,0,0,0
9196,44677.72096,9195.568248,78263822,0.956887,0.972206,85.182093,24.069788,-0.043869,-0.028451,120.514207,0.965281,0.00965281,0,-0.036155,0.00779,400,64.4655,0,0,0,0,0,0
9240,44677.72147,9239.568248,78263866,0.933867,0.949527,81.25157,24.047108,-0.066885,-0.051098,114.955288,0.932602,0.00932602,0,-0.05903,0.01019,400,64.4591,0,0,0,0,0,0
9284,44677.72198,9283.568248,78263910,0.912031,0.928223,77.484054,24.026399,-0.088793,-0.07253,109.646436,0.90176,0.0090176,0,-0.080607,0.00744,400,64.4534,0,0,0,0,0,0
9328,44677.72249,9327.568248,78263954,0.890595,0.906817,73.90451,24.005691,-0.11016,-0.093928,104.562258,0.871284,0.00871284,0,-0.102097,0.00434,400,64.4476,0,0,0,0,0,0
9372,44677.723,9371.568248,78263998,0.868209,0.884381,70.223532,23.983997,-0.132474,-0.116214,99.355754,0.839278,0.00839278,0,-0.124422,0.00359,400,64.442,0,0,0,0,0,0
9416,44677.72351,9415.568248,78264042,0.84518,0.860281,66.417338,23.96033,-0.155612,-0.14034,93.980127,0.805545,0.00805545,0,-0.148025,0.01001,400,64.4359,0,0,0,0,0,0
9460,44677.72402,9459.568248,78264086,0.825442,0.840308,63.319793,23.939622,-0.175262,-0.160358,89.581302,0.777284,0.00777284,0,-0.167806,0.00515,400,64.4311,0,0,0,0,0,0
9504,44677.72453,9503.568248,78264130,0.800291,0.814845,59.353535,23.913983,-0.200418,-0.185733,83.97946,0.741033,0.00741033,0,-0.193129,0.00732,400,64.4249,0,0,0,0,0,0
9548,44677.72504,9547.568248,78264174,0.778822,0.793386,55.919069,23.893274,-0.222376,-0.207855,79.161738,0.710005,0.00710005,0,-0.215019,0.00535,400,64.4206,0,0,0,0,0,0
9592,44677.72554,9591.568248,78264218,0.758026,0.772756,52.885695,23.872566,-0.242724,-0.227938,74.823971,0.680744,0.00680744,0,-0.235331,0.009,400,64.4149,0,0,0,0,0,0
9636,44677.72605,9635.568248,78264262,0.735049,0.750397,49.429069,23.847913,-0.265734,-0.250487,69.932055,0.648301,0.00648301,0,-0.25805,0.00909,400,64.4092,0,0,0,0,0,0
9680,44677.72656,9679.568248,78264306,0.714193,0.729062,46.468815,23.831149,-0.286467,-0.271688,65.749791,0.61841,0.0061841,0,-0.279074,0.00608,400,64.4038,0,0,0,0,0,0
9724,44677.72707,9723.568248,78264350,0.693175,0.706088,43.489126,23.808469,-0.307601,-0.294763,61.519504,0.586782,0.00586782,0,-0.301083,0.00544,400,64.3988,0,0,0,0,0,0
9768,44677.72758,9767.568248,78264394,0.672464,0.683921,40.604576,23.788747,-0.328326,-0.316983,57.452033,0.556101,0.00556101,0,-0.322585,0.0057,400,64.3939,0,0,0,0,0,0
9812,44677.72809,9811.568248,78264438,0.649139,0.660852,37.49603,23.763108,-0.351606,-0.339794,53.046744,0.52313,0.0052313,0,-0.345669,0.00564,400,64.3886,0,0,0,0,0,0
9856,44677.7286,9855.568248,78264482,0.626745,0.637541,34.51363,23.743386,-0.374089,-0.363099,48.834697,0.490343,0.00490343,0,-0.368652,0.01048,400,64.3836,0,0,0,0,0,0
9900,44677.72911,9899.568248,78264526,0.606931,0.617412,32.069161,23.722677,-0.393832,-0.383413,45.375239,0.461904,0.00461904,0,-0.388519,0.00188,400,64.3793,0,0,0,0,0,0
9944,44677.72962,9943.568248,78264570,0.585373,0.595843,29.484838,23.702955,-0.415422,-0.404811,41.722755,0.430995,0.00430995,0,-0.410155,0.0055,400,64.3743,0,0,0,0,0,0
9988,44677.73013,9987.568248,78264614,0.563649,0.574261,26.952367,23.680275,-0.437271,-0.426374,38.138891,0.399973,0.00399973,0,-0.431871,0.00683,400,64.3691,0,0,0,0,0,0
10032,44677.73064,10031.56825,78264658,0.542018,0.553234,24.598196,23.660552,-0.458839,-0.447607,34.805951,0.369533,0.00369533,0,-0.45321,0.00593,400,64.3642,0,0,0,0,0,0
10076,44677.73115,10075.56825,78264702,0.518114,0.530194,22.083657,23.636886,-0.482645,-0.470518,31.248833,0.336168,0.00336168,0,-0.476638,0.00579,400,64.3585,0,0,0,0,0,0
10120,44677.73166,10119.56825,78264746,0.495571,0.507571,19.739426,23.615191,-0.505352,-0.493264,27.929936,0.303657,0.00303657,0,-0.499297,0.0077,400,64.3533,0,0,0,0,0,0
10164,44677.73216,10163.56825,78264790,0.471867,0.484793,17.454558,23.589552,-0.528977,-0.516042,24.696656,0.270603,0.00270603,0,-0.522429,0.01016,400,64.348,0,0,0,0,0,0
10208,44677.73267,10207.56825,78264834,0.448732,0.464048,15.313102,23.568844,-0.552409,-0.537112,21.683941,0.238841,0.00238841,0,-0.544671,0.00946,400,64.3433,0,0,0,0,0,0
10252,44677.73318,10251.56825,78264878,0.46055,0.473614,17.016904,23.574761,-0.540216,-0.527054,24.070133,0.254518,0.00254518,0,-0.533689,-0.0022,400,64.3435,0,0,0,0,0,0
10296,44677.73369,10295.56825,78264922,0.484675,0.4961,19.877035,23.593497,-0.515972,-0.504538,28.109255,0.287969,0.00287969,0,-0.510243,-0.00556,400,64.353,0,0,0,0,0,0
10340,44677.7342,10339.56825,78264966,0.508176,0.519417,22.788216,23.61815,-0.492502,-0.481036,32.230019,0.321402,0.00321402,0,-0.486793,0,400,64.3559,0,0,0,0,0,0
10384,44677.73471,10383.56825,78265010,0.526383,0.536971,25.111974,23.6359,-0.473911,-0.463451,35.504497,0.347227,0.00347227,0,-0.468772,-0.00286,400,64.3589,0,0,0,0,0,0
10428,44677.73522,10427.56825,78265054,0.549694,0.559503,28.076843,23.659566,-0.450883,-0.441034,39.70623,0.379834,0.00379834,0,-0.446003,0,400,64.3622,0,0,0,0,0,0
10472,44677.73573,10471.56825,78265098,0.571403,0.580844,30.983485,23.680275,-0.429253,-0.419832,43.822779,0.410464,0.00410464,0,-0.424484,-0.00619,400,64.3662,0,0,0,0,0,0
10516,44677.73624,10515.56825,78265142,0.595529,0.60477,34.475454,23.704927,-0.404108,-0.39495,48.690482,0.445698,0.00445698,0,-0.399688,-0.00602,400,64.3706,0,0,0,0,0,0
10560,44677.73675,10559.56825,78265186,0.616469,0.625589,37.319972,23.724649,-0.384157,-0.375097,52.790121,0.474634,0.00474634,0,-0.379625,-0.00353,400,64.3738,0,0,0,0,0,0
10604,44677.73726,10603.56825,78265230,0.625802,0.635807,38.06277,23.731552,-0.379495,-0.369706,54.164411,0.483474,0.00483474,0,-0.374056,0.6064,422.6,64.0628,0,0,0,0,0,0
10648,44677.73777,10647.56825,78265274,0.625497,0.63565,39.543353,23.736483,-0.377927,-0.367734,55.962458,0.484367,0.00484367,0,-0.372832,0.90162,500,63.0225,0,0,0,0,0,0
10692,44677.73828,10691.56825,78265318,0.644086,0.654156,43.087318,23.750288,-0.356614,-0.346368,60.961173,0.514649,0.00514649,0,-0.351661,0.03495,500,62.9831,0,0,0,0,0,0
10736,44677.73879,10735.56825,78265362,0.666072,0.676175,46.61694,23.773955,-0.334246,-0.324247,65.947944,0.546591,0.00546591,0,-0.329154,0.02166,500,62.9643,0,0,0,0,0,0
10780,44677.73929,10779.56825,78265406,0.687009,0.698022,49.99873,23.794663,-0.313086,-0.302093,70.677147,0.577326,0.00577326,0,-0.307647,0.01514,500,62.9519,0,0,0,0,0,0
10824,44677.7398,10823.56825,78265450,0.707496,0.720731,53.201299,23.814386,-0.292992,-0.279971,75.251195,0.607727,0.00607727,0,-0.286443,0.01007,500,62.9432,0,0,0,0,0,0
10868,44677.74031,10867.56825,78265494,0.728883,0.743151,56.671127,23.833122,-0.271647,-0.257225,80.148524,0.63909,0.0063909,0,-0.26454,0.00697,500,62.9375,0,0,0,0,0,0
10912,44677.74082,10911.56825,78265538,0.751094,0.765407,60.333056,23.855802,-0.249411,-0.235071,85.34092,0.670766,0.00670766,0,-0.242225,0.00431,500,62.9335,0,0,0,0,0,0
10956,44677.74133,10955.56825,78265582,0.773058,0.786843,63.944982,23.878483,-0.227643,-0.213541,90.432201,0.701742,0.00701742,0,-0.220625,0.00324,500,62.9308,0,0,0,0,0,0
11000,44677.74184,10999.56825,78265626,0.794751,0.80928,67.648161,23.900177,-0.205782,-0.191321,95.687881,0.733343,0.00733343,0,-0.198512,0.00002,500,62.9294,0,0,0,0,0,0
11044,44677.74235,11043.56825,78265670,0.816647,0.831474,71.468656,23.921872,-0.183237,-0.168477,101.064438,0.765366,0.00765366,0,-0.175855,0.0004,500,62.9289,0,0,0,0,0,0
11088,44677.74286,11087.56825,78265714,0.838611,0.853825,75.116954,23.944552,-0.161934,-0.146585,106.263504,0.796412,0.00796412,0,-0.15429,0,500,62.9289,0,0,0,0,0,0
11132,44677.74337,11131.56825,78265758,0.859173,0.875062,78.749391,23.964274,-0.140875,-0.124727,111.278409,0.82648,0.0082648,0,-0.133203,0,500,62.9289,0,0,0,0,0,0
11176,44677.74388,11175.56825,78265802,0.881718,0.89846,82.581042,23.985969,-0.11879,-0.102145,116.811835,0.859092,0.00859092,0,-0.1105,-0.01569,500,62.9321,0,0,0,0,0,0
11220,44677.74439,11219.56825,78265846,0.903396,0.920082,86.351982,24.006677,-0.097111,-0.080221,122.148819,0.890109,0.00890109,0,-0.088822,-0.0099,500,62.9403,0,0,0,0,0,0
11264,44677.7449,11263.56825,78265890,0.925725,0.942227,90.297463,24.03133,-0.07474,-0.058198,127.728854,0.921905,0.00921905,0,-0.066518,0,500,62.9428,0,0,0,0,0,0
11308,44677.74541,11307.56825,78265934,0.947617,0.963511,94.104392,24.053024,-0.052929,-0.036997,133.12041,0.952656,0.00952656,0,-0.045005,-0.01103,500,62.9456,0,0,0,0,0,0
11352,44677.74591,11351.56825,78265978,0.969392,0.984996,97.868346,24.072747,-0.031145,-0.015698,138.454424,0.983488,0.00983488,0,-0.023346,-0.01109,500,62.9475,0,0,0,0,0,0
11396,44677.74642,11395.56825,78266022,0.99288,1.007893,101.985366,24.093455,-0.007618,0.007509,144.273718,1.016783,0.01016783,0,-0.000104,-0.01091,500,62.9511,0,0,0,0,0,0
11440,44677.74693,11439.56825,78266066,1.013353,1.028493,105.542846,24.117122,0.012927,0.027986,149.30829,1.046158,0.01046158,0,0.020494,0,500,62.9534,0,0,0,0,0,0
11484,44677.74744,11483.56825,78266110,1.035211,1.050098,109.413024,24.139802,0.034699,0.049483,154.776785,1.077126,0.01077126,0,0.042161,-0.00587,500,62.9574,0,0,0,0,0,0
11528,44677.74795,11527.56825,78266154,1.057578,1.072497,113.374403,24.161497,0.057171,0.072295,160.381641,1.109268,0.01109268,0,0.06464,-0.00781,500,62.9611,0,0,0,0,0,0
11572,44677.74846,11571.56825,78266198,1.079635,1.094802,117.278013,24.182205,0.07922,0.094449,165.902891,1.140899,0.01140899,0,0.086792,-0.00999,500,62.9655,0,0,0,0,0,0
11616,44677.74897,11615.56825,78266242,1.101101,1.116738,121.088833,24.202913,0.100673,0.116275,171.305134,1.171857,0.01171857,0,0.10845,-0.00613,500,62.9692,0,0,0,0,0,0
11660,44677.74948,11659.56825,78266286,1.122915,1.138932,124.95283,24.22658,0.122518,0.138528,176.756599,1.203357,0.01203357,0,0.130498,-0.00567,500,62.9737,0,0,0,0,0,0
11704,44677.74999,11703.56825,78266330,1.144358,1.161328,128.77432,24.247288,0.144015,0.160945,182.172934,1.234702,0.01234702,0,0.152391,-0.01627,500,62.9784,0,0,0,0,0,0
11748,44677.7505,11747.56825,78266374,1.166732,1.183858,132.707697,24.270955,0.165993,0.183428,187.539912,1.265824,0.01265824,0,0.174298,-0.01262,500,62.9835,0,0,0,0,0,0
11792,44677.75101,11791.56825,78266418,1.189609,1.205853,136.71605,24.292649,0.189241,0.205616,193.41007,1.298716,0.01298716,0,0.197329,-0.01016,500,62.9884,0,0,0,0,0,0
11836,44677.75152,11835.56825,78266462,1.21087,1.226716,140.22176,24.312372,0.210347,0.226192,198.37607,1.328808,0.01328808,0,0.218295,-0.00761,500,62.9928,0,0,0,0,0,0
11880,44677.75203,11879.56825,78266506,1.233379,1.248761,144.128548,24.338997,0.232927,0.24838,203.886367,1.360596,0.01360596,0,0.240519,-0.00625,500,62.9978,0,0,0,0,0,0
11924,44677.75254,11923.56825,78266550,1.255703,1.271187,147.973549,24.360691,0.255353,0.270731,209.337182,1.392702,0.01392702,0,0.263065,-0.00668,500,63.0039,0,0,0,0,0,0
11968,44677.75304,11967.56825,78266594,1.276796,1.292832,151.462113,24.381399,0.276251,0.292458,214.233044,1.422985,0.01422985,0,0.284238,-0.00865,500,63.0092,0,0,0,0,0,0
12012,44677.75355,12011.56825,78266638,1.298245,1.315187,155.103104,24.402108,0.297835,0.314908,219.416486,1.454502,0.01454502,0,0.306347,-0.00622,500,63.0153,0,0,0,0,0,0
12056,44677.75406,12055.56825,78266682,1.319577,1.337704,158.617485,24.425774,0.319178,0.337424,224.393383,1.485841,0.01485841,0,0.328204,-0.00802,500,63.0212,0,0,0,0,0,0
12100,44677.75457,12099.56825,78266726,1.340991,1.361301,161.775281,24.44451,0.339838,0.359973,229.12966,1.517673,0.01517673,0,0.350343,-0.00764,500,63.0274,0,0,0,0,0,0
12144,44677.75508,12143.56825,78266770,1.361978,1.384838,165.230825,24.464233,0.362003,0.384922,233.594485,1.549767,0.01549767,0,0.373049,-0.00964,500,63.0339,0,0,0,0,0,0
12188,44677.75559,12187.56825,78266814,1.383096,1.407414,168.172625,24.483955,0.382665,0.406978,237.867021,1.581004,0.01581004,0,0.394747,-0.00946,500,63.0404,0,0,0,0,0,0
12232,44677.7561,12231.56825,78266858,1.406101,1.427827,171.411465,24.506635,0.405817,0.427488,242.450588,1.61209,0.0161209,0,0.416508,-0.01048,500,63.0479,0,0,0,0,0,0
12276,44677.75661,12275.56825,78266902,1.430428,1.447765,174.685896,24.52833,0.430031,0.447408,247.113533,1.643689,0.01643689,0,0.438628,-0.01366,500,63.0568,0,0,0,0,0,0
12320,44677.75712,12319.56825,78266946,1.4546,1.467545,177.724176,24.553969,0.454028,0.467294,251.403506,1.674896,0.01674896,0,0.460592,-0.01329,500,63.0665,0,0,0,0,0,0
12364,44677.75763,12363.56825,78266990,1.478549,1.487082,180.539358,24.575663,0.478144,0.486786,255.498092,1.706215,0.01706215,0,0.482496,-0.01395,500,63.0769,0,0,0,0,0,0
12408,44677.75814,12407.56825,78267034,1.502374,1.507937,183.261891,24.602288,0.501987,0.507626,259.205359,1.737901,0.01737901,0,0.504703,-0.01624,500,63.0891,0,0,0,0,0,0
12452,44677.75865,12451.56825,78267078,1.525028,1.529925,185.596281,24.622997,0.524553,0.529649,262.538641,1.769814,0.01769814,0,0.527097,-0.01731,500,63.1014,0,0,0,0,0,0
12496,44677.75916,12495.56825,78267122,1.546158,1.552025,187.434352,24.648635,0.545717,0.55177,265.381339,1.801418,0.01801418,0,0.548933,-0.01595,500,63.1137,0,0,0,0,0,0
12540,44677.75966,12539.56825,78267166,1.567257,1.574989,189.044902,24.667372,0.567085,0.574812,267.277261,1.832181,0.01832181,0,0.570675,-0.01824,500,63.1265,0,0,0,0,0,0
12584,44677.76017,12583.56825,78267210,1.588495,1.59796,190.248508,24.687094,0.588452,0.597887,269.093173,1.864011,0.01864011,0,0.593155,-0.01902,500,63.1405,0,0,0,0,0,0
12628,44677.76068,12627.56825,78267254,1.609339,1.619698,191.046807,24.708788,0.609239,0.619352,270.448364,1.894916,0.01894916,0,0.614661,-0.02334,500,63.1557,0,0,0,0,0,0
12672,44677.76119,12671.56825,78267298,1.63147,1.642009,191.448825,24.725552,0.631069,0.641769,270.714534,1.926004,0.01926004,0,0.636351,-0.02577,500,63.1734,0,0,0,0,0,0
12716,44677.7617,12715.56825,78267342,1.653494,1.6642,190.82825,24.749219,0.653146,0.663792,270.023516,1.957781,0.01957781,0,0.658462,-0.03226,500,63.1934,0,0,0,0,0,0
12760,44677.76221,12759.56825,78267386,1.675575,1.686436,186.361736,24.769927,0.675399,0.686243,263.580404,1.989529,0.01989529,0,0.680839,-0.03732,500,63.2213,0,0,0,0,0,0
12804,44677.76272,12803.56825,78267430,1.694569,1.707645,175.841791,24.788663,0.694256,0.707378,249.001128,2.018181,0.02018181,0,0.700947,-0.06704,500,63.257,0,0,0,0,0,0
12820,44677.76291,12819.56825,78267446,1.686222,1.699877,171.078875,24.779788,0.685458,0.699226,242.235724,2.006431,0.02006431,0,0.692476,0,500,63.2584,0,0,0,0,0,0