File: PB6_TRI_20522.csv
Index,Date,Time,Counter,FbLoad,Lvdt1,Lvdt2,Force(kN),Potm,LVDT1,LVDT2,Chain,Stress [MPa],Strain Ax. [%],Strain Ax [-],Strain Rad. [%],Strain Vol. [%],Gemidd,IFlow,IPress,IVol,FlowA,PressA,VolA,FlowB,PressB,VolB
0,44701.43304,0,57964187,1.226215,0.076668,0.078619,1.23631,2.482008,-0.923566,-0.921229,19.912166,1.719996,-0.003207,-0.00003207,0,-0.003207,-0.922398,-0.00101,10,80.0247,0,0,0,0,0,0
27,44701.43335,26.361603,57964213,1.268909,0.077819,0.079598,1.233412,2.482994,-0.923677,-0.921623,19.912166,1.792204,-0.001639,-0.00001639,0,-0.001639,-0.922175,-0.00028,10,80.0248,0,0,0,0,0,0
54,44701.43366,53.361603,57964240,1.216131,0.076564,0.078407,1.208452,2.482994,-0.924287,-0.922018,19.912166,1.695917,-0.004063,-0.00004063,0,-0.004063,-0.923365,-0.00179,10,80.0252,0,0,0,0,0,0
81,44701.43397,80.361603,57964267,1.22558,0.076546,0.078457,1.194885,2.482994,-0.924505,-0.922577,19.912166,1.720633,-0.003738,-0.00003738,0,-0.003738,-0.923206,0,10,80.0252,0,0,0,0,0,0
108,44701.43428,107.361603,57964294,1.186564,0.075847,0.077756,1.137493,2.482008,-0.926216,-0.923694,19.912166,1.650063,-0.005451,-0.00005451,0,-0.005451,-0.924937,0,10,80.0255,0,0,0,0,0,0
135,44701.43459,134.361603,57964321,1.952197,0.092062,0.093059,1.882278,2.497785,-0.909215,-0.9091,19.912166,2.804631,0.019412,0.00019412,0,0.019412,-0.907244,1.04079,20,79.7553,0,0,0,0,0,0
162,44701.43491,161.361603,57964348,3.53106,0.126773,0.127068,3.525454,2.532299,-0.87388,-0.873568,19.912166,4.95317,0.067333,0.00067333,0,0.067333,-0.873854,0.36315,40,79.2503,0,0,0,0,0,0
189,44701.43522,188.361603,57964375,4.280093,0.140455,0.140333,4.40273,2.54709,-0.859238,-0.859039,19.912166,6.116014,0.087469,0.00087469,0,0.087469,-0.859859,3.5452,55.1,78.913,0,0,0,0,0,0
216,44701.43553,215.361603,57964402,6.390238,0.169669,0.168811,6.332507,2.573715,-0.832556,-0.832743,19.912166,9.03262,0.127311,0.00127311,0,0.127311,-0.832783,1.32842,85.4,78.2709,0,0,0,0,0,0
243,44701.43585,242.361603,57964429,7.840745,0.187177,0.185948,7.832818,2.590478,-0.8138,-0.814994,19.912166,11.143849,0.153679,0.00153679,0,0.153679,-0.814311,0.20323,100,77.9407,0,0,0,0,0,0
270,44701.43616,269.361603,57964456,8.026967,0.18983,0.188684,8.078159,2.595409,-0.810779,-0.811772,19.912166,11.364067,0.157536,0.00157536,0,0.157536,-0.811524,0.04575,100,77.9176,0,0,0,0,0,0
297,44701.43647,296.361603,57964483,10.32966,0.216765,0.215491,10.400607,2.622034,-0.783756,-0.785049,19.912166,14.721055,0.196566,0.00196566,0,0.196566,-0.784487,0.02539,100,77.9044,0,0,0,0,0,0
324,44701.43678,323.361603,57964510,12.817545,0.24409,0.242557,12.922707,2.648658,-0.756479,-0.75803,19.912166,18.27623,0.235735,0.00235735,0,0.235735,-0.757238,0.01804,100,77.8954,0,0,0,0,0,0
351,44701.4371,350.361603,57964537,15.545054,0.271489,0.269883,15.672012,2.676269,-0.729093,-0.730518,19.912166,22.104131,0.275043,0.00275043,0,0.275043,-0.730004,0.01245,100,77.8891,0,0,0,0,0,0
378,44701.43741,377.361603,57964564,18.454432,0.298234,0.296669,18.591422,2.699935,-0.70226,-0.703828,19.912166,26.283575,0.313974,0.00313974,0,0.313974,-0.703306,0.0086,100,77.8847,0,0,0,0,0,0
405,44701.43772,404.361603,57964591,21.564127,0.325171,0.323355,21.739929,2.725574,-0.675152,-0.676973,19.912166,30.715305,0.352681,0.00352681,0,0.352681,-0.676238,0.00556,100,77.8817,0,0,0,0,0,0
432,44701.43803,431.361603,57964618,24.876957,0.352469,0.350242,25.047705,2.753185,-0.647984,-0.650151,19.912166,35.360501,0.391651,0.00391651,0,0.391651,-0.649283,0.0028,100,77.8803,0,0,0,0,0,0
459,44701.43835,458.361603,57964645,28.3258,0.379492,0.377255,28.524781,2.778823,-0.620975,-0.623297,19.912166,40.323338,0.430734,0.00430734,0,0.430734,-0.622101,0.00005,100,77.8801,0,0,0,0,0,0
486,44701.43866,485.361603,57964672,31.911255,0.406547,0.404237,32.127673,2.806434,-0.593825,-0.595916,19.912166,45.472813,0.469902,0.00469902,0,0.469902,-0.594989,0,100,77.8801,0,0,0,0,0,0
513,44701.43897,512.361603,57964699,35.658193,0.433663,0.431494,35.829009,2.835031,-0.567101,-0.569193,19.912166,50.792421,0.508859,0.00508859,0,0.508859,-0.568084,-0.00002,100,77.8801,0,0,0,0,0,0
540,44701.43928,539.361603,57964726,39.500674,0.460242,0.458495,39.778536,2.861655,-0.540323,-0.542043,19.912166,56.239963,0.547547,0.00547547,0,0.547547,-0.541215,-0.01132,100,77.8837,0,0,0,0,0,0
567,44701.4396,566.361603,57964753,43.573535,0.487534,0.48561,43.873553,2.887294,-0.512957,-0.514958,19.912166,62.08241,0.586972,0.00586972,0,0.586972,-0.513828,-0.00825,100,77.8874,0,0,0,0,0,0
594,44701.43991,593.361603,57964780,47.663287,0.514815,0.512233,47.976065,2.913919,-0.485794,-0.488202,19.912166,67.939279,0.625759,0.00625759,0,0.625759,-0.487072,-0.00973,100,77.8913,0,0,0,0,0,0
621,44701.44022,620.361603,57964807,51.903815,0.542129,0.539169,52.328794,2.940543,-0.458257,-0.460887,19.912166,73.990812,0.665111,0.00665111,0,0.665111,-0.459718,-0.01242,100,77.8963,0,0,0,0,0,0
648,44701.44053,647.361603,57964834,56.031821,0.568861,0.566114,56.506225,2.966182,-0.431609,-0.434229,19.912166,79.89674,0.703648,0.00703648,0,0.703648,-0.433058,-0.01294,100,77.9017,0,0,0,0,0,0
675,44701.44085,674.361603,57964861,60.136941,0.59596,0.593094,60.648937,2.993793,-0.404402,-0.407178,19.912166,85.714436,0.742466,0.00742466,0,0.742466,-0.405987,-0.01601,100,77.9085,0,0,0,0,0,0
702,44701.44116,701.361603,57964888,64.033904,0.623052,0.619939,64.588567,3.018445,-0.377437,-0.380422,19.912166,91.408883,0.781724,0.00781724,0,0.781724,-0.378962,-0.02087,100,77.9177,0,0,0,0,0,0
729,44701.44147,728.361603,57964915,67.837637,0.650249,0.646974,68.453032,3.046056,-0.350292,-0.353633,19.912166,96.864095,0.820747,0.00820747,0,0.820747,-0.351919,-0.02542,100,77.9286,0,0,0,0,0,0
756,44701.44178,755.361603,57964942,71.461509,0.677333,0.673772,72.233672,3.071694,-0.323007,-0.326581,19.912166,102.085817,0.859478,0.00859478,0,0.859478,-0.324976,-0.03104,100,77.9421,0,0,0,0,0,0
783,44701.4421,782.361603,57964969,74.838414,0.704447,0.700641,75.69667,3.097333,-0.295997,-0.299628,19.912166,107.142398,0.89871,0.0089871,0,0.89871,-0.29789,-0.03625,100,77.958,0,0,0,0,0,0
810,44701.44241,809.361603,57964996,77.944519,0.731439,0.727863,78.947773,3.12593,-0.269129,-0.272477,19.912166,111.695243,0.937658,0.00937658,0,0.937658,-0.270915,-0.04398,100,77.977,0,0,0,0,0,0
837,44701.44272,836.361603,57965023,79.292865,0.749087,0.745982,80.394105,3.142693,-0.251626,-0.254563,19.912166,113.734015,0.963308,0.00963308,0,0.963308,-0.253124,-0.02473,100,77.9948,0,0,0,0,0,0
864,44701.44303,863.361603,57965050,76.335317,0.735669,0.73276,77.546483,3.126916,-0.265162,-0.268237,19.912166,109.772505,0.943904,0.00943904,0,0.943904,-0.266571,0.00587,100,77.9934,0,0,0,0,0,0
891,44701.44335,890.361603,57965077,74.191787,0.725353,0.722798,75.652157,3.117055,-0.27531,-0.277835,19.912166,106.926807,0.929387,0.00929387,0,0.929387,-0.276626,0.00599,100,77.9873,0,0,0,0,0,0
918,44701.44366,917.361603,57965104,68.887324,0.698529,0.696289,70.455438,3.09043,-0.302219,-0.304591,19.912166,99.710342,0.890978,0.00890978,0,0.890978,-0.303182,0.02142,100,77.9785,0,0,0,0,0,0
945,44701.44397,944.361603,57965131,63.684975,0.6716,0.669354,65.459464,3.063806,-0.329238,-0.33138,19.912166,92.622428,0.851982,0.00851982,0,0.851982,-0.330308,0.02177,100,77.9689,0,0,0,0,0,0
972,44701.44428,971.361603,57965158,58.625897,0.644465,0.642618,60.607516,3.038167,-0.356431,-0.358004,19.912166,85.731865,0.813062,0.00813062,0,0.813062,-0.357409,0.02212,100,77.9591,0,0,0,0,0,0
999,44701.4446,998.361603,57965185,53.691866,0.617307,0.615909,55.977911,3.008584,-0.383494,-0.384958,19.912166,79.101588,0.774129,0.00774129,0,0.774129,-0.384225,0.02284,100,77.949,0,0,0,0,0,0
1026,44701.44491,1025.361603,57965212,48.898722,0.590091,0.589128,51.37068,2.98689,-0.410888,-0.412009,19.912166,72.712031,0.735161,0.00735161,0,0.735161,-0.411306,0.02351,100,77.9385,0,0,0,0,0,0
1053,44701.44522,1052.361603,57965239,44.268255,0.56321,0.562513,47.04267,2.959279,-0.437764,-0.438338,19.912166,66.655694,0.696851,0.00696851,0,0.696851,-0.437914,0.02319,100,77.9281,0,0,0,0,0,0
1080,44701.44553,1079.361603,57965266,39.718725,0.535891,0.535302,42.892528,2.930682,-0.46481,-0.465522,19.912166,60.66649,0.657353,0.00657353,0,0.657353,-0.465174,0.0238,100,77.9174,0,0,0,0,0,0
1107,44701.44585,1106.361603,57965293,35.363309,0.50889,0.508811,38.802404,2.90603,-0.492462,-0.492573,19.912166,54.964051,0.618344,0.00618344,0,0.618344,-0.492303,0.02325,100,77.9067,0,0,0,0,0,0
1134,44701.44616,1133.361603,57965320,31.080359,0.481347,0.481868,34.980615,2.879405,-0.519354,-0.519066,19.912166,49.503837,0.57959,0.0057959,0,0.57959,-0.519041,0.0238,100,77.8958,0,0,0,0,0,0
1161,44701.44647,1160.361603,57965347,27.039151,0.454562,0.454673,31.292669,2.853767,-0.546202,-0.546184,19.912166,44.320731,0.54051,0.0054051,0,0.54051,-0.545935,0.0231,100,77.885,0,0,0,0,0,0
1188,44701.44678,1187.361603,57965374,23.171283,0.427911,0.427723,27.836951,2.827142,-0.573033,-0.573269,19.912166,39.431654,0.501683,0.00501683,0,0.501683,-0.57303,0.02229,100,77.8747,0,0,0,0,0,0
1215,44701.4471,1214.361603,57965401,19.483896,0.400967,0.400685,24.57803,2.799531,-0.600009,-0.600025,19.912166,34.790878,0.462618,0.00462618,0,0.462618,-0.600268,0.02122,100,77.8651,0,0,0,0,0,0
1242,44701.44741,1241.361603,57965428,15.864784,0.373928,0.373911,21.385797,2.770934,-0.627275,-0.627044,19.912166,30.293284,0.423719,0.00423719,0,0.423719,-0.627162,0.02102,100,77.8556,0,0,0,0,0,0
1269,44701.44772,1268.361603,57965455,12.590838,0.348544,0.348639,18.68906,2.748254,-0.652216,-0.652156,19.912166,26.387291,0.387441,0.00387441,0,0.387441,-0.65214,0.02003,100,77.8465,0,0,0,0,0,0
1296,44701.44803,1295.361603,57965482,13.107152,0.34813,0.348034,19.630932,2.747268,-0.653057,-0.65311,19.912166,27.83708,0.386669,0.00386669,0,0.386669,-0.652889,-0.0556,140,77.129,0,0,0,0,0,0
1323,44701.44835,1322.361603,57965509,13.465888,0.347728,0.34759,20.656159,2.747268,-0.652065,-0.652156,19.912166,29.117983,0.386781,0.00386781,0,0.386781,-0.652225,-3.87128,176.1,76.4541,0,0,0,0,0,0
1350,44701.44866,1349.361603,57965536,13.625452,0.349535,0.349276,21.227731,2.747268,-0.65114,-0.651302,19.912166,30.098095,0.389098,0.00389098,0,0.389098,-0.651052,0.29396,200,76.0445,0,0,0,0,0,0
1377,44701.44897,1376.361603,57965563,16.859928,0.376735,0.376335,24.998252,2.774879,-0.623994,-0.62425,19.912166,35.400899,0.427898,0.00427898,0,0.427898,-0.624163,0.05128,200,76.0191,0,0,0,0,0,0
1404,44701.44928,1403.361603,57965590,20.146817,0.40395,0.403067,28.914565,2.804462,-0.596557,-0.597395,19.912166,40.848739,0.466838,0.00466838,0,0.466838,-0.597115,0.03095,200,76.0031,0,0,0,0,0,0
1431,44701.4496,1430.361603,57965617,23.609554,0.430963,0.429911,32.877974,2.831086,-0.56974,-0.570836,19.912166,46.464297,0.505647,0.00505647,0,0.505647,-0.570345,0.02151,200,75.9922,0,0,0,0,0,0
1458,44701.44991,1457.361603,57965644,27.200814,0.457986,0.456991,37.072658,2.858697,-0.542604,-0.543752,19.912166,52.399299,0.544678,0.00544678,0,0.544678,-0.543235,0.01502,200,75.9847,0,0,0,0,0,0
1485,44701.45022,1484.361603,57965671,30.957014,0.48503,0.48396,41.35243,2.88335,-0.5157,-0.516568,19.912166,58.469338,0.583592,0.00583592,0,0.583592,-0.516278,0.01068,200,75.9795,0,0,0,0,0,0
1512,44701.45053,1511.361603,57965698,34.784042,0.512194,0.510356,45.834971,2.909974,-0.4881,-0.490075,19.912166,64.759173,0.622659,0.00622659,0,0.622659,-0.489272,0.00512,200,75.9762,0,0,0,0,0,0
1539,44701.45085,1538.361603,57965725,38.801355,0.540137,0.537186,50.298749,2.936599,-0.460726,-0.463418,19.912166,71.198385,0.661828,0.00661828,0,0.661828,-0.46205,0.00272,200,75.9747,0,0,0,0,0,0
1566,44701.45116,1565.361603,57965752,42.711229,0.567054,0.56381,54.888322,2.96421,-0.433371,-0.43653,19.912166,77.559747,0.700694,0.00700694,0,0.700694,-0.435082,0.00005,200,75.9744,0,0,0,0,0,0
1593,44701.45147,1592.361603,57965779,46.721927,0.594451,0.5909,59.46558,2.989848,-0.406083,-0.409643,19.912166,84.147849,0.740114,0.00740114,0,0.740114,-0.407752,0,200,75.9744,0,0,0,0,0,0
1620,44701.45178,1619.361603,57965806,50.743198,0.621354,0.617582,64.008625,3.017459,-0.379085,-0.383183,19.912166,90.619662,0.778878,0.00778878,0,0.778878,-0.380869,0,200,75.9744,0,0,0,0,0,0
1647,44701.4521,1646.361603,57965833,54.771143,0.648462,0.644543,68.614775,3.042111,-0.352127,-0.356032,19.912166,97.09357,0.817542,0.00817542,0,0.817542,-0.354142,-0.00836,200,75.9798,0,0,0,0,0,0
1674,44701.45241,1673.361603,57965860,58.912832,0.675699,0.6714,73.374273,3.070708,-0.324724,-0.328915,19.912166,103.76543,0.856702,0.00856702,0,0.856702,-0.326988,-0.00839,200,75.9838,0,0,0,0,0,0
1701,44701.45272,1700.361603,57965887,62.926599,0.702718,0.698096,77.941348,3.097333,-0.297657,-0.30229,19.912166,110.218954,0.895377,0.00895377,0,0.895377,-0.300026,-0.01143,200,75.9885,0,0,0,0,0,0
1728,44701.45303,1727.361603,57965914,67.00352,0.730171,0.725786,82.508446,3.12593,-0.2704,-0.274745,19.912166,116.780098,0.935367,0.00935367,0,0.935367,-0.272487,-0.01219,200,75.9939,0,0,0,0,0,0
1755,44701.45335,1754.361603,57965941,70.787821,0.756733,0.752677,86.9863,3.14861,-0.243745,-0.247759,19.912166,123.017421,0.973879,0.00973879,0,0.973879,-0.245743,-0.01343,200,75.9998,0,0,0,0,0,0
1782,44701.45366,1781.361603,57965968,74.540191,0.783366,0.77942,91.347941,3.177207,-0.216889,-0.220871,19.912166,129.106174,1.012296,0.01012296,0,1.012296,-0.219136,-0.01511,200,76.0064,0,0,0,0,0,0
1809,44701.45397,1808.361603,57965995,78.283847,0.810303,0.806498,95.598829,3.203832,-0.190019,-0.193754,19.912166,135.126007,1.051226,0.01051226,0,1.051226,-0.192069,-0.01697,200,76.0139,0,0,0,0,0,0
1836,44701.45428,1835.361603,57966022,81.935621,0.837581,0.833916,99.791894,3.22947,-0.162747,-0.166406,19.912166,141.19499,1.091089,0.01091089,0,1.091089,-0.164562,-0.01969,200,76.0226,0,0,0,0,0,0
1863,44701.4546,1862.361603,57966049,85.272013,0.864194,0.860927,103.69697,3.255109,-0.136233,-0.139486,19.912166,146.620706,1.129381,0.01129381,0,1.129381,-0.138035,-0.02148,200,76.0323,0,0,0,0,0,0
1890,44701.45491,1889.361603,57966076,88.563008,0.891503,0.888557,107.537926,3.281733,-0.108865,-0.111974,19.912166,152.135934,1.169226,0.01169226,0,1.169226,-0.110305,-0.02791,200,76.044,0,0,0,0,0,0
1917,44701.45522,1916.361603,57966103,91.455196,0.918036,0.915084,110.931075,3.306386,-0.082545,-0.08525,19.912166,156.962216,1.207324,0.01207324,0,1.207324,-0.084046,-0.03081,200,76.0572,0,0,0,0,0,0
1944,44701.45553,1943.361603,57966130,89.744228,0.918933,0.916729,109.766493,3.306386,-0.081854,-0.084067,19.912166,155.236119,1.208937,0.01208937,0,1.208937,-0.082994,0.00524,200,76.0639,0,0,0,0,0,0
1971,44701.45585,1970.361603,57966157,83.575258,0.891428,0.890243,104.11715,3.280747,-0.109681,-0.110461,19.912166,147.37872,1.169974,0.01169974,0,1.169974,-0.110118,0.02053,200,76.0518,0,0,0,0,0,0
1998,44701.45616,1997.361603,57966184,77.693045,0.864534,0.863643,98.95279,3.253136,-0.135945,-0.136725,19.912166,139.871551,1.131373,0.01131373,0,1.131373,-0.13649,0.02134,200,76.0423,0,0,0,0,0,0
2025,44701.45647,2024.361603,57966211,71.940931,0.838052,0.836932,93.687834,3.228484,-0.16275,-0.164335,19.912166,132.563814,1.093006,0.01093006,0,1.093006,-0.163188,0.02096,200,76.0327,0,0,0,0,0,0
2052,44701.45678,2051.361603,57966238,66.163931,0.810807,0.809642,88.557497,3.199887,-0.189907,-0.190861,19.912166,125.15766,1.053326,0.01053326,0,1.053326,-0.190857,0.02119,200,76.0232,0,0,0,0,0,0
2079,44701.4571,2078.361603,57966265,60.614087,0.783883,0.782651,83.492771,3.176221,-0.216876,-0.218143,19.912166,118.249582,1.015088,0.01015088,0,1.015088,-0.21738,0.0209,200,76.0137,0,0,0,0,0,0
2106,44701.45741,2105.361603,57966292,54.998177,0.756721,0.755453,78.505726,3.14861,-0.244091,-0.245458,19.912166,111.135905,0.975638,0.00975638,0,0.975638,-0.244579,0.02096,200,76.004,0,0,0,0,0,0
2133,44701.45772,2132.361603,57966319,49.49698,0.729846,0.72831,73.657193,3.121985,-0.271078,-0.272444,19.912166,104.194598,0.936308,0.00936308,0,0.936308,-0.271831,0.02221,200,75.9941,0,0,0,0,0,0
2160,44701.45803,2159.361603,57966346,44.135809,0.702868,0.701105,68.932038,3.094375,-0.298117,-0.299792,19.912166,97.517457,0.897362,0.00897362,0,0.897362,-0.298961,0.02226,200,75.9842,0,0,0,0,0,0
2187,44701.45835,2186.361603,57966373,38.87771,0.675814,0.674503,64.273325,3.068736,-0.325119,-0.326318,19.912166,90.964554,0.858613,0.00858613,0,0.858613,-0.325756,0.02273,200,75.9739,0,0,0,0,0,0
2214,44701.45866,2213.361603,57966400,33.637368,0.648542,0.647201,59.71805,3.042111,-0.352293,-0.353731,19.912166,84.530772,0.819328,0.00819328,0,0.819328,-0.352945,0.02308,200,75.9636,0,0,0,0,0,0
2241,44701.45897,2240.361603,57966427,28.523067,0.621592,0.620178,55.313399,3.014501,-0.379271,-0.380685,19.912166,78.273344,0.780385,0.00780385,0,0.780385,-0.379893,0.02189,200,75.9536,0,0,0,0,0,0
2268,44701.45928,2267.361603,57966454,23.586725,0.594258,0.593451,51.053895,2.989848,-0.40659,-0.407342,19.912166,72.240256,0.741462,0.00741462,0,0.741462,-0.406928,0.02258,200,75.9438,0,0,0,0,0,0
2295,44701.4596,2294.361603,57966481,18.745326,0.567112,0.566439,46.953227,2.961251,-0.433683,-0.434262,19.912166,66.426084,0.702178,0.00702178,0,0.702178,-0.43419,0.02122,200,75.9341,0,0,0,0,0,0
2322,44701.45991,2321.361603,57966508,14.036654,0.539867,0.539767,42.873506,2.934627,-0.46117,-0.461084,19.912166,60.751021,0.663398,0.00663398,0,0.663398,-0.461117,0.02061,200,75.9245,0,0,0,0,0,0
2349,44701.46022,2348.361603,57966535,9.449388,0.512661,0.513094,39.013024,2.909974,-0.488228,-0.487676,19.912166,55.275685,0.624935,0.00624935,0,0.624935,-0.487822,0.02087,200,75.9153,0,0,0,0,0,0
2376,44701.46053,2375.361603,57966562,4.961695,0.485689,0.486131,35.262693,2.884336,-0.515267,-0.514958,19.912166,49.899186,0.585346,0.00585346,0,0.585346,-0.514995,0.01946,200,75.9065,0,0,0,0,0,0
2403,44701.46085,2402.361603,57966589,0.714874,0.459181,0.459139,31.803738,2.858697,-0.541439,-0.541615,19.912166,44.879124,0.546748,0.00546748,0,0.546748,-0.541574,0.01876,200,75.8981,0,0,0,0,0,0
2430,44701.46116,2429.361603,57966616,-3.437849,0.432319,0.432119,28.322085,2.833059,-0.56875,-0.568799,19.912166,40.066819,0.507916,0.00507916,0,0.507916,-0.568907,0.01807,200,75.8897,0,0,0,0,0,0
2457,44701.46147,2456.361603,57966643,-7.486312,0.404703,0.404583,24.990065,2.803476,-0.596208,-0.596212,19.912166,35.415872,0.468431,0.00468431,0,0.468431,-0.596141,0.01746,200,75.8818,0,0,0,0,0,0
2484,44701.46178,2483.361603,57966670,-7.233659,0.404127,0.404066,26.085209,2.803476,-0.595759,-0.59585,19.912166,36.839619,0.468355,0.00468355,0,0.468355,-0.595884,-0.03822,240,75.2431,0,0,0,0,0,0
2511,44701.4621,2510.361603,57966697,-6.795131,0.40378,0.403696,27.184912,2.803476,-0.596971,-0.596968,19.912166,38.407658,0.466983,0.00466983,0,0.466983,-0.597019,0.77089,299.4,74.296,0,0,0,0,0,0
2538,44701.46241,2537.361603,57966724,-4.294853,0.425173,0.424674,30.41634,2.826156,-0.575375,-0.575931,19.912166,43.018282,0.497981,0.00497981,0,0.497981,-0.575596,0.06431,300,74.2497,0,0,0,0,0,0
2565,44701.46272,2564.361603,57966751,-0.866539,0.452383,0.451734,34.555208,2.852781,-0.548289,-0.548682,19.912166,48.921632,0.537111,0.00537111,0,0.537111,-0.548479,0.03895,300,74.2298,0,0,0,0,0,0
2592,44701.46303,2591.361603,57966778,2.66085,0.479239,0.478492,38.889063,2.878419,-0.5211,-0.521663,19.912166,54.924431,0.575811,0.00575811,0,0.575811,-0.521797,0.02641,300,74.2165,0,0,0,0,0,0
2619,44701.46335,2618.361603,57966805,6.437243,0.506428,0.505364,43.332735,2.904058,-0.493957,-0.49494,19.912166,61.23862,0.614761,0.00614761,0,0.614761,-0.494628,0.01847,300,74.2072,0,0,0,0,0,0
2646,44701.46366,2645.361603,57966832,10.289801,0.534001,0.531899,47.780215,2.931668,-0.466653,-0.468611,19.912166,67.596213,0.653859,0.00653859,0,0.653859,-0.467748,0.01398,300,74.2006,0,0,0,0,0,0
2673,44701.46397,2672.361603,57966859,14.171509,0.561288,0.558467,52.370138,2.957307,-0.439191,-0.442085,19.912166,74.093367,0.692744,0.00692744,0,0.692744,-0.440455,0.00944,300,74.1957,0,0,0,0,0,0
2700,44701.46428,2699.361603,57966886,18.179754,0.588845,0.585449,57.074061,2.983932,-0.411632,-0.414771,19.912166,80.745883,0.732182,0.00732182,0,0.732182,-0.413295,0.00628,300,74.1926,0,0,0,0,0,0
2727,44701.4646,2726.361603,57966913,22.153453,0.615646,0.611864,61.61364,3.00957,-0.384982,-0.388771,19.912166,87.249001,0.770609,0.00770609,0,0.770609,-0.386787,0.00283,300,74.1908,0,0,0,0,0,0
2754,44701.46491,2753.361603,57966940,26.22352,0.642727,0.63879,66.326026,3.036195,-0.358194,-0.361883,19.912166,93.891199,0.809283,0.00809283,0,0.809283,-0.36006,0.00081,300,74.1901,0,0,0,0,0,0
2781,44701.46522,2780.361603,57966967,30.42553,0.669529,0.665827,71.164862,3.063806,-0.331,-0.334634,19.912166,100.739757,0.848349,0.00848349,0,0.848349,-0.332804,0,300,74.1901,0,0,0,0,0,0
2808,44701.46553,2807.361603,57966994,34.599688,0.696506,0.692625,75.933449,3.089444,-0.304086,-0.307681,19.912166,107.355862,0.886939,0.00886939,0,0.886939,-0.306024,0,300,74.1901,0,0,0,0,0,0
2835,44701.46584,2834.361603,57967021,38.864045,0.723946,0.719617,80.816416,3.118041,-0.276445,-0.281089,19.912166,114.307138,0.92637,0.0092637,0,0.92637,-0.278606,-0.01844,300,74.1966,0,0,0,0,0,0
2862,44701.46616,2861.361603,57967048,43.155773,0.75111,0.746888,85.687031,3.144666,-0.249164,-0.253413,19.912166,121.201074,0.96595,0.0096595,0,0.96595,-0.25138,-0.00616,300,74.1994,0,0,0,0,0,0
2889,44701.46647,2888.361603,57967075,47.312295,0.777546,0.773571,90.321223,3.170304,-0.22278,-0.226788,19.912166,127.853305,1.004109,0.01004109,0,1.004109,-0.224849,-0.00822,300,74.2029,0,0,0,0,0,0
2916,44701.46678,2915.361603,57967102,51.524052,0.804476,0.800768,95.075008,3.197915,-0.196137,-0.199637,19.912166,134.462749,1.042823,0.01042823,0,1.042823,-0.198054,-0.00825,300,74.2071,0,0,0,0,0,0
2943,44701.4671,2942.361603,57967129,55.667812,0.830923,0.827274,99.814122,3.222567,-0.169308,-0.173013,19.912166,141.092315,1.081202,0.01081202,0,1.081202,-0.171424,-0.01001,300,74.2113,0,0,0,0,0,0
2970,44701.46741,2969.361603,57967156,60.03654,0.858404,0.854799,104.615102,3.248206,-0.141873,-0.145534,19.912166,147.913484,1.120999,0.01120999,0,1.120999,-0.143634,-0.01094,300,74.2168,0,0,0,0,0,0
2997,44701.46772,2996.361603,57967183,64.117386,0.885033,0.881834,109.124906,3.275817,-0.115567,-0.118745,19.912166,154.475894,1.159683,0.01159683,0,1.159683,-0.117107,-0.01349,300,74.2229,0,0,0,0,0,0
3024,44701.46803,3023.361603,57967210,68.315481,0.912029,0.909011,113.831793,3.302441,-0.08827,-0.091233,19.912166,160.961851,1.198823,0.01198823,0,1.198823,-0.089831,-0.01531,300,74.2291,0,0,0,0,0,0
3051,44701.46835,3050.361603,57967237,72.221455,0.938641,0.935701,118.105455,3.32808,-0.062004,-0.06497,19.912166,167.171268,1.237279,0.01237279,0,1.237279,-0.063462,-0.01572,300,74.2359,0,0,0,0,0,0
3078,44701.46866,3077.361603,57967264,76.162078,0.965738,0.962838,122.595755,3.353719,-0.034384,-0.037326,19.912166,173.330008,1.276431,0.01276431,0,1.276431,-0.035974,-0.0174,300,74.2433,0,0,0,0,0,0
3105,44701.46897,3104.361603,57967291,79.8675,0.992685,0.989953,126.632938,3.377385,-0.007881,-0.010734,19.912166,179.176338,1.315344,0.01315344,0,1.315344,-0.009163,-0.01824,300,74.2513,0,0,0,0,0,0
3132,44701.46928,3131.361603,57967318,83.392461,1.019112,1.01654,130.622406,3.404996,0.018845,0.016351,19.912166,184.772356,1.353753,0.01353753,0,1.353753,0.017549,-0.02157,300,74.2601,0,0,0,0,0,0
3159,44701.4696,3158.361603,57967345,86.757155,1.045872,1.043691,134.454746,3.430634,0.045698,0.043468,19.912166,190.165536,1.392641,0.01392641,0,1.392641,0.044598,-0.02276,300,74.2704,0,0,0,0,0,0
3186,44701.46991,3185.361603,57967372,89.973704,1.073193,1.071429,138.042001,3.457259,0.072813,0.071243,19.912166,195.224285,1.432232,0.01432232,0,1.432232,0.07184,-0.02814,300,74.2822,0,0,0,0,0,0
3213,44701.47022,3212.361603,57967399,92.773861,1.099521,1.098308,141.228448,3.481911,0.099003,0.098065,19.912166,199.814418,1.470699,0.01470699,0,1.470699,0.098349,-0.03176,300,74.2959,0,0,0,0,0,0
3240,44701.47053,3239.361603,57967426,86.985979,1.076353,1.075761,135.811479,3.460217,0.075806,0.075286,19.912166,192.295041,1.437911,0.01437911,0,1.437911,0.075703,0.04813,300,74.2866,0,0,0,0,0,0
3267,44701.47085,3266.361603,57967453,80.923837,1.049294,1.049109,130.238522,3.434579,0.048718,0.048695,19.912166,184.24252,1.398826,0.01398826,0,1.398826,0.04869,0.02064,300,74.2772,0,0,0,0,0,0
3294,44701.47116,3293.361603,57967480,74.932445,1.021911,1.022071,124.662619,3.40894,0.021127,0.021182,19.912166,176.418293,1.359336,0.01359336,0,1.359336,0.021172,0.02114,300,74.2679,0,0,0,0,0,0
3321,44701.47147,3320.361603,57967507,69.174805,0.995178,0.995397,119.274721,3.380343,-0.005979,-0.005705,19.912166,168.737597,1.320181,0.01320181,0,1.320181,-0.005811,0.01986,300,74.2586,0,0,0,0,0,0
3348,44701.47178,3347.361603,57967534,63.520893,0.968211,0.968378,114.116848,3.354705,-0.032537,-0.03233,19.912166,161.478317,1.281844,0.01281844,0,1.281844,-0.032379,0.02061,300,74.2494,0,0,0,0,0,0
3375,44701.4721,3374.361603,57967561,57.784726,0.9407,0.94087,108.89077,3.330052,-0.060014,-0.059678,19.912166,154.000489,1.241921,0.01241921,0,1.241921,-0.059946,0.02198,300,74.2398,0,0,0,0,0,0
3402,44701.47241,3401.361603,57967588,52.165411,0.913618,0.913834,103.760916,3.302441,-0.087261,-0.087157,19.912166,146.727736,1.202833,0.01202833,0,1.202833,-0.087129,0.02171,300,74.2302,0,0,0,0,0,0
3429,44701.47272,3428.361603,57967615,46.774522,0.887139,0.887296,98.78366,3.278775,-0.113852,-0.113716,19.912166,139.764388,1.16469,0.0116469,0,1.16469,-0.113796,0.02102,300,74.2209,0,0,0,0,0,0
3456,44701.47303,3455.361603,57967642,41.295085,0.860184,0.860106,93.804395,3.249192,-0.140761,-0.14103,19.912166,132.782896,1.125651,0.01125651,0,1.125651,-0.140638,0.02079,300,74.2113,0,0,0,0,0,0
3483,44701.47335,3482.361603,57967669,35.86025,0.833175,0.83299,88.918855,3.22454,-0.167963,-0.168378,19.912166,125.784614,1.086029,0.01086029,0,1.086029,-0.168178,0.02082,300,74.202,0,0,0,0,0,0
3510,44701.47366,3509.361603,57967696,30.503432,0.805876,0.80562,84.220927,3.197915,-0.194555,-0.194806,19.912166,119.006377,1.047396,0.01047396,0,1.047396,-0.194851,0.02148,300,74.1924,0,0,0,0,0,0
3537,44701.47397,3536.361603,57967723,25.242835,0.77909,0.778669,79.345419,3.170304,-0.221935,-0.221923,19.912166,112.342172,1.008463,0.01008463,0,1.008463,-0.22206,0.0209,300,74.183,0,0,0,0,0,0
3564,44701.47428,3563.361603,57967750,20.002407,0.751933,0.751609,74.714981,3.14368,-0.249031,-0.249501,19.912166,105.714009,0.969148,0.00969148,0,0.969148,-0.249121,0.02082,300,74.1735,0,0,0,0,0,0
3591,44701.4746,3590.361603,57967777,14.843048,0.724869,0.724405,70.195619,3.119027,-0.275729,-0.276158,19.912166,99.236877,0.930185,0.00930185,0,0.930185,-0.275992,0.02056,300,74.1641,0,0,0,0,0,0
3618,44701.47491,3617.361603,57967804,9.687927,0.697824,0.697421,65.612299,3.089444,-0.30303,-0.303408,19.912166,92.803517,0.891128,0.00891128,0,0.891128,-0.303032,0.02056,300,74.155,0,0,0,0,0,0
3645,44701.47522,3644.361603,57967831,4.75499,0.670976,0.670773,61.303287,3.064792,-0.329691,-0.329934,19.912166,86.759525,0.85271,0.0085271,0,0.85271,-0.329585,0.01963,300,74.146,0,0,0,0,0,0
3672,44701.47553,3671.361603,57967858,-0.171355,0.643727,0.643681,56.927958,3.039153,-0.357183,-0.357084,19.912166,80.604794,0.813333,0.00813333,0,0.813333,-0.357113,0.01989,300,74.137,0,0,0,0,0,0
3699,44701.47585,3698.361603,57967885,-4.937887,0.616731,0.616829,52.831249,3.011542,-0.38403,-0.383939,19.912166,74.714342,0.774444,0.00774444,0,0.774444,-0.384007,0.01859,300,74.1284,0,0,0,0,0,0
3726,44701.47616,3725.361603,57967912,-9.653379,0.589653,0.590204,48.729972,2.987876,-0.411266,-0.410892,19.912166,68.945392,0.735602,0.00735602,0,0.735602,-0.410925,0.01864,300,74.1199,0,0,0,0,0,0
3753,44701.47647,3752.361603,57967939,-14.288595,0.562212,0.563086,44.711979,2.958293,-0.438785,-0.438141,19.912166,63.307098,0.696373,0.00696373,0,0.696373,-0.438097,0.01795,300,74.1118,0,0,0,0,0,0
3780,44701.47678,3779.361603,57967966,-18.815824,0.534985,0.536094,40.86298,2.933641,-0.465983,-0.464996,19.912166,57.843786,0.657152,0.00657152,0,0.657152,-0.465418,0.01781,300,74.1039,0,0,0,0,0,0
3807,44701.4771,3806.361603,57967993,-23.168952,0.507712,0.509147,37.173517,2.908002,-0.493088,-0.491785,19.912166,52.577075,0.618095,0.00618095,0,0.618095,-0.492356,0.01757,300,74.0959,0,0,0,0,0,0
3834,44701.47741,3833.361603,57968020,-27.356446,0.481137,0.482404,33.572981,2.880391,-0.520057,-0.518639,19.912166,47.573069,0.579499,0.00579499,0,0.579499,-0.519104,0.01641,300,74.0882,0,0,0,0,0,0
3861,44701.47772,3860.361603,57968047,-28.179524,0.472488,0.473243,33.372129,2.875461,-0.528999,-0.528139,19.912166,47.316276,0.566378,0.00566378,0,0.566378,-0.528543,1.25915,338.3,73.5267,0,0,0,0,0,0
3888,44701.47803,3887.361603,57968074,-27.494405,0.472347,0.473017,34.755881,2.874475,-0.5285,-0.527646,19.912166,49.166425,0.56654,0.0056654,0,0.56654,-0.528115,2.8021,395.1,72.6839,0,0,0,0,0,0
3915,44701.47835,3914.361603,57968101,-24.317368,0.49512,0.495096,38.616361,2.896169,-0.505651,-0.505458,19.912166,54.652704,0.599047,0.00599047,0,0.599047,-0.505596,0.05638,400,72.5844,0,0,0,0,0,0
3942,44701.47866,3941.361603,57968128,-20.443439,0.522544,0.521799,43.04468,2.922794,-0.478379,-0.478801,19.912166,60.918911,0.637894,0.00637894,0,0.637894,-0.478703,0.03168,400,72.5673,0,0,0,0,0,0
3969,44701.47897,3968.361603,57968155,-16.542239,0.549807,0.54785,47.65729,2.949418,-0.450483,-0.452669,19.912166,67.360226,0.676701,0.00676701,0,0.676701,-0.451537,0.02276,400,72.5558,0,0,0,0,0,0
3996,44701.47928,3995.361603,57968182,-12.528453,0.576944,0.574589,52.198684,2.973085,-0.423593,-0.425815,19.912166,73.894479,0.715758,0.00715758,0,0.715758,-0.424672,0.01552,400,72.5481,0,0,0,0,0,0
4023,44701.4796,4022.361603,57968209,-8.420096,0.604202,0.60138,56.965335,3.002668,-0.395944,-0.398796,19.912166,80.475538,0.754767,0.00754767,0,0.754767,-0.397643,0.01025,400,72.5427,0,0,0,0,0,0
4050,44701.47991,4049.361603,57968236,-4.272237,0.631473,0.627949,61.641664,3.028306,-0.368756,-0.372303,19.912166,87.195973,0.793703,0.00793703,0,0.793703,-0.370428,0.00752,400,72.539,0,0,0,0,0,0
4077,44701.48022,4076.361603,57968263,-0.029046,0.658704,0.655001,66.4027,3.054931,-0.341717,-0.345349,19.912166,93.853023,0.832279,0.00832279,0,0.832279,-0.34369,0.0044,400,72.5366,0,0,0,0,0,0
4104,44701.48053,4103.361603,57968290,4.22669,0.68541,0.681555,71.084312,3.080569,-0.315276,-0.319152,19.912166,100.64698,0.871116,0.00871116,0,0.871116,-0.317158,0.00211,400,72.5354,0,0,0,0,0,0
4131,44701.48085,4130.361603,57968317,8.637778,0.71257,0.708795,76.087043,3.109166,-0.287845,-0.291443,19.912166,107.581046,0.910541,0.00910541,0,0.910541,-0.289692,0.00005,400,72.5351,0,0,0,0,0,0
4158,44701.48116,4157.361603,57968344,13.058564,0.739489,0.735855,80.940327,3.134805,-0.260898,-0.264457,19.912166,114.496796,0.94944,0.0094944,0,0.94944,-0.262676,0,400,72.5351,0,0,0,0,0,0
4185,44701.48147,4184.361603,57968371,17.481574,0.766376,0.762424,85.827441,3.161429,-0.233997,-0.237734,19.912166,121.386523,0.987821,0.00987821,0,0.987821,-0.236065,0,400,72.5351,0,0,0,0,0,0
4212,44701.48178,4211.361603,57968398,21.919557,0.793298,0.789546,90.684961,3.188054,-0.207142,-0.210616,19.912166,128.288075,1.027042,0.01027042,0,1.027042,-0.208956,-0.01905,400,72.5437,0,0,0,0,0,0
4239,44701.4821,4238.361603,57968425,26.445298,0.820327,0.816835,95.642679,3.213693,-0.179814,-0.183203,19.912166,135.112597,1.065988,0.01065988,0,1.065988,-0.181848,-0.00767,400,72.5466,0,0,0,0,0,0
4266,44701.48241,4265.361603,57968452,30.929528,0.847326,0.84365,100.430925,3.240317,-0.153229,-0.156742,19.912166,142.076963,1.104739,0.01104739,0,1.104739,-0.155138,-0.00764,400,72.5494,0,0,0,0,0,0
4293,44701.48272,4292.361603,57968479,35.466995,0.874309,0.871025,105.339443,3.266942,-0.126082,-0.129395,19.912166,148.966653,1.144142,0.01144142,0,1.144142,-0.127806,-0.00657,400,72.5529,0,0,0,0,0,0
4320,44701.48303,4319.361603,57968506,39.984167,0.901122,0.898273,110.081218,3.29258,-0.099515,-0.102376,19.912166,155.837897,1.18305,0.0118305,0,1.18305,-0.100886,-0.01059,400,72.5573,0,0,0,0,0,0
4347,44701.48335,4346.361603,57968533,44.502277,0.927995,0.925065,114.948889,3.319205,-0.072601,-0.075192,19.912166,162.588829,1.221664,0.01221664,0,1.221664,-0.074053,-0.01126,400,72.5619,0,0,0,0,0,0
4374,44701.48366,4373.361603,57968560,49.051702,0.954926,0.952116,119.801893,3.34583,-0.045566,-0.048239,19.912166,169.445814,1.260749,0.01260749,0,1.260749,-0.047092,-0.01132,400,72.567,0,0,0,0,0,0
4401,44701.48397,4400.361603,57968587,53.600031,0.981925,0.979186,124.621106,3.371468,-0.018422,-0.021023,19.912166,176.202691,1.299872,0.01299872,0,1.299872,-0.019885,-0.01363,400,72.5724,0,0,0,0,0,0
4428,44701.48428,4427.361603,57968614,58.08704,1.008886,1.006244,129.380832,3.400065,0.008573,0.005898,19.912166,183.005959,1.338832,0.01338832,0,1.338832,0.007327,-0.01369,400,72.5784,0,0,0,0,0,0
4455,44701.4846,4454.361603,57968641,62.580999,1.035743,1.033388,134.119511,3.42669,0.035464,0.033081,19.912166,189.683517,1.37793,0.0137793,0,1.37793,0.034264,-0.01378,400,72.5851,0,0,0,0,0,0
4482,44701.48491,4481.361603,57968668,66.997089,1.062609,1.060691,138.750845,3.452328,0.062159,0.060265,19.912166,196.214918,1.416903,0.01416903,0,1.416903,0.061217,-0.01471,400,72.5918,0,0,0,0,0,0
4509,44701.48522,4508.361603,57968695,71.263227,1.089321,1.08758,143.266749,3.474023,0.088888,0.087382,19.912166,202.576425,1.455468,0.01455468,0,1.455468,0.087942,-0.01656,400,72.599,0,0,0,0,0,0
4536,44701.48553,4535.361603,57968722,75.530423,1.116449,1.114922,147.678875,3.498675,0.116101,0.1145,19.912166,208.876238,1.49489,0.0149489,0,1.49489,0.115305,-0.01676,400,72.6066,0,0,0,0,0,0
4563,44701.48585,4562.361603,57968749,79.440045,1.142985,1.141977,151.887464,3.527272,0.142804,0.141782,19.912166,214.715329,1.533502,0.01533502,0,1.533502,0.142076,-0.01896,400,72.6147,0,0,0,0,0,0
4590,44701.48616,4589.361603,57968776,83.263341,1.169913,1.169253,155.809383,3.550938,0.169463,0.168801,19.912166,220.384899,1.572505,0.01572505,0,1.572505,0.169012,-0.01847,400,72.6236,0,0,0,0,0,0
4617,44701.48647,4616.361603,57968803,86.874055,1.196732,1.196527,159.642067,3.578549,0.196315,0.196248,19.912166,225.800341,1.6117,0.016117,0,1.6117,0.196248,-0.02418,400,72.6335,0,0,0,0,0,0
4644,44701.48678,4643.361603,57968830,90.253756,1.223246,1.223596,163.244438,3.605174,0.222957,0.223267,19.912166,230.896132,1.650327,0.01650327,0,1.650327,0.222989,-0.02681,400,72.6446,0,0,0,0,0,0
4671,44701.4871,4670.361603,57968857,93.290956,1.250286,1.251186,166.498632,3.630812,0.250106,0.250976,19.912166,235.57945,1.690083,0.01690083,0,1.690083,0.25064,-0.03046,400,72.6575,0,0,0,0,0,0
4698,44701.48741,4697.361603,57968884,95.998259,1.277302,1.278371,169.440067,3.657437,0.276929,0.277831,19.912166,239.65072,1.728821,0.01728821,0,1.728821,0.277454,-0.03278,400,72.672,0,0,0,0,0,0
4725,44701.48772,4724.361603,57968911,89.298037,1.2504,1.2519,162.944725,3.630812,0.249579,0.251239,19.912166,230.460988,1.689958,0.01689958,0,1.689958,0.250405,0.04697,400,72.6573,0,0,0,0,0,0
4752,44701.48803,4751.361603,57968938,83.400574,1.222821,1.225313,157.230532,3.603201,0.222121,0.22445,19.912166,222.466223,1.650976,0.01650976,0,1.650976,0.223382,0.02082,400,72.648,0,0,0,0,0,0
4779,44701.48835,4778.361603,57968965,77.696751,1.196256,1.198641,151.748273,3.576577,0.19545,0.197563,19.912166,214.818496,1.612531,0.01612531,0,1.612531,0.196755,0.02102,400,72.6385,0,0,0,0,0,0
4806,44701.48866,4805.361603,57968992,71.964727,1.168975,1.171033,146.461932,3.549952,0.168379,0.170741,19.912166,207.082788,1.572942,0.01572942,0,1.572942,0.169491,0.02108,400,72.629,0,0,0,0,0,0
4833,44701.48897,4832.361603,57969019,66.331307,1.142085,1.143853,140.984441,3.526286,0.141311,0.1429,19.912166,199.549448,1.534029,0.01534029,0,1.534029,0.142158,0.02093,400,72.6198,0,0,0,0,0,0
4860,44701.48928,4859.361603,57969046,60.726202,1.11528,1.116574,135.748319,3.499661,0.114567,0.115979,19.912166,192.042425,1.494894,0.01494894,0,1.494894,0.115265,0.02053,400,72.6106,0,0,0,0,0,0
4887,44701.4896,4886.361603,57969073,55.276069,1.088683,1.089672,130.603927,3.474023,0.087716,0.088566,19.912166,184.802677,1.456133,0.01456133,0,1.456133,0.088284,0.0196,400,72.6015,0,0,0,0,0,0
4914,44701.48991,4913.361603,57969100,49.738066,1.061528,1.062789,125.467669,3.44937,0.060871,0.06204,19.912166,177.560074,1.417273,0.01417273,0,1.417273,0.061533,0.0207,400,72.5922,0,0,0,0,0,0
4941,44701.49022,4940.361603,57969127,44.364489,1.035097,1.035755,120.514649,3.423732,0.034541,0.035218,19.912166,170.505044,1.378842,0.01378842,0,1.378842,0.034841,0.02108,400,72.5828,0,0,0,0,0,0
4968,44701.49053,4967.361603,57969154,38.90997,1.008284,1.008571,115.47928,3.397107,0.007642,0.008067,19.912166,163.324361,1.339726,0.01339726,0,1.339726,0.007827,0.02064,400,72.5736,0,0,0,0,0,0
4995,44701.49085,4994.361603,57969181,33.561938,0.981529,0.981678,110.495129,3.36851,-0.019246,-0.019182,19.912166,156.447704,1.301065,0.01301065,0,1.301065,-0.019167,0.02131,400,72.5642,0,0,0,0,0,0
5022,44701.49116,5021.361603,57969208,28.210203,0.954312,0.954565,105.561733,3.343858,-0.046512,-0.046234,19.912166,149.481086,1.262001,0.01262001,0,1.262001,-0.046281,0.0209,400,72.5549,0,0,0,0,0,0
5049,44701.49147,5048.361603,57969235,22.879217,0.927486,0.927646,100.882676,3.318219,-0.073182,-0.072891,19.912166,142.634022,1.222888,0.01222888,0,1.222888,-0.073303,0.02038,400,72.5458,0,0,0,0,0,0
5076,44701.49178,5075.361603,57969262,17.606896,0.900554,0.900851,96.031605,3.29258,-0.100355,-0.099976,19.912166,135.890668,1.184153,0.01184153,0,1.184153,-0.100211,0.02009,400,72.5368,0,0,0,0,0,0
5103,44701.4921,5102.361603,57969289,12.486167,0.873789,0.873767,91.38709,3.266942,-0.126899,-0.127061,19.912166,129.415556,1.145591,0.01145591,0,1.145591,-0.126805,0.02027,400,72.5276,0,0,0,0,0,0
5130,44701.49241,5129.361603,57969316,7.227552,0.846885,0.846646,86.754606,3.240317,-0.153929,-0.154343,19.912166,122.717164,1.106297,0.01106297,0,1.106297,-0.154097,0.02064,400,72.5184,0,0,0,0,0,0
5157,44701.49272,5156.361603,57969343,2.124707,0.820118,0.819952,82.192608,3.213693,-0.180632,-0.180573,19.912166,116.28866,1.067878,0.01067878,0,1.067878,-0.180776,0.02012,400,72.5092,0,0,0,0,0,0
5184,44701.49303,5183.361603,57969370,-2.89985,0.793616,0.793324,77.639111,3.188054,-0.207504,-0.208118,19.912166,110.021069,1.029688,0.01029688,0,1.029688,-0.207396,0.01954,400,72.5002,0,0,0,0,0,0
5211,44701.49335,5210.361603,57969397,-8.033874,0.766234,0.765871,73.211262,3.162415,-0.234539,-0.234808,19.912166,103.550077,0.9899,0.009899,0,0.9899,-0.234696,0.0203,400,72.4913,0,0,0,0,0,0
5238,44701.49366,5237.361603,57969424,-13.035042,0.739432,0.73915,68.795171,3.132832,-0.261568,-0.261959,19.912166,97.352801,0.951085,0.00951085,0,0.951085,-0.261594,0.01948,400,72.4826,0,0,0,0,0,0
5265,44701.49397,5264.361603,57969451,-17.970777,0.712448,0.711963,64.513175,3.107194,-0.288347,-0.288748,19.912166,91.257679,0.912258,0.00912258,0,0.912258,-0.288557,0.01946,400,72.4739,0,0,0,0,0,0
5292,44701.49428,5291.361603,57969478,-22.728199,0.685583,0.685117,60.268257,3.078597,-0.315463,-0.316227,19.912166,85.308057,0.873227,0.00873227,0,0.873227,-0.315508,0.01725,400,72.466,0,0,0,0,0,0
5319,44701.4946,5318.361603,57969505,-27.540899,0.658595,0.658293,56.047639,3.050986,-0.34283,-0.343147,19.912166,79.559589,0.834834,0.00834834,0,0.834834,-0.342403,0.01772,400,72.4578,0,0,0,0,0,0
5346,44701.49491,5345.361603,57969532,-32.196128,0.631622,0.631461,52.099065,3.026334,-0.369329,-0.369509,19.912166,73.721651,0.795698,0.00795698,0,0.795698,-0.369428,0.0185,400,72.4495,0,0,0,0,0,0
5373,44701.49522,5372.361603,57969559,-36.732681,0.604499,0.604751,48.160055,2.999709,-0.396557,-0.396298,19.912166,68.215646,0.756966,0.00756966,0,0.756966,-0.396309,0.01807,400,72.4417,0,0,0,0,0,0
5400,44701.49553,5399.361603,57969586,-41.233678,0.576962,0.577688,44.253002,2.972098,-0.42426,-0.423678,19.912166,62.691321,0.717475,0.00717475,0,0.717475,-0.423656,0.01809,400,72.4338,0,0,0,0,0,0
5427,44701.49585,5426.361603,57969613,-45.549466,0.549876,0.550846,40.61418,2.945474,-0.451078,-0.450138,19.912166,57.479666,0.678475,0.00678475,0,0.678475,-0.450513,0.0174,400,72.4258,0,0,0,0,0,0
5454,44701.49616,5453.361603,57969640,-46.263684,0.542881,0.543676,40.658446,2.938571,-0.457702,-0.457008,19.912166,57.423254,0.668063,0.00668063,0,0.668063,-0.457401,4.91729,431.5,72.013,0,0,0,0,0,0
5481,44701.49647,5480.361603,57969667,-45.550168,0.543098,0.543299,41.854809,2.940543,-0.457947,-0.4576,19.912166,59.197621,0.667874,0.00667874,0,0.667874,-0.45769,0.51663,480,71.316,0,0,0,0,0,0
5508,44701.49678,5507.361603,57969694,-43.151281,0.557348,0.556855,44.84557,2.954349,-0.443235,-0.443696,19.912166,63.490028,0.688719,0.00688719,0,0.688719,-0.443414,0.0494,500,71.0169,0,0,0,0,0,0
5535,44701.49709,5534.361603,57969721,-39.096115,0.584681,0.58357,49.52853,2.981959,-0.415627,-0.416677,19.912166,70.044608,0.727716,0.00727716,0,0.727716,-0.416287,0.03116,500,71.0004,0,0,0,0,0,0
5562,44701.49741,5561.361603,57969748,-34.916054,0.612343,0.610408,54.223029,3.008584,-0.387967,-0.39002,19.912166,76.66977,0.767096,0.00767096,0,0.767096,-0.388903,0.0203,500,70.9901,0,0,0,0,0,0
5589,44701.49772,5588.361603,57969775,-30.7624,0.639715,0.636902,58.895294,3.036195,-0.360665,-0.363494,19.912166,83.368267,0.806086,0.00806086,0,0.806086,-0.362079,0.01392,500,70.9831,0,0,0,0,0,0
5616,44701.49803,5615.361603,57969802,-26.421174,0.667018,0.663768,63.682625,3.060847,-0.333469,-0.336803,19.912166,90.174188,0.845169,0.00845169,0,0.845169,-0.334995,0.00944,500,70.9783,0,0,0,0,0,0
5643,44701.49835,5642.361603,57969829,-22.121266,0.6941,0.690471,68.38601,3.088458,-0.306737,-0.310409,19.912166,96.893017,0.883587,0.00883587,0,0.883587,-0.308394,0.00683,500,70.975,0,0,0,0,0,0
5670,44701.49866,5669.361603,57969856,-17.759513,0.721052,0.717214,73.380689,3.115083,-0.279186,-0.282897,19.912166,103.730891,0.922676,0.00922676,0,0.922676,-0.281185,0.00388,500,70.973,0,0,0,0,0,0
5697,44701.49897,5696.361603,57969883,-13.204013,0.748452,0.744377,78.214857,3.142693,-0.251983,-0.256009,19.912166,110.658776,0.962077,0.00962077,0,0.962077,-0.254002,0.00086,500,70.9722,0,0,0,0,0,0
5724,44701.49928,5723.361603,57969910,-8.651741,0.775846,0.771567,83.141869,3.169318,-0.224765,-0.229089,19.912166,117.685007,1.001241,0.01001241,0,1.001241,-0.226839,0,500,70.9722,0,0,0,0,0,0
5751,44701.4996,5750.361603,57969937,-4.208856,0.802397,0.798513,87.990159,3.194957,-0.19806,-0.201905,19.912166,124.543433,1.040007,0.01040007,0,1.040007,-0.199972,0,500,70.9722,0,0,0,0,0,0
5778,44701.49991,5777.361603,57969964,0.459588,0.829436,0.825658,92.967745,3.223554,-0.170851,-0.174854,19.912166,131.45262,1.078969,0.01078969,0,1.078969,-0.172803,-0.0006,500,70.9724,0,0,0,0,0,0
5805,44701.50022,5804.361603,57969991,5.04023,0.856514,0.852682,97.850137,3.250178,-0.143984,-0.147539,19.912166,138.468129,1.118058,0.01118058,0,1.118058,-0.145771,-0.01196,500,70.983,0,0,0,0,0,0
5832,44701.50053,5831.361603,57970018,9.68198,0.883284,0.879888,102.706809,3.276803,-0.117172,-0.120684,19.912166,145.367795,1.157071,0.01157071,0,1.157071,-0.118863,-0.0057,500,70.9855,0,0,0,0,0,0
5859,44701.50085,5858.361603,57970045,14.343098,0.909974,0.906934,107.666603,3.302441,-0.090351,-0.093369,19.912166,152.265052,1.195901,0.01195901,0,1.195901,-0.09185,-0.00509,500,70.988,0,0,0,0,0,0
5886,44701.50116,5885.361603,57970072,19.081345,0.937174,0.934099,112.563666,3.327094,-0.063243,-0.066317,19.912166,159.226782,1.235238,0.01235238,0,1.235238,-0.064676,-0.00738,500,70.9913,0,0,0,0,0,0
5913,44701.50147,5912.361603,57970099,23.824643,0.964235,0.961334,117.380879,3.353719,-0.036514,-0.039331,19.912166,166.236922,1.274172,0.01274172,0,1.274172,-0.037801,-0.0097,500,70.995,0,0,0,0,0,0
5940,44701.50178,5939.361603,57970126,28.569033,0.991159,0.988187,122.28087,3.382315,-0.009416,-0.012542,19.912166,173.09317,1.313099,0.01313099,0,1.313099,-0.010784,-0.00955,500,70.9993,0,0,0,0,0,0
5967,44701.5021,5966.361603,57970153,33.354455,1.01815,1.015232,127.2538,3.409926,0.017697,0.014674,19.912166,179.982966,1.351712,0.01351712,0,1.351712,0.016128,-0.01068,500,71.004,0,0,0,0,0,0
5994,44701.50241,5993.361603,57970180,38.119456,1.044843,1.042381,132.030085,3.438523,0.044314,0.042219,19.912166,186.859635,1.390888,0.01390888,0,1.390888,0.043156,-0.01143,500,71.0091,0,0,0,0,0,0
6021,44701.50272,6020.361603,57970207,42.909584,1.071677,1.069571,136.991428,3.462189,0.071489,0.069238,19.912166,193.73037,1.429817,0.01429817,0,1.429817,0.070167,-0.01103,500,71.0144,0,0,0,0,0,0
6048,44701.50303,6047.361603,57970234,47.707541,1.098803,1.096823,141.807001,3.487828,0.098355,0.096257,19.912166,200.584477,1.469121,0.01469121,0,1.469121,0.097434,-0.01193,500,71.0203,0,0,0,0,0,0
6075,44701.50335,6074.361603,57970261,52.435475,1.125539,1.123847,146.578161,3.513466,0.125193,0.123474,19.912166,207.449684,1.508214,0.01508214,0,1.508214,0.1246,-0.01575,500,71.0266,0,0,0,0,0,0
6102,44701.50366,6101.361603,57970288,57.228241,1.152514,1.151149,151.444364,3.539105,0.152435,0.150723,19.912166,214.089229,1.546869,0.01546869,0,1.546869,0.151561,-0.01361,500,71.0328,0,0,0,0,0,0
6129,44701.50397,6128.361603,57970315,61.853325,1.17913,1.177928,156.004176,3.564744,0.178807,0.177643,19.912166,220.770561,1.585824,0.01585824,0,1.585824,0.178337,-0.01543,500,71.0399,0,0,0,0,0,0
6156,44701.50428,6155.361603,57970342,66.500459,1.206059,1.205334,160.715969,3.592354,0.205692,0.205221,19.912166,227.242354,1.624647,0.01624647,0,1.624647,0.205259,-0.01676,500,71.0474,0,0,0,0,0,0
6183,44701.5046,6182.361603,57970369,71.061033,1.232662,1.232628,165.204935,3.615035,0.232393,0.232339,19.912166,233.801523,1.663805,0.01663805,0,1.663805,0.23232,-0.01665,500,71.0547,0,0,0,0,0,0
6210,44701.50491,6209.361603,57970396,75.494177,1.259784,1.2597,169.655547,3.641659,0.25932,0.259555,19.912166,239.941598,1.702729,0.01702729,0,1.702729,0.259304,-0.01795,500,71.0623,0,0,0,0,0,0
6237,44701.50522,6236.361603,57970423,79.733383,1.286609,1.28656,173.848267,3.667298,0.286262,0.286213,19.912166,245.931259,1.741563,0.01741563,0,1.741563,0.286206,-0.01966,500,71.0708,0,0,0,0,0,0
6264,44701.50553,6263.361603,57970450,83.838205,1.313916,1.313694,177.931948,3.693922,0.313557,0.313265,19.912166,251.789825,1.780841,0.01780841,0,1.780841,0.313536,-0.02093,500,71.0793,0,0,0,0,0,0
6291,44701.50585,6290.361603,57970477,87.696217,1.34098,1.340483,181.758817,3.719561,0.340671,0.340054,19.912166,257.217209,1.819828,0.01819828,0,1.819828,0.340444,-0.02087,500,71.0883,0,0,0,0,0,0
6318,44701.50616,6317.361603,57970504,91.272141,1.367922,1.367401,185.397868,3.746186,0.367668,0.367073,19.912166,262.328228,1.858708,0.01858708,0,1.858708,0.367456,-0.02255,500,71.0984,0,0,0,0,0,0
6345,44701.50647,6344.361603,57970531,94.576004,1.395185,1.394719,188.716211,3.769852,0.394734,0.394224,19.912166,266.98965,1.897799,0.01897799,0,1.897799,0.39445,-0.02357,500,71.1099,0,0,0,0,0,0
6372,44701.50678,6371.361603,57970558,97.462636,1.42185,1.421554,191.671334,3.797463,0.421518,0.421473,19.912166,271.029459,1.936358,0.01936358,0,1.936358,0.421308,-0.03023,500,71.1224,0,0,0,0,0,0
6399,44701.5071,6398.361603,57970585,100.180602,1.449001,1.449278,194.434899,3.825074,0.448618,0.449018,19.912166,275.059584,1.976038,0.01976038,0,1.976038,0.448725,-0.03454,500,71.1374,0,0,0,0,0,0
6426,44701.50741,6425.361603,57970612,102.347894,1.475211,1.476384,196.742658,3.849726,0.475038,0.476564,19.912166,278.322677,2.014747,0.02014747,0,2.014747,0.475619,-0.03834,500,71.1537,0,0,0,0,0,0
6453,44701.50772,6452.361603,57970639,104.217299,1.501634,1.504287,198.644742,3.878323,0.501558,0.50401,19.912166,281.101218,2.054064,0.02054064,0,2.054064,0.502875,-0.04141,500,71.1721,0,0,0,0,0,0
6480,44701.50803,6479.361603,57970666,105.465137,1.528089,1.531704,200.119845,3.904948,0.527845,0.531621,19.912166,282.981408,2.09284,0.0209284,0,2.09284,0.529659,-0.04624,500,71.1927,0,0,0,0,0,0
6507,44701.50835,6506.361603,57970693,105.710963,1.554553,1.558895,200.536656,3.930586,0.554387,0.558936,19.912166,283.632016,2.131577,0.02131577,0,2.131577,0.556641,-0.05447,500,71.2155,0,0,0,0,0,0
6534,44701.50866,6533.361603,57970720,100.736215,1.580738,1.58712,195.620687,3.959183,0.580552,0.586942,19.912166,276.752877,2.170756,0.02170756,0,2.170756,0.583885,-0.0836,500,71.2483,0,0,0,0,0,0
6561,44701.50897,6560.361603,57970747,82.492759,1.607569,1.614385,177.549549,3.988766,0.607442,0.614355,19.912166,251.225117,2.209843,0.02209843,0,2.209843,0.610725,-0.1692,500,71.3009,0,0,0,0,0,0
6588,44701.50928,6587.361603,57970774,80.213244,1.63412,1.641411,175.639698,4.015391,0.633924,0.641309,19.912166,248.249893,2.24854,0.0224854,0,2.24854,0.637629,-0.03729,500,71.319,0,0,0,0,0,0
6615,44701.5096,6614.361603,57970801,79.089299,1.661224,1.668485,174.705253,4.041029,0.661064,0.668493,19.912166,247.353081,2.287899,0.02287899,0,2.287899,0.664654,-0.03813,500,71.3361,0,0,0,0,0,0
6633,44701.5098,6632.361603,57970819,76.178491,1.663378,1.670635,172.062008,4.043987,0.662979,0.670235,19.912166,243.393871,2.290544,0.02290544,0,2.290544,0.666647,-0.00295,500,71.3417,0,0,0,0,0,0